Workbook

Sheet 대시보드
A1: 통합 이커머스 매출 및 재고 관리 시스템 (Mini-ERP)
A3: 📊 주요 KPI | F3: 📊 채널별 성과
A5: 지표 | B5: 금액/값 | C5: 목표 | D5: 상태 | F5: 채널 | G5: 매출액 | H5: 비중
A6: 총 매출액 (VAT제외) | B6: =SUM(손익분석!J:J) -> 1.269106e+08 | C6: 50000000 | D6: =IF(B6>=C6,"✅ 달성","🔺 미달") -> ✅ 달성 | F6: SK스토아 | G6: =SUMIF(손익분석!A:A,"SK스토아",손익분석!J:J) -> 94332145 | H6: =IF($G$10=0,0,G6/$G$10) -> 0.98856483
A7: 공헌이익 | B7: =SUM(손익분석!M:M) -> 50148218 | F7: 네이버 | G7: =SUMIF(손익분석!A:A,"네이버",손익분석!J:J) -> 94000 | H7: =IF($G$10=0,0,G7/$G$10) -> 0.00098508407
A8: 공헌이익률 | B8: =IF(B6=0,0,B7/B6) -> 0.39514602 | C8: 0.1 | D8: =IF(B8>=C8,"✅ 달성","🔺 미달") -> ✅ 달성 | F8: 쿠팡 | G8: =SUMIF(손익분석!A:A,"쿠팡",손익분석!J:J) -> 705727.27 | H8: =IF($G$10=0,0,G8/$G$10) -> 0.0073957521
A9: 재고 알람 건수 | B9: =COUNTIF(재고현황!G:G,"*발주필요*") -> 0 | C9: 0건 | D9: =IF(B9=0,"✅ 정상","⚠️ 확인필요") -> ✅ 정상 | F9: 카카오+리씨크 | G9: =SUMIF(손익분석!A:A,"카카오",손익분석!J:J)+SUMIF(손익분석!A:A,"리씨크",손익분석!J:J) -> 291454.55 | H9: =IF($G$10=0,0,G9/$G$10) -> 0.0030543322
A10: 총 판매건수 | B10: =COUNTA(정규화데이터!A:A)-1 -> 1544 | C10: - | F10: 합계 | G10: =SUM(G6:G9) -> 95423327 | H10: =SUM(H6:H9) -> 1
A11: 데이터 기간 | B11: 2026-02-04 ~ 2026-02-05 | F11: 데이터 흐름 | G11: 금액
A13: 📅 기간별 매출 조회 | F13: 1단계: 매출(VAT제외) | G13: =SUM(손익분석!J:J) -> 1.269106e+08
F14: 2단계: 변동비(총원가) | G14: =SUM(손익분석!L:L) -> 76762382
A15: 조회 기간 선택 | B15: 일별 | F15: 3단계: 공헌이익 | G15: =SUM(손익분석!M:M) -> 50148218 | H15: 매출 - 변동비
A16: 조회할 날짜 입력 | B16: 20260210 | C16: (예: 20260204) | F16: 공헌이익률 | G16: =IF(G13=0,0,G15/G13) -> 0.39514602
A18: 일별 매출 | B18: 금액 | C18: 건수 | D18: 공헌이익
A19: 46057 | B19: =SUMIFS(손익분석!J:J,손익분석!B:B,">="&B16&"000000",손익분석!B:B,"<="&B16&"999999") -> 41454636 | C19: =COUNTIFS(손익분석!B:B,">="&B16&"000000",손익분석!B:B,"<="&B16&"999999") -> 388 | D19: =SUMIFS(손익분석!M:M,손익분석!B:B,">="&B16&"000000",손익분석!B:B,"<="&B16&"999999") -> 17532692
A21: 조회 기간 선택 | B21: 월별
A22: 조회할 월 입력 | B22: 202602 | C22: (예: 202602)
A23: 월별 매출 | B23: 금액 | C23: 건수 | D23: 공헌이익
A24: 2026-02 | B24: =SUMIFS(손익분석!J:J,손익분석!B:B,">="&B22&"00000000",손익분석!B:B,"<="&B22&"99999999") -> 94332145 | C24: =COUNTIFS(손익분석!B:B,">="&B22&"00000000",손익분석!B:B,"<="&B22&"99999999") -> 880 | D24: =SUMIFS(손익분석!M:M,손익분석!B:B,">="&B22&"00000000",손익분석!B:B,"<="&B22&"99999999") -> 39692949
A52: Layer | B52: Component | C52: Description
A53: 1. 입력층 | B53: Raw_SK | C53: 채널 원본 데이터 (CSV/Excel 직접 입력)
B54: Product_Master | C54: 자사 SKU, 원가, 재고 마스터
B55: Channel_Mapping | C55: 채널코드 ↔ 자사SKU 매핑 테이블
A56: 2. 처리층 | B56: Normalized_Data | C56: 표준 스키마로 정규화 (VLOOKUP 자동 매핑)
B57: Inventory_Status | C57: 재고 차감 엔진 (SUMIF 기반)
B58: PnL_Analysis | C58: 손익 계산 엔진 (공헌이익/영업이익)
A59: 3. 출력층 | B59: Dashboard | C59: KPI 시각화 및 알람
B60: Reports | C60: 채널별/SKU별 분석 리포트
A62: 🚀 확장 가이드
A64: 확장 항목 | B64: 구현 방법 | C64: 난이도
A65: 네이버/쿠팡 추가 | B65: 1) Raw_Naver, Raw_Coupang 시트 생성 | C65: ⭐ 쉬움
B66: 2) Channel_Mapping에 해당 채널 코드 추가
B67: 3) Normalized_Data 수식에서 해당 시트 참조 추가
A68: Power Query 자동화 | B68: 폴더 감시 → 자동 데이터 로드 구현 | C68: ⭐⭐ 중간
A69: VBA 버튼 추가 | B69: "데이터 새로고침" 버튼으로 전체 갱신 | C69: ⭐⭐ 중간
A70: 차트/피벗 추가 | B70: PnL_Analysis 데이터로 차트/피벗테이블 생성 | C70: ⭐ 쉬움
A72: ✅ 시스템 구축 완료
A74: 구축된 기능 | B74: 상태 | C74: 비고
A75: ✓ 제품 마스터 데이터 | B75: ✅ 완료 | C75: 10개 샘플 SKU 등록됨
A76: ✓ 채널 매핑 시스템 | B76: ✅ 완료 | C76: SK스토아 5개 상품 매핑됨
...

Sheet 제품마스터
A1: 자사 SKU | B1: 제품명 | C1: 카테고리 | D1: 매입원가 | E1: 기초재고 | F1: 안전재고 | G1: 물류사 | H1: 브랜드 | I1: 출시일 | J1: 중량 | K1: 보관온도 | L1: 소비기한 | M1: 식품유형 | N1: 면/과세 | O1: 품목바코드 | P1: 제조원가 | Q1: 로얄티 | R1: 상품원가 | S1: 유통전문판매원 | T1: 제조사 | U1: 물류지 | V1: 발주리드타임 | W1: 입수 | X1: 적재수/1PLT | Y1: 제품규격_가로 | Z1: 제품규격_세로 | AA1: 제품규격_높이 | AB1: MOQ
A2: SKU001 | B2: [워커힐] 시그니처 양념갈비 300G | C2: 양념육 | D2: 7687 | E2: 25000 | F2: 5000 | G2: 주식회사 정인 | H2: 워커힐 | I2: 01월 30일 | J2: 300g | K2: 냉동 | L2: 제조일로부터 1년 | M2: 양념육(비살균제품) | N2: 과세 | O2: 8800286500186 | P2: 7300 | Q2: 387 | R2: 7687 | S2: SK네트웍스ⓚSC워커힐 | T2: 주식회사 미더스 | U2: 주식회사 정인 | V2: 4주 | W2: 30 | X2: 42 | Y2: 164 | Z2: 214 | AA2: 30

Sheet 채널매핑
A1: 채널명 | B1: 채널상품코드 | C1: 채널상품명 | D1: 자사SKU | E1: 세트수량 (1세트당 SKU 개수) | F1: 매핑일자 | G1: 📝 세트 수량 설명
A2: SK스토아 | B2: 58999583 | C2: [워커힐]워커힐 고메 시그니처 양념 본갈비 8팩 | D2: SKU001 | E2: 8 | F2: 45306 | G2: 예시: | H2: SK스토아에서 1세트 판매 = 자샊SKU 8개 소비
A3: SK스토아 | B3: 58481090 | C3: [워커힐]워커힐 고메 시그니처 양념 본갈비 8팩 | D3: SKU001 | E3: 8 | F3: 45306 | G3: 설정: | H3: E열에 8 입력
A4: SK스토아 | B4: 59163204 | C4: [워커힐]워커힐 시그니처 양념 본갈비 4팩 | D4: SKU001 | E4: 4 | G4: 결과: | H4: 채널에서 2세트 판매 → 재고 16개 차감
A5: 쿠팡 | B5: 쿠팡_미지정 | C5: 워커힐 시그니처 양념 본갈비 300g | D5: SKU001 | E5: 1
A6: 네이버 | B6: A1 | C6: 워커힐 시그니처 양념 본갈비 300g, 1개 | D6: SKU001 | E6: 1 | G6: 채널별 판매 수수료율 입력 | H6: 1 (단품 판매)
A7: 네이버 | B7: A2 | C7: 워커힐 시그니처 양념 본갈비 300g, 2개 | D7: SKU001 | E7: 2 | G7: 파란색 = 사용자 입력 필수 | H7: 1세트당 포함된 SKU 개수 입력
A8: 카카오 | B8: A1 | C8: 워커힐 시그니처 양념 본갈비 300g, 1개 | D8: SKU001 | E8: 1 | G8: ⚠️ 주의: | H8: 파란색 = 수동 입력 필수
A9: 리씽크 | B9: 143790 | C9: 워커힐 본갈비 3+1 최초❤️5만원대! 총1.2kg | D9: SKU001 | E9: 4
A10: 리씽크 | B10: 143812 | C10: 워커힐 본갈비 추가구매 | D10: SKU001 | E10: 2
A11: 쿠팡(기본) | B11: DEFAULT | C11: 워커힐 시그니처 양념 본갈비 300g (기본) | D11: SKU001 | E11: 1

Sheet 원본데이터_SK
A1: No | B1: 업체코드 | C1: 업체명 | D1: 주문번호 | E1: 고객명 | F1: 상품코드 | G1: 소싱매체 | H1: 상품명 | I1: 단품코드 | J1: 단품명 | K1: 결제방법 | L1: 과세여부 | M1: 완료일 | N1: 배송상태 | O1: 판매가 | P1: 매입가 | Q1: 배송수량 | R1: 할인프로모션(업체) | S1: 쿠폰할인(업체) | T1: ARS할인(업체) | U1: 일시불할인(업체) | V1: 등급할인(업체) | W1: 수수료율 | X1: 할인프로모션(당사) | Y1: 쿠폰할인(당사) | Z1: ARS할인(당사) | AA1: 일시불할인(당사) | AB1: 등급할인(당사) | AC1: 판매가 기준 주문금액 | AD1: 매입가 기준 주문금액 | AE1: 업체프로모션 | AF1: 당사프로모션 | AG1: 고객결제금액 | AH1: 벤더사지급대금 | AI1: 위수탁수수료(공급가) | AJ1: 위수탁수수료(세액) | AK1: 위수탁수수료(합계)
A2: 1 | B2: 133329 | C2: 주식회사 로가온 | D2: 20260204818446 | E2: 이*진 | F2: 58481090 | G2: 방송 | H2: [워커힐]워커힐 고메 시그니처 양념 본갈비 8팩 | I2: 001 | J2: 없음 | K2: 신용카드 | L2: 과세 | M2: 2026-02-06 | N2: 배송완료 | O2: 119000 | P2: 82110 | Q2: 1 | R2: 0 | S2: 0 | T2: 0 | U2: 0 | V2: 0 | W2: 31 | X2: 0 | Y2: 10000 | Z2: 0 | AA2: 0 | AB2: 0 | AC2: 119000 | AD2: 82110 | AE2: 0 | AF2: 10000 | AG2: 109000 | AH2: 82110 | AI2: 24445 | AJ2: 2445 | AK2: 26890
A3: 2 | B3: 133329 | C3: 주식회사 로가온 | D3: 20260204842609 | E3: 이*희 | F3: 58481090 | G3: 방송 | H3: [워커힐]워커힐 고메 시그니처 양념 본갈비 8팩 | I3: 001 | J3: 없음 | K3: 신용카드 | L3: 과세 | M3: 2026-02-06 | N3: 배송완료 | O3: 119000 | P3: 82110 | Q3: 1 | R3: 0 | S3: 0 | T3: 0 | U3: 0 | V3: 0 | W3: 31 | X3: 0 | Y3: 15000 | Z3: 0 | AA3: 0 | AB3: 5200 | AC3: 119000 | AD3: 82110 | AE3: 0 | AF3: 20200 | AG3: 98800 | AH3: 82110 | AI3: 15173 | AJ3: 1517 | AK3: 16690
A4: 3 | B4: 133329 | C4: 주식회사 로가온 | D4: 20260205994554 | E4: 유*진 | F4: 58481090 | G4: 방송 | H4: [워커힐]워커힐 고메 시그니처 양념 본갈비 8팩 | I4: 001 | J4: 없음 | K4: 신용카드 | L4: 과세 | M4: 2026-02-06 | N4: 회수확정 | O4: 119000 | P4: 82110 | Q4: -1 | R4: 0 | S4: 0 | T4: 0 | U4: 0 | V4: 0 | W4: 31 | X4: 0 | Y4: 0 | Z4: 0 | AA4: 0 | AB4: -5950 | AC4: -119000 | AD4: -82110 | AE4: 0 | AF4: -5950 | AG4: -113050 | AH4: -82110 | AI4: -28127 | AJ4: -2813 | AK4: -30940
A5: 4 | B5: 133329 | C5: 주식회사 로가온 | D5: 20260205994554 | E5: 유*진 | F5: 58481090 | G5: 방송 | H5: [워커힐]워커힐 고메 시그니처 양념 본갈비 8팩 | I5: 001 | J5: 없음 | K5: 신용카드 | L5: 과세 | M5: 2026-02-06 | N5: 배송완료 | O5: 119000 | P5: 82110 | Q5: 1 | R5: 0 | S5: 0 | T5: 0 | U5: 0 | V5: 0 | W5: 31 | X5: 0 | Y5: 0 | Z5: 0 | AA5: 0 | AB5: 5950 | AC5: 119000 | AD5: 82110 | AE5: 0 | AF5: 5950 | AG5: 113050 | AH5: 82110 | AI5: 28127 | AJ5: 2813 | AK5: 30940
A6: 5 | B6: 133329 | C6: 주식회사 로가온 | D6: 20260205974443 | E6: 최*민 | F6: 58999583 | G6: 방송 | H6: [워커힐]워커힐 고메 시그니처 양념 본갈비 8팩 | I6: 001 | J6: 없음 | L6: 과세 | M6: 2026-02-06 | N6: 배송완료 | O6: 119000 | P6: 82110 | Q6: 1 | R6: 0 | S6: 0 | T6: 0 | U6: 0 | V6: 0 | W6: 31 | X6: 0 | Y6: 0 | Z6: 0 | AA6: 0 | AB6: 0 | AC6: 119000 | AD6: 82110 | AE6: 0 | AF6: 0 | AG6: 119000 | AH6: 82110 | AI6: 33536 | AJ6: 3354 | AK6: 36890
A7: 6 | B7: 133329 | C7: 주식회사 로가온 | D7: 20260204816757 | E7: 최*수 | F7: 58999583 | G7: 방송 | H7: [워커힐]워커힐 고메 시그니처 양념 본갈비 8팩 | I7: 001 | J7: 없음 | L7: 과세 | M7: 2026-02-06 | N7: 배송완료 | O7: 119000 | P7: 82110 | Q7: 1 | R7: 0 | S7: 0 | T7: 0 | U7: 0 | V7: 0 | W7: 31 | X7: 0 | Y7: 0 | Z7: 0 | AA7: 0 | AB7: 0 | AC7: 119000 | AD7: 82110 | AE7: 0 | AF7: 0 | AG7: 119000 | AH7: 82110 | AI7: 33536 | AJ7: 3354 | AK7: 36890
A8: 7 | B8: 133329 | C8: 주식회사 로가온 | D8: 20260204838783 | E8: 주* | F8: 58999583 | G8: 방송 | H8: [워커힐]워커힐 고메 시그니처 양념 본갈비 8팩 | I8: 001 | J8: 없음 | K8: 신용카드 | L8: 과세 | M8: 2026-02-06 | N8: 배송완료 | O8: 119000 | P8: 82110 | Q8: 1 | R8: 0 | S8: 0 | T8: 0 | U8: 0 | V8: 0 | W8: 31 | X8: 17850 | Y8: 0 | Z8: 0 | AA8: 0 | AB8: 0 | AC8: 119000 | AD8: 82110 | AE8: 0 | AF8: 17850 | AG8: 101150 | AH8: 82110 | AI8: 17309 | AJ8: 1731 | AK8: 19040
A9: 8 | B9: 133329 | C9: 주식회사 로가온 | D9: 20260205993814 | E9: 김*원 | F9: 58481090 | G9: 방송 | H9: [워커힐]워커힐 고메 시그니처 양념 본갈비 8팩 | I9: 001 | J9: 없음 | K9: 신용카드 | L9: 과세 | M9: 2026-02-07 | N9: 배송완료 | O9: 119000 | P9: 82110 | Q9: 2 | R9: 0 | S9: 0 | T9: 0 | U9: 0 | V9: 0 | W9: 31 | X9: 0 | Y9: 0 | Z9: 0 | AA9: 0 | AB9: 0 | AC9: 238000 | AD9: 164220 | AE9: 0 | AF9: 0 | AG9: 238000 | AH9: 164220 | AI9: 67073 | AJ9: 6707 | AK9: 73780
A10: 9 | B10: 133329 | C10: 주식회사 로가온 | D10: 20260205994105 | E10: 유*정 | F10: 58481090 | G10: 방송 | H10: [워커힐]워커힐 고메 시그니처 양념 본갈비 8팩 | I10: 001 | J10: 없음 | K10: 신용카드 | L10: 과세 | M10: 2026-02-07 | N10: 배송완료 | O10: 119000 | P10: 82110 | Q10: 1 | R10: 0 | S10: 0 | T10: 0 | U10: 0 | V10: 0 | W10: 31 | X10: 0 | Y10: 0 | Z10: 0 | AA10: 0 | AB10: 0 | AC10: 119000 | AD10: 82110 | AE10: 0 | AF10: 0 | AG10: 119000 | AH10: 82110 | AI10: 33536 | AJ10: 3354 | AK10: 36890
A11: 10 | B11: 133329 | C11: 주식회사 로가온 | D11: 20260205995257 | E11: 박*옥 | F11: 58481090 | G11: 방송 | H11: [워커힐]워커힐 고메 시그니처 양념 본갈비 8팩 | I11: 001 | J11: 없음 | K11: 신용카드 | L11: 과세 | M11: 2026-02-07 | N11: 배송완료 | O11: 119000 | P11: 82110 | Q11: 1 | R11: 0 | S11: 0 | T11: 0 | U11: 0 | V11: 0 | W11: 31 | X11: 0 | Y11: 0 | Z11: 0 | AA11: 0 | AB11: 0 | AC11: 119000 | AD11: 82110 | AE11: 0 | AF11: 0 | AG11: 119000 | AH11: 82110 | AI11: 33536 | AJ11: 3354 | AK11: 36890
A12: 11 | B12: 133329 | C12: 주식회사 로가온 | D12: 20260205993931 | E12: 정*석 | F12: 58481090 | G12: 방송 | H12: [워커힐]워커힐 고메 시그니처 양념 본갈비 8팩 | I12: 001 | J12: 없음 | K12: 신용카드 | L12: 과세 | M12: 2026-02-07 | N12: 배송완료 | O12: 119000 | P12: 82110 | Q12: 1 | R12: 0 | S12: 0 | T12: 0 | U12: 0 | V12: 0 | W12: 31 | X12: 0 | Y12: 0 | Z12: 0 | AA12: 0 | AB12: 0 | AC12: 119000 | AD12: 82110 | AE12: 0 | AF12: 0 | AG12: 119000 | AH12: 82110 | AI12: 33536 | AJ12: 3354 | AK12: 36890
A13: 12 | B13: 133329 | C13: 주식회사 로가온 | D13: 20260205992438 | E13: 김*자 | F13: 58481090 | G13: 방송 | H13: [워커힐]워커힐 고메 시그니처 양념 본갈비 8팩 | I13: 001 | J13: 없음 | K13: 신용카드 | L13: 과세 | M13: 2026-02-07 | N13: 배송완료 | O13: 119000 | P13: 82110 | Q13: 1 | R13: 0 | S13: 0 | T13: 0 | U13: 0 | V13: 0 | W13: 31 | X13: 0 | Y13: 0 | Z13: 0 | AA13: 0 | AB13: 0 | AC13: 119000 | AD13: 82110 | AE13: 0 | AF13: 0 | AG13: 119000 | AH13: 82110 | AI13: 33536 | AJ13: 3354 | AK13: 36890
A14: 13 | B14: 133329 | C14: 주식회사 로가온 | D14: 20260205992964 | E14: 송*영 | F14: 58481090 | G14: 방송 | H14: [워커힐]워커힐 고메 시그니처 양념 본갈비 8팩 | I14: 001 | J14: 없음 | K14: 신용카드 | L14: 과세 | M14: 2026-02-07 | N14: 배송완료 | O14: 119000 | P14: 82110 | Q14: 1 | R14: 0 | S14: 0 | T14: 0 | U14: 0 | V14: 0 | W14: 31 | X14: 0 | Y14: 0 | Z14: 0 | AA14: 0 | AB14: 5950 | AC14: 119000 | AD14: 82110 | AE14: 0 | AF14: 5950 | AG14: 113050 | AH14: 82110 | AI14: 28127 | AJ14: 2813 | AK14: 30940
A15: 14 | B15: 133329 | C15: 주식회사 로가온 | D15: 20260205995526 | E15: 임*희 | F15: 58481090 | G15: 방송 | H15: [워커힐]워커힐 고메 시그니처 양념 본갈비 8팩 | I15: 001 | J15: 없음 | K15: 신용카드 | L15: 과세 | M15: 2026-02-07 | N15: 배송완료 | O15: 119000 | P15: 82110 | Q15: 1 | R15: 0 | S15: 0 | T15: 0 | U15: 0 | V15: 0 | W15: 31 | X15: 0 | Y15: 0 | Z15: 0 | AA15: 0 | AB15: 0 | AC15: 119000 | AD15: 82110 | AE15: 0 | AF15: 0 | AG15: 119000 | AH15: 82110 | AI15: 33536 | AJ15: 3354 | AK15: 36890
A16: 15 | B16: 133329 | C16: 주식회사 로가온 | D16: 20260205995622 | E16: 김*재 | F16: 58481090 | G16: 방송 | H16: [워커힐]워커힐 고메 시그니처 양념 본갈비 8팩 | I16: 001 | J16: 없음 | K16: 신용카드 | L16: 과세 | M16: 2026-02-07 | N16: 배송완료 | O16: 119000 | P16: 82110 | Q16: 1 | R16: 0 | S16: 0 | T16: 0 | U16: 0 | V16: 0 | W16: 31 | X16: 0 | Y16: 0 | Z16: 0 | AA16: 0 | AB16: 0 | AC16: 119000 | AD16: 82110 | AE16: 0 | AF16: 0 | AG16: 119000 | AH16: 82110 | AI16: 33536 | AJ16: 3354 | AK16: 36890
A17: 16 | B17: 133329 | C17: 주식회사 로가온 | D17: 20260205997344 | E17: 최*숙 | F17: 58481090 | G17: 방송 | H17: [워커힐]워커힐 고메 시그니처 양념 본갈비 8팩 | I17: 001 | J17: 없음 | K17: 신용카드 | L17: 과세 | M17: 2026-02-07 | N17: 배송완료 | O17: 119000 | P17: 82110 | Q17: 1 | R17: 0 | S17: 0 | T17: 0 | U17: 0 | V17: 0 | W17: 31 | X17: 0 | Y17: 0 | Z17: 0 | AA17: 0 | AB17: 5950 | AC17: 119000 | AD17: 82110 | AE17: 0 | AF17: 5950 | AG17: 113050 | AH17: 82110 | AI17: 28127 | AJ17: 2813 | AK17: 30940
A18: 17 | B18: 133329 | C18: 주식회사 로가온 | D18: 20260205995265 | E18: 임*아 | F18: 58481090 | G18: 방송 | H18: [워커힐]워커힐 고메 시그니처 양념 본갈비 8팩 | I18: 001 | J18: 없음 | K18: 신용카드 | L18: 과세 | M18: 2026-02-07 | N18: 배송완료 | O18: 119000 | P18: 82110 | Q18: 1 | R18: 0 | S18: 0 | T18: 0 | U18: 0 | V18: 0 | W18: 31 | X18: 0 | Y18: 0 | Z18: 0 | AA18: 0 | AB18: 0 | AC18: 119000 | AD18: 82110 | AE18: 0 | AF18: 0 | AG18: 119000 | AH18: 82110 | AI18: 33536 | AJ18: 3354 | AK18: 36890
A19: 18 | B19: 133329 | C19: 주식회사 로가온 | D19: 20260205994047 | E19: 이*연 | F19: 58481090 | G19: 방송 | H19: [워커힐]워커힐 고메 시그니처 양념 본갈비 8팩 | I19: 001 | J19: 없음 | K19: 신용카드 | L19: 과세 | M19: 2026-02-07 | N19: 배송완료 | O19: 119000 | P19: 82110 | Q19: 1 | R19: 0 | S19: 0 | T19: 0 | U19: 0 | V19: 0 | W19: 31 | X19: 0 | Y19: 5000 | Z19: 0 | AA19: 0 | AB19: 0 | AC19: 119000 | AD19: 82110 | AE19: 0 | AF19: 5000 | AG19: 114000 | AH19: 82110 | AI19: 28991 | AJ19: 2899 | AK19: 31890
... A94: 93 | B94: 133329 | C94: 주식회사 로가온 | D94: 20260205993036 | E94: 김* | F94: 58481090 | G94: 방송 | H94: [워커힐]워커힐 고메 시그니처 양념 본갈비 8팩 | I94: 001 | J94: 없음 | K94: 신용카드 | L94: 과세 | M94: 2026-02-07 | N94: 배송완료 | O94: 119000 | P94: 82110 | Q94: 1 | R94: 0 | S94: 0 | T94: 0 | U94: 0 | V94: 0 | W94: 31 | X94: 19040 | Y94: 0 | Z94: 0 | AA94: 0 | AB94: 0 | AC94: 119000 | AD94: 82110 | AE94: 0 | AF94: 19040 | AG94: 99960 | AH94: 82110 | AI94: 16227 | AJ94: 1623 | AK94: 17850
A95: 94 | B95: 133329 | C95: 주식회사 로가온 | D95: 20260205995472 | E95: 심*경 | F95: 58481090 | G95: 방송 | H95: [워커힐]워커힐 고메 시그니처 양념 본갈비 8팩 | I95: 001 | J95: 없음 | L95: 과세 | M95: 2026-02-07 | N95: 배송완료 | O95: 119000 | P95: 82110 | Q95: 1 | R95: 0 | S95: 0 | T95: 0 | U95: 0 | V95: 0 | W95: 31 | X95: 0 | Y95: 5950 | Z95: 0 | AA95: 0 | AB95: 0 | AC95: 119000 | AD95: 82110 | AE95: 0 | AF95: 5950 | AG95: 113050 | AH95: 82110 | AI95: 28127 | AJ95: 2813 | AK95: 30940
A96: 95 | B96: 133329 | C96: 주식회사 로가온 | D96: 20260205992483 | E96: 김*지 | F96: 58481090 | G96: 방송 | H96: [워커힐]워커힐 고메 시그니처 양념 본갈비 8팩 | I96: 001 | J96: 없음 | K96: 신용카드 | L96: 과세 | M96: 2026-02-07 | N96: 배송완료 | O96: 119000 | P96: 82110 | Q96: 1 | R96: 0 | S96: 0 | T96: 0 | U96: 0 | V96: 0 | W96: 31 | X96: 0 | Y96: 10000 | Z96: 0 | AA96: 0 | AB96: 0 | AC96: 119000 | AD96: 82110 | AE96: 0 | AF96: 10000 | AG96: 109000 | AH96: 82110 | AI96: 24445 | AJ96: 2445 | AK96: 26890
A97: 96 | B97: 133329 | C97: 주식회사 로가온 | D97: 20260205995325 | E97: 한*윤 | F97: 58481090 | G97: 방송 | H97: [워커힐]워커힐 고메 시그니처 양념 본갈비 8팩 | I97: 001 | J97: 없음 | K97: 신용카드 | L97: 과세 | M97: 2026-02-07 | N97: 배송완료 | O97: 119000 | P97: 82110 | Q97: 1 | R97: 0 | S97: 0 | T97: 0 | U97: 0 | V97: 0 | W97: 31 | X97: 0 | Y97: 0 | Z97: 0 | AA97: 0 | AB97: 0 | AC97: 119000 | AD97: 82110 | AE97: 0 | AF97: 0 | AG97: 119000 | AH97: 82110 | AI97: 33536 | AJ97: 3354 | AK97: 36890
A98: 97 | B98: 133329 | C98: 주식회사 로가온 | D98: 20260205992634 | E98: 한*례 | F98: 58481090 | G98: 방송 | H98: [워커힐]워커힐 고메 시그니처 양념 본갈비 8팩 | I98: 001 | J98: 없음 | K98: 무통장입금 | L98: 과세 | M98: 2026-02-07 | N98: 배송완료 | O98: 119000 | P98: 82110 | Q98: 1 | R98: 0 | S98: 0 | T98: 0 | U98: 0 | V98: 0 | W98: 31 | X98: 0 | Y98: 0 | Z98: 0 | AA98: 0 | AB98: 0 | AC98: 119000 | AD98: 82110 | AE98: 0 | AF98: 0 | AG98: 119000 | AH98: 82110 | AI98: 33536 | AJ98: 3354 | AK98: 36890
A99: 98 | B99: 133329 | C99: 주식회사 로가온 | D99: 20260205994152 | E99: 김*자 | F99: 58481090 | G99: 방송 | H99: [워커힐]워커힐 고메 시그니처 양념 본갈비 8팩 | I99: 001 | J99: 없음 | K99: 신용카드 | L99: 과세 | M99: 2026-02-07 | N99: 배송완료 | O99: 119000 | P99: 82110 | Q99: 1 | R99: 0 | S99: 0 | T99: 0 | U99: 0 | V99: 0 | W99: 31 | X99: 0 | Y99: 0 | Z99: 0 | AA99: 0 | AB99: 0 | AC99: 119000 | AD99: 82110 | AE99: 0 | AF99: 0 | AG99: 119000 | AH99: 82110 | AI99: 33536 | AJ99: 3354 | AK99: 36890
A100: 99 | B100: 133329 | C100: 주식회사 로가온 | D100: 20260205995109 | E100: 김*주 | F100: 58481090 | G100: 방송 | H100: [워커힐]워커힐 고메 시그니처 양념 본갈비 8팩 | I100: 001 | J100: 없음 | K100: 신용카드 | L100: 과세 | M100: 2026-02-07 | N100: 배송완료 | O100: 119000 | P100: 82110 | Q100: 1 | R100: 0 | S100: 0 | T100: 0 | U100: 0 | V100: 0 | W100: 31 | X100: 0 | Y100: 0 | Z100: 0 | AA100: 0 | AB100: 0 | AC100: 119000 | AD100: 82110 | AE100: 0 | AF100: 0 | AG100: 119000 | AH100: 82110 | AI100: 33536 | AJ100: 3354 | AK100: 36890
A101: 100 | B101: 133329 | C101: 주식회사 로가온 | D101: 20260205994273 | E101: 장*주 | F101: 58481090 | G101: 방송 | H101: [워커힐]워커힐 고메 시그니처 양념 본갈비 8팩 | I101: 001 | J101: 없음 | K101: 신용카드 | L101: 과세 | M101: 2026-02-07 | N101: 배송완료 | O101: 119000 | P101: 82110 | Q101: 1 | R101: 0 | S101: 0 | T101: 0 | U101: 0 | V101: 0 | W101: 31 | X101: 0 | Y101: 0 | Z101: 0 | AA101: 0 | AB101: 0 | AC101: 119000 | AD101: 82110 | AE101: 0 | AF101: 0 | AG101: 119000 | AH101: 82110 | AI101: 33536 | AJ101: 3354 | AK101: 36890
A102: 101 | B102: 133329 | C102: 주식회사 로가온 | D102: 20260205995097 | E102: 차*의 | F102: 58481090 | G102: 방송 | H102: [워커힐]워커힐 고메 시그니처 양념 본갈비 8팩 | I102: 001 | J102: 없음 | K102: 신용카드 | L102: 과세 | M102: 2026-02-07 | N102: 배송완료 | O102: 119000 | P102: 82110 | Q102: 1 | R102: 0 | S102: 0 | T102: 0 | U102: 0 | V102: 0 | W102: 31 | X102: 0 | Y102: 0 | Z102: 0 | AA102: 0 | AB102: 0 | AC102: 119000 | AD102: 82110 | AE102: 0 | AF102: 0 | AG102: 119000 | AH102: 82110 | AI102: 33536 | AJ102: 3354 | AK102: 36890
A103: 102 | B103: 133329 | C103: 주식회사 로가온 | D103: 20260205995180 | E103: 노*희 | F103: 58481090 | G103: 방송 | H103: [워커힐]워커힐 고메 시그니처 양념 본갈비 8팩 | I103: 001 | J103: 없음 | K103: 신용카드 | L103: 과세 | M103: 2026-02-07 | N103: 배송완료 | O103: 119000 | P103: 82110 | Q103: 1 | R103: 0 | S103: 0 | T103: 0 | U103: 0 | V103: 0 | W103: 31 | X103: 22610 | Y103: 0 | Z103: 0 | AA103: 0 | AB103: 0 | AC103: 119000 | AD103: 82110 | AE103: 0 | AF103: 22610 | AG103: 96390 | AH103: 82110 | AI103: 12982 | AJ103: 1298 | AK103: 14280
A104: 103 | B104: 133329 | C104: 주식회사 로가온 | D104: 20260205992870 | E104: 회*애 | F104: 58481090 | G104: 방송 | H104: [워커힐]워커힐 고메 시그니처 양념 본갈비 8팩 | I104: 001 | J104: 없음 | K104: 신용카드 | L104: 과세 | M104: 2026-02-07 | N104: 배송완료 | O104: 119000 | P104: 82110 | Q104: 1 | R104: 0 | S104: 0 | T104: 0 | U104: 0 | V104: 0 | W104: 31 | X104: 0 | Y104: 0 | Z104: 0 | AA104: 0 | AB104: 0 | AC104: 119000 | AD104: 82110 | AE104: 0 | AF104: 0 | AG104: 119000 | AH104: 82110 | AI104: 33536 | AJ104: 3354 | AK104: 36890
A105: 104 | B105: 133329 | C105: 주식회사 로가온 | D105: 20260205992940 | E105: 백*진 | F105: 58481090 | G105: 방송 | H105: [워커힐]워커힐 고메 시그니처 양념 본갈비 8팩 | I105: 001 | J105: 없음 | K105: 신용카드 | L105: 과세 | M105: 2026-02-07 | N105: 배송완료 | O105: 119000 | P105: 82110 | Q105: 1 | R105: 0 | S105: 0 | T105: 0 | U105: 0 | V105: 0 | W105: 31 | X105: 0 | Y105: 0 | Z105: 0 | AA105: 0 | AB105: 0 | AC105: 119000 | AD105: 82110 | AE105: 0 | AF105: 0 | AG105: 119000 | AH105: 82110 | AI105: 33536 | AJ105: 3354 | AK105: 36890
A106: 105 | B106: 133329 | C106: 주식회사 로가온 | D106: 20260205993059 | E106: 김*화 | F106: 58481090 | G106: 방송 | H106: [워커힐]워커힐 고메 시그니처 양념 본갈비 8팩 | I106: 001 | J106: 없음 | K106: 신용카드 | L106: 과세 | M106: 2026-02-07 | N106: 배송완료 | O106: 119000 | P106: 82110 | Q106: 1 | R106: 0 | S106: 0 | T106: 0 | U106: 0 | V106: 0 | W106: 31 | X106: 0 | Y106: 0 | Z106: 0 | AA106: 0 | AB106: 0 | AC106: 119000 | AD106: 82110 | AE106: 0 | AF106: 0 | AG106: 119000 | AH106: 82110 | AI106: 33536 | AJ106: 3354 | AK106: 36890
A107: 106 | B107: 133329 | C107: 주식회사 로가온 | D107: 20260205993112 | E107: 안*옥 | F107: 58481090 | G107: 방송 | H107: [워커힐]워커힐 고메 시그니처 양념 본갈비 8팩 | I107: 001 | J107: 없음 | K107: 신용카드 | L107: 과세 | M107: 2026-02-07 | N107: 배송완료 | O107: 119000 | P107: 82110 | Q107: 1 | R107: 0 | S107: 0 | T107: 0 | U107: 0 | V107: 0 | W107: 31 | X107: 0 | Y107: 0 | Z107: 0 | AA107: 0 | AB107: 0 | AC107: 119000 | AD107: 82110 | AE107: 0 | AF107: 0 | AG107: 119000 | AH107: 82110 | AI107: 33536 | AJ107: 3354 | AK107: 36890
... A123: 122 | B123: 133329 | C123: 주식회사 로가온 | D123: 20260205995613 | E123: 최*희 | F123: 58481090 | G123: 방송 | H123: [워커힐]워커힐 고메 시그니처 양념 본갈비 8팩 | I123: 001 | J123: 없음 | K123: 신용카드 | L123: 과세 | M123: 2026-02-07 | N123: 배송완료 | O123: 119000 | P123: 82110 | Q123: 1 | R123: 0 | S123: 0 | T123: 0 | U123: 0 | V123: 0 | W123: 31 | X123: 0 | Y123: 0 | Z123: 0 | AA123: 0 | AB123: 0 | AC123: 119000 | AD123: 82110 | AE123: 0 | AF123: 0 | AG123: 119000 | AH123: 82110 | AI123: 33536 | AJ123: 3354 | AK123: 36890
A124: 123 | B124: 133329 | C124: 주식회사 로가온 | D124: 20260205002375 | E124: 정*순 | F124: 58481090 | G124: 방송 | H124: [워커힐]워커힐 고메 시그니처 양념 본갈비 8팩 | I124: 001 | J124: 없음 | L124: 과세 | M124: 2026-02-07 | N124: 배송완료 | O124: 119000 | P124: 82110 | Q124: 1 | R124: 0 | S124: 0 | T124: 0 | U124: 0 | V124: 0 | W124: 31 | X124: 0 | Y124: 0 | Z124: 0 | AA124: 0 | AB124: 0 | AC124: 119000 | AD124: 82110 | AE124: 0 | AF124: 0 | AG124: 119000 | AH124: 82110 | AI124: 33536 | AJ124: 3354 | AK124: 36890
A125: 124 | B125: 133329 | C125: 주식회사 로가온 | D125: 20260205994008 | E125: 옥*화 | F125: 58481090 | G125: 방송 | H125: [워커힐]워커힐 고메 시그니처 양념 본갈비 8팩 | I125: 001 | J125: 없음 | K125: 신용카드 | L125: 과세 | M125: 2026-02-07 | N125: 배송완료 | O125: 119000 | P125: 82110 | Q125: 1 | R125: 0 | S125: 0 | T125: 0 | U125: 0 | V125: 0 | W125: 31 | X125: 0 | Y125: 10000 | Z125: 0 | AA125: 0 | AB125: 0 | AC125: 119000 | AD125: 82110 | AE125: 0 | AF125: 10000 | AG125: 109000 | AH125: 82110 | AI125: 24445 | AJ125: 2445 | AK125: 26890
A126: 125 | B126: 133329 | C126: 주식회사 로가온 | D126: 20260205993800 | E126: 박*옥 | F126: 58481090 | G126: 방송 | H126: [워커힐]워커힐 고메 시그니처 양념 본갈비 8팩 | I126: 001 | J126: 없음 | K126: 신용카드 | L126: 과세 | M126: 2026-02-07 | N126: 배송완료 | O126: 119000 | P126: 82110 | Q126: 1 | R126: 0 | S126: 0 | T126: 0 | U126: 0 | V126: 0 | W126: 31 | X126: 0 | Y126: 0 | Z126: 0 | AA126: 0 | AB126: 0 | AC126: 119000 | AD126: 82110 | AE126: 0 | AF126: 0 | AG126: 119000 | AH126: 82110 | AI126: 33536 | AJ126: 3354 | AK126: 36890
A127: 126 | B127: 133329 | C127: 주식회사 로가온 | D127: 20260206644091 | E127: 유*진 | F127: 58481090 | G127: 방송 | H127: [워커힐]워커힐 고메 시그니처 양념 본갈비 8팩 | I127: 001 | J127: 없음 | K127: 신용카드 | L127: 과세 | M127: 2026-02-07 | N127: 배송완료 | O127: 119000 | P127: 82110 | Q127: 1 | R127: 0 | S127: 0 | T127: 0 | U127: 0 | V127: 0 | W127: 31 | X127: 0 | Y127: 0 | Z127: 0 | AA127: 0 | AB127: 5950 | AC127: 119000 | AD127: 82110 | AE127: 0 | AF127: 5950 | AG127: 113050 | AH127: 82110 | AI127: 28127 | AJ127: 2813 | AK127: 30940
A128: 127 | B128: 133329 | C128: 주식회사 로가온 | D128: 20260205995701 | E128: 김*현 | F128: 58481090 | G128: 방송 | H128: [워커힐]워커힐 고메 시그니처 양념 본갈비 8팩 | I128: 001 | J128: 없음 | K128: 신용카드 | L128: 과세 | M128: 2026-02-07 | N128: 배송완료 | O128: 119000 | P128: 82110 | Q128: 1 | R128: 0 | S128: 0 | T128: 0 | U128: 0 | V128: 0 | W128: 31 | X128: 0 | Y128: 0 | Z128: 0 | AA128: 0 | AB128: 0 | AC128: 119000 | AD128: 82110 | AE128: 0 | AF128: 0 | AG128: 119000 | AH128: 82110 | AI128: 33536 | AJ128: 3354 | AK128: 36890
A129: 128 | B129: 133329 | C129: 주식회사 로가온 | D129: 20260205995459 | E129: 문*완 | F129: 58481090 | G129: 방송 | H129: [워커힐]워커힐 고메 시그니처 양념 본갈비 8팩 | I129: 001 | J129: 없음 | K129: 신용카드 | L129: 과세 | M129: 2026-02-07 | N129: 배송완료 | O129: 119000 | P129: 82110 | Q129: 1 | R129: 0 | S129: 0 | T129: 0 | U129: 0 | V129: 0 | W129: 31 | X129: 19040 | Y129: 0 | Z129: 0 | AA129: 0 | AB129: 0 | AC129: 119000 | AD129: 82110 | AE129: 0 | AF129: 19040 | AG129: 99960 | AH129: 82110 | AI129: 16227 | AJ129: 1623 | AK129: 17850
...

Sheet 정규화데이터
A1: 판매채널 | B1: 주문번호 | C1: 상품명 | D1: 상품코드 | E1: 자사SKU | F1: 판매수량 | G1: 판매가 | H1: 총판매가 | I1: 실정산금액 | J1: VAT제외금액 | K1: 원가 | L1: 총원가
A2: SK스토아 | B2: 20260204818446 | C2: [워커힐]워커힐 고메 시그니처 양념 본갈비 8팩 | D2: 58481090 | E2: SKU001 | F2: 1 | G2: 119000 | H2: 109000 | I2: 82110 | J2: 99090.909 | K2: 61496 | L2: 61496 | M2: Raw_SK 시트에 데이터 입력 완료 후
A3: SK스토아 | B3: 20260204842609 | C3: [워커힐]워커힐 고메 시그니처 양념 본갈비 8팩 | D3: 58481090 | E3: SKU001 | F3: 1 | G3: 119000 | H3: 98800 | I3: 82110 | J3: 89818.182 | K3: 61496 | L3: 61496 | M3: A2:H2 수식을 아래로 복사
A4: SK스토아 | B4: 20260205994554 | C4: [워커힐]워커힐 고메 시그니처 양념 본갈비 8팩 | D4: 58481090 | E4: SKU001 | F4: -1 | G4: 119000 | H4: -113050 | I4: -82110 | J4: -102772.73 | K4: 61496 | L4: -61496 | M4: 자동으로 표준 포맷 변환
A5: SK스토아 | B5: 20260205994554 | C5: [워커힐]워커힐 고메 시그니처 양념 본갈비 8팩 | D5: 58481090 | E5: SKU001 | F5: 1 | G5: 119000 | H5: 113050 | I5: 82110 | J5: 102772.73 | K5: 61496 | L5: 61496
A6: SK스토아 | B6: 20260205974443 | C6: [워커힐]워커힐 고메 시그니처 양념 본갈비 8팩 | D6: 58999583 | E6: SKU001 | F6: 1 | G6: 119000 | H6: 119000 | I6: 82110 | J6: 108181.82 | K6: 61496 | L6: 61496 | M6: Channel_Mapping 테이블에
A7: SK스토아 | B7: 20260204816757 | C7: [워커힐]워커힐 고메 시그니처 양념 본갈비 8팩 | D7: 58999583 | E7: SKU001 | F7: 1 | G7: 119000 | H7: 119000 | I7: 82110 | J7: 108181.82 | K7: 61496 | L7: 61496 | M7: 채널코드가 반드시 등록되어 있어야
A8: SK스토아 | B8: 20260204838783 | C8: [워커힐]워커힐 고메 시그니처 양념 본갈비 8팩 | D8: 58999583 | E8: SKU001 | F8: 1 | G8: 119000 | H8: 101150 | I8: 82110 | J8: 91954.545 | K8: 61496 | L8: 61496 | M8: 자사SKU 매핑이 정상 작동합니다.
A9: SK스토아 | B9: 20260205993814 | C9: [워커힐]워커힐 고메 시그니처 양념 본갈비 8팩 | D9: 58481090 | E9: SKU001 | F9: 2 | G9: 119000 | H9: 238000 | I9: 164220 | J9: 216363.64 | K9: 61496 | L9: 122992
A10: SK스토아 | B10: 20260205994105 | C10: [워커힐]워커힐 고메 시그니처 양념 본갈비 8팩 | D10: 58481090 | E10: SKU001 | F10: 1 | G10: 119000 | H10: 119000 | I10: 82110 | J10: 108181.82 | K10: 61496 | L10: 61496 | M10: 회색 = 자동계산 수식
A11: SK스토아 | B11: 20260205995257 | C11: [워커힐]워커힐 고메 시그니처 양념 본갈비 8팩 | D11: 58481090 | E11: SKU001 | F11: 1 | G11: 119000 | H11: 119000 | I11: 82110 | J11: 108181.82 | K11: 61496 | L11: 61496
A12: SK스토아 | B12: 20260205993931 | C12: [워커힐]워커힐 고메 시그니처 양념 본갈비 8팩 | D12: 58481090 | E12: SKU001 | F12: 1 | G12: 119000 | H12: 119000 | I12: 82110 | J12: 108181.82 | K12: 61496 | L12: 61496
A13: SK스토아 | B13: 20260205992438 | C13: [워커힐]워커힐 고메 시그니처 양념 본갈비 8팩 | D13: 58481090 | E13: SKU001 | F13: 1 | G13: 119000 | H13: 119000 | I13: 82110 | J13: 108181.82 | K13: 61496 | L13: 61496
A14: SK스토아 | B14: 20260205992964 | C14: [워커힐]워커힐 고메 시그니처 양념 본갈비 8팩 | D14: 58481090 | E14: SKU001 | F14: 1 | G14: 119000 | H14: 113050 | I14: 82110 | J14: 102772.73 | K14: 61496 | L14: 61496
A15: SK스토아 | B15: 20260205995526 | C15: [워커힐]워커힐 고메 시그니처 양념 본갈비 8팩 | D15: 58481090 | E15: SKU001 | F15: 1 | G15: 119000 | H15: 119000 | I15: 82110 | J15: 108181.82 | K15: 61496 | L15: 61496
A16: SK스토아 | B16: 20260205995622 | C16: [워커힐]워커힐 고메 시그니처 양념 본갈비 8팩 | D16: 58481090 | E16: SKU001 | F16: 1 | G16: 119000 | H16: 119000 | I16: 82110 | J16: 108181.82 | K16: 61496 | L16: 61496
A17: SK스토아 | B17: 20260205997344 | C17: [워커힐]워커힐 고메 시그니처 양념 본갈비 8팩 | D17: 58481090 | E17: SKU001 | F17: 1 | G17: 119000 | H17: 113050 | I17: 82110 | J17: 102772.73 | K17: 61496 | L17: 61496
A18: SK스토아 | B18: 20260205995265 | C18: [워커힐]워커힐 고메 시그니처 양념 본갈비 8팩 | D18: 58481090 | E18: SKU001 | F18: 1 | G18: 119000 | H18: 119000 | I18: 82110 | J18: 108181.82 | K18: 61496 | L18: 61496
A19: SK스토아 | B19: 20260205994047 | C19: [워커힐]워커힐 고메 시그니처 양념 본갈비 8팩 | D19: 58481090 | E19: SKU001 | F19: 1 | G19: 119000 | H19: 114000 | I19: 82110 | J19: 103636.36 | K19: 61496 | L19: 61496
A20: SK스토아 | B20: 20260205995035 | C20: [워커힐]워커힐 고메 시그니처 양념 본갈비 8팩 | D20: 58481090 | E20: SKU001 | F20: 1 | G20: 119000 | H20: 119000 | I20: 82110 | J20: 108181.82 | K20: 61496 | L20: 61496
A21: SK스토아 | B21: 20260205994804 | C21: [워커힐]워커힐 고메 시그니처 양념 본갈비 8팩 | D21: 58481090 | E21: SKU001 | F21: 1 | G21: 119000 | H21: 119000 | I21: 82110 | J21: 108181.82 | K21: 61496 | L21: 61496
A22: SK스토아 | B22: 20260205993699 | C22: [워커힐]워커힐 고메 시그니처 양념 본갈비 8팩 | D22: 58481090 | E22: SKU001 | F22: 1 | G22: 119000 | H22: 105910 | I22: 82110 | J22: 96281.818 | K22: 61496 | L22: 61496
... A590: SK스토아 | B590: 20260210361447 | C590: [워커힐]워커힐 고메 시그니처 양념 본갈비 8팩 | D590: 58481090 | E590: SKU001 | F590: 1 | G590: 119000 | H590: 119000 | I590: 80920 | J590: 108181.82 | K590: 61496 | L590: 61496
A591: SK스토아 | B591: 20260210361487 | C591: [워커힐]워커힐 고메 시그니처 양념 본갈비 8팩 | D591: 58481090 | E591: SKU001 | F591: 1 | G591: 119000 | H591: 119000 | I591: 80920 | J591: 108181.82 | K591: 61496 | L591: 61496 | M591: Raw_SK 시트에 데이터 입력 완료 후
A592: SK스토아 | B592: 20260210361437 | C592: [워커힐]워커힐 고메 시그니처 양념 본갈비 8팩 | D592: 58481090 | E592: SKU001 | F592: 1 | G592: 119000 | H592: 119000 | I592: 80920 | J592: 108181.82 | K592: 61496 | L592: 61496 | M592: Raw_SK 시트에 데이터 입력 완료 후
A593: SK스토아 | B593: 20260210361980 | C593: [워커힐]워커힐 고메 시그니처 양념 본갈비 8팩 | D593: 58481090 | E593: SKU001 | F593: 1 | G593: 119000 | H593: 119000 | I593: 80920 | J593: 108181.82 | K593: 61496 | L593: 61496 | M593: Raw_SK 시트에 데이터 입력 완료 후
A594: SK스토아 | B594: 20260210361671 | C594: [워커힐]워커힐 고메 시그니처 양념 본갈비 8팩 | D594: 58481090 | E594: SKU001 | F594: 1 | G594: 119000 | H594: 119000 | I594: 80920 | J594: 108181.82 | K594: 61496 | L594: 61496 | M594: Raw_SK 시트에 데이터 입력 완료 후
A595: SK스토아 | B595: 20260210361805 | C595: [워커힐]워커힐 고메 시그니처 양념 본갈비 8팩 | D595: 58481090 | E595: SKU001 | F595: 1 | G595: 119000 | H595: 119000 | I595: 80920 | J595: 108181.82 | K595: 61496 | L595: 61496 | M595: Raw_SK 시트에 데이터 입력 완료 후
A596: SK스토아 | B596: 20260210361070 | C596: [워커힐]워커힐 고메 시그니처 양념 본갈비 8팩 | D596: 58481090 | E596: SKU001 | F596: 1 | G596: 119000 | H596: 119000 | I596: 80920 | J596: 108181.82 | K596: 61496 | L596: 61496 | M596: Raw_SK 시트에 데이터 입력 완료 후
A597: SK스토아 | B597: 20260210361609 | C597: [워커힐]워커힐 고메 시그니처 양념 본갈비 8팩 | D597: 58481090 | E597: SKU001 | F597: 1 | G597: 119000 | H597: 109000 | I597: 80920 | J597: 99090.909 | K597: 61496 | L597: 61496 | M597: Raw_SK 시트에 데이터 입력 완료 후
A598: SK스토아 | B598: 20260210361990 | C598: [워커힐]워커힐 고메 시그니처 양념 본갈비 8팩 | D598: 58481090 | E598: SKU001 | F598: 1 | G598: 119000 | H598: 113050 | I598: 80920 | J598: 102772.73 | K598: 61496 | L598: 61496 | M598: Raw_SK 시트에 데이터 입력 완료 후
A599: SK스토아 | B599: 20260210361401 | C599: [워커힐]워커힐 고메 시그니처 양념 본갈비 8팩 | D599: 58481090 | E599: SKU001 | F599: 1 | G599: 119000 | H599: 119000 | I599: 80920 | J599: 108181.82 | K599: 61496 | L599: 61496 | M599: Raw_SK 시트에 데이터 입력 완료 후
A600: SK스토아 | B600: 20260210360406 | C600: [워커힐]워커힐 고메 시그니처 양념 본갈비 8팩 | D600: 58481090 | E600: SKU001 | F600: 1 | G600: 119000 | H600: 119000 | I600: 80920 | J600: 108181.82 | K600: 61496 | L600: 61496 | M600: Raw_SK 시트에 데이터 입력 완료 후
A601: SK스토아 | B601: 20260210361356 | C601: [워커힐]워커힐 고메 시그니처 양념 본갈비 8팩 | D601: 58481090 | E601: SKU001 | F601: 1 | G601: 119000 | H601: 119000 | I601: 80920 | J601: 108181.82 | K601: 61496 | L601: 61496 | M601: Raw_SK 시트에 데이터 입력 완료 후
A602: SK스토아 | B602: 20260210360454 | C602: [워커힐]워커힐 고메 시그니처 양념 본갈비 8팩 | D602: 58481090 | E602: SKU001 | F602: 1 | G602: 119000 | H602: 119000 | I602: 80920 | J602: 108181.82 | K602: 61496 | L602: 61496 | M602: Raw_SK 시트에 데이터 입력 완료 후
... A880: SK스토아 | B880: 20260210360908 | C880: [워커힐]워커힐 고메 시그니처 양념 본갈비 8팩 | D880: 58481090 | E880: SKU001 | F880: 1 | G880: 119000 | H880: 113050 | I880: 80920 | J880: 102772.73 | K880: 61496 | L880: 61496 | M880: Raw_SK 시트에 데이터 입력 완료 후
A881: SK스토아 | B881: 20260210342835 | C881: [워커힐]워커힐 고메 시그니처 양념 본갈비 8팩 | D881: 58481090 | E881: SKU001 | F881: 1 | G881: 119000 | H881: 119000 | I881: 80920 | J881: 108181.82 | K881: 61496 | L881: 61496
A882: 쿠팡 | B882: 12100169248866 | C882: 워커힐 시그니처 양념 본갈비 300g | D882: 쿠팡_미지정 | E882: SKU001 | F882: 1 | G882: 20900 | H882: 20900 | I882: 18183 | J882: 19000 | K882: 7687 | L882: 7687
A883: 쿠팡 | B883: 28100169339326 | C883: 워커힐 시그니처 양념 본갈비 300g | D883: 쿠팡_미지정 | E883: SKU001 | F883: 1 | G883: 20900 | H883: 20900 | I883: 18183 | J883: 19000 | K883: 7687 | L883: 7687
A884: 쿠팡 | B884: 30100169868577 | C884: 워커힐 시그니처 양념 본갈비 300g | D884: 쿠팡_미지정 | E884: SKU001 | F884: 3 | G884: 20900 | H884: 62700 | I884: 54549 | J884: 57000 | K884: 7687 | L884: 23061
...

Sheet 정규화데이터 (2)
A1: 주문번호 | B1: 판매채널 | C1: 주문일 | D1: 판매수량 | E1: 판매가 | F1: 총판매가 | G1: 실정산금액 | H1: 총원가
A2: 20260204818446 | B2: SK스토아 | C2: =DATE(LEFT(TEXT(A2,"0"),4),MID(TEXT(A2,"0"),5,2),MID(TEXT(A2,"0"),7,2)) -> 46057 | D2: 1 | E2: 119000 | F2: 109000 | G2: 82110 | H2: 61496
A3: 20260204842609 | B3: SK스토아 | C3: =DATE(LEFT(TEXT(A3,"0"),4),MID(TEXT(A3,"0"),5,2),MID(TEXT(A3,"0"),7,2)) -> 46057 | D3: 1 | E3: 119000 | F3: 98800 | G3: 82110 | H3: 61496
A4: 20260205994554 | B4: SK스토아 | C4: =DATE(LEFT(TEXT(A4,"0"),4),MID(TEXT(A4,"0"),5,2),MID(TEXT(A4,"0"),7,2)) -> 46058 | D4: -1 | E4: 119000 | F4: -113050 | G4: -82110 | H4: -61496
A5: 20260205994554 | B5: SK스토아 | C5: =DATE(LEFT(TEXT(A5,"0"),4),MID(TEXT(A5,"0"),5,2),MID(TEXT(A5,"0"),7,2)) -> 46058 | D5: 1 | E5: 119000 | F5: 113050 | G5: 82110 | H5: 61496
A6: 20260205974443 | B6: SK스토아 | C6: =DATE(LEFT(TEXT(A6,"0"),4),MID(TEXT(A6,"0"),5,2),MID(TEXT(A6,"0"),7,2)) -> 46058 | D6: 1 | E6: 119000 | F6: 119000 | G6: 82110 | H6: 61496
A7: 20260204816757 | B7: SK스토아 | C7: =DATE(LEFT(TEXT(A7,"0"),4),MID(TEXT(A7,"0"),5,2),MID(TEXT(A7,"0"),7,2)) -> 46057 | D7: 1 | E7: 119000 | F7: 119000 | G7: 82110 | H7: 61496
A8: 20260204838783 | B8: SK스토아 | C8: =DATE(LEFT(TEXT(A8,"0"),4),MID(TEXT(A8,"0"),5,2),MID(TEXT(A8,"0"),7,2)) -> 46057 | D8: 1 | E8: 119000 | F8: 101150 | G8: 82110 | H8: 61496
A9: 20260205993814 | B9: SK스토아 | C9: =DATE(LEFT(TEXT(A9,"0"),4),MID(TEXT(A9,"0"),5,2),MID(TEXT(A9,"0"),7,2)) -> 46058 | D9: 2 | E9: 119000 | F9: 238000 | G9: 164220 | H9: 122992
A10: 20260205994105 | B10: SK스토아 | C10: =DATE(LEFT(TEXT(A10,"0"),4),MID(TEXT(A10,"0"),5,2),MID(TEXT(A10,"0"),7,2)) -> 46058 | D10: 1 | E10: 119000 | F10: 119000 | G10: 82110 | H10: 61496
A11: 20260205995257 | B11: SK스토아 | C11: =DATE(LEFT(TEXT(A11,"0"),4),MID(TEXT(A11,"0"),5,2),MID(TEXT(A11,"0"),7,2)) -> 46058 | D11: 1 | E11: 119000 | F11: 119000 | G11: 82110 | H11: 61496
A12: 20260205993931 | B12: SK스토아 | C12: =DATE(LEFT(TEXT(A12,"0"),4),MID(TEXT(A12,"0"),5,2),MID(TEXT(A12,"0"),7,2)) -> 46058 | D12: 1 | E12: 119000 | F12: 119000 | G12: 82110 | H12: 61496
A13: 20260205992438 | B13: SK스토아 | C13: =DATE(LEFT(TEXT(A13,"0"),4),MID(TEXT(A13,"0"),5,2),MID(TEXT(A13,"0"),7,2)) -> 46058 | D13: 1 | E13: 119000 | F13: 119000 | G13: 82110 | H13: 61496
... A1545: 2.026021e+18 | B1545: 리씽크 | C1545: =DATE(LEFT(TEXT(A1545,"0"),4),MID(TEXT(A1545,"0"),5,2),MID(TEXT(A1545,"0"),7,2)) -> 46063 | D1545: 1 | E1545: 57272.727 | F1545: 63000 | G1545: 63000 | H1545: 30748

Sheet 재고현황
A1: 자사SKU | B1: 제품명 | C1: 기초재고 | D1: 누적판매 | E1: 현재고 | F1: 안전재고 | G1: 재고상태 | H1: 발주수량 | J1: 📦 재고 관리 로직
A2: =제품마스터!A2 -> SKU001 | B2: =제품마스터!B2 -> [워커힐] 시그니처 양념갈비 300G | C2: =제품마스터!E2 -> 25000 | D2: =SUMIF(정규화데이터!$C:$C,$A2,정규화데이터!$G:$G) -> 0 | E2: =C2-D2 -> 25000 | F2: =제품마스터!F2 -> 5000 | G2: =IF(E2<F2,"⚠️ 발주필요",IF(E2<F2*1.5,"⚡ 주의","✅ 정상")) -> ✅ 정상 | H2: =IF(E2<F2,MAX(F2*3-E2,0),"") | J2: 현재고: | K2: 기초재고 - 누적소비수량
J3: 누적판매: | K3: 정규화데이터에서 실제 SKU 소비수량 합계
K4: (세트수량 반영됨)
J5: 재고상태:
J6: 재고상태: | K6: 현재고 < 안전재고
J7: ⚠️ 발주필요 | K7: 현재고 < 안전재고
J8: ⚡ 주의 | K8: 현재고 < 안전재고×1.5
J9: ✅ 정상 | K9: 그 외 정상 재고
J10: 발주수량: | K10: 안전재고의 3배까지 발주
J11: 발주수량: | K11: 안전재고의 3배까지 발주
J12: 사용법: | K12: (현재고 부족 시)
J13: 사용법: | K13: A2:H2를 아래로 복사하면 모든 SKU 자동 계산

Sheet 손익분석
A1: 판매채널 | B1: 주문번호 | C1: 상품명 | D1: 상품코드 | E1: 자사SKU | F1: 판매수량 | G1: 판매가 | H1: 총판매가 | I1: 실정산금액 | J1: VAT제외금액 | K1: 원가 | L1: 총원가 | M1: 공헌이익 | N1: 공헌이익율
A2: =정규화데이터!A2 -> SK스토아 | B2: =정규화데이터!B2 -> 20260204818446 | C2: =정규화데이터!C2 -> [워커힐]워커힐 고메 시그니처 양념 본갈비 8팩 | D2: =정규화데이터!D2 -> 58481090 | E2: =정규화데이터!E2 -> SKU001 | F2: =정규화데이터!F2 -> 1 | G2: =정규화데이터!G2 -> 119000 | H2: =정규화데이터!H2 -> 109000 | ... L2: =정규화데이터!L2 -> 61496 | M2: =J2-L2 -> 37594.909 | N2: =IF(J2=0,0,M2/J2) -> 0.37939817
A3: =정규화데이터!A3 -> SK스토아 | B3: =정규화데이터!B3 -> 20260204842609 | C3: =정규화데이터!C3 -> [워커힐]워커힐 고메 시그니처 양념 본갈비 8팩 | D3: =정규화데이터!D3 -> 58481090 | E3: =정규화데이터!E3 -> SKU001 | F3: =정규화데이터!F3 -> 1 | G3: =정규화데이터!G3 -> 119000 | H3: =정규화데이터!H3 -> 98800 | ... L3: =정규화데이터!L3 -> 61496 | M3: =J3-L3 -> 28322.182 | N3: =IF(J3=0,0,M3/J3) -> 0.31532794
A4: =정규화데이터!A4 -> SK스토아 | B4: =정규화데이터!B4 -> 20260205994554 | C4: =정규화데이터!C4 -> [워커힐]워커힐 고메 시그니처 양념 본갈비 8팩 | D4: =정규화데이터!D4 -> 58481090 | E4: =정규화데이터!E4 -> SKU001 | F4: =정규화데이터!F4 -> -1 | G4: =정규화데이터!G4 -> 119000 | H4: =정규화데이터!H4 -> -113050 | ... L4: =정규화데이터!L4 -> -61496 | M4: =J4-L4 -> -41276.727 | N4: =IF(J4=0,0,M4/J4) -> 0.40163114
A5: =정규화데이터!A5 -> SK스토아 | B5: =정규화데이터!B5 -> 20260205994554 | C5: =정규화데이터!C5 -> [워커힐]워커힐 고메 시그니처 양념 본갈비 8팩 | D5: =정규화데이터!D5 -> 58481090 | E5: =정규화데이터!E5 -> SKU001 | F5: =정규화데이터!F5 -> 1 | G5: =정규화데이터!G5 -> 119000 | H5: =정규화데이터!H5 -> 113050 | ... L5: =정규화데이터!L5 -> 61496 | M5: =J5-L5 -> 41276.727 | N5: =IF(J5=0,0,M5/J5) -> 0.40163114
A6: =정규화데이터!A6 -> SK스토아 | B6: =정규화데이터!B6 -> 20260205974443 | C6: =정규화데이터!C6 -> [워커힐]워커힐 고메 시그니처 양념 본갈비 8팩 | D6: =정규화데이터!D6 -> 58999583 | E6: =정규화데이터!E6 -> SKU001 | F6: =정규화데이터!F6 -> 1 | G6: =정규화데이터!G6 -> 119000 | H6: =정규화데이터!H6 -> 119000 | ... L6: =정규화데이터!L6 -> 61496 | M6: =J6-L6 -> 46685.818 | N6: =IF(J6=0,0,M6/J6) -> 0.43154958
A7: =정규화데이터!A7 -> SK스토아 | B7: =정규화데이터!B7 -> 20260204816757 | C7: =정규화데이터!C7 -> [워커힐]워커힐 고메 시그니처 양념 본갈비 8팩 | D7: =정규화데이터!D7 -> 58999583 | E7: =정규화데이터!E7 -> SKU001 | F7: =정규화데이터!F7 -> 1 | G7: =정규화데이터!G7 -> 119000 | H7: =정규화데이터!H7 -> 119000 | ... L7: =정규화데이터!L7 -> 61496 | M7: =J7-L7 -> 46685.818 | N7: =IF(J7=0,0,M7/J7) -> 0.43154958
A8: =정규화데이터!A8 -> SK스토아 | B8: =정규화데이터!B8 -> 20260204838783 | C8: =정규화데이터!C8 -> [워커힐]워커힐 고메 시그니처 양념 본갈비 8팩 | D8: =정규화데이터!D8 -> 58999583 | E8: =정규화데이터!E8 -> SKU001 | F8: =정규화데이터!F8 -> 1 | G8: =정규화데이터!G8 -> 119000 | H8: =정규화데이터!H8 -> 101150 | ... L8: =정규화데이터!L8 -> 61496 | M8: =J8-L8 -> 30458.545 | N8: =IF(J8=0,0,M8/J8) -> 0.3312348
A9: =정규화데이터!A9 -> SK스토아 | B9: =정규화데이터!B9 -> 20260205993814 | C9: =정규화데이터!C9 -> [워커힐]워커힐 고메 시그니처 양념 본갈비 8팩 | D9: =정규화데이터!D9 -> 58481090 | E9: =정규화데이터!E9 -> SKU001 | F9: =정규화데이터!F9 -> 2 | G9: =정규화데이터!G9 -> 119000 | H9: =정규화데이터!H9 -> 238000 | ... L9: =정규화데이터!L9 -> 122992 | M9: =J9-L9 -> 93371.636 | N9: =IF(J9=0,0,M9/J9) -> 0.43154958
A10: =정규화데이터!A10 -> SK스토아 | B10: =정규화데이터!B10 -> 20260205994105 | C10: =정규화데이터!C10 -> [워커힐]워커힐 고메 시그니처 양념 본갈비 8팩 | D10: =정규화데이터!D10 -> 58481090 | E10: =정규화데이터!E10 -> SKU001 | F10: =정규화데이터!F10 -> 1 | G10: =정규화데이터!G10 -> 119000 | H10: =정규화데이터!H10 -> 119000 | ... L10: =정규화데이터!L10 -> 61496 | M10: =J10-L10 -> 46685.818 | N10: =IF(J10=0,0,M10/J10) -> 0.43154958
A11: =정규화데이터!A11 -> SK스토아 | B11: =정규화데이터!B11 -> 20260205995257 | C11: =정규화데이터!C11 -> [워커힐]워커힐 고메 시그니처 양념 본갈비 8팩 | D11: =정규화데이터!D11 -> 58481090 | E11: =정규화데이터!E11 -> SKU001 | F11: =정규화데이터!F11 -> 1 | G11: =정규화데이터!G11 -> 119000 | H11: =정규화데이터!H11 -> 119000 | ... L11: =정규화데이터!L11 -> 61496 | M11: =J11-L11 -> 46685.818 | N11: =IF(J11=0,0,M11/J11) -> 0.43154958
A12: =정규화데이터!A12 -> SK스토아 | B12: =정규화데이터!B12 -> 20260205993931 | C12: =정규화데이터!C12 -> [워커힐]워커힐 고메 시그니처 양념 본갈비 8팩 | D12: =정규화데이터!D12 -> 58481090 | E12: =정규화데이터!E12 -> SKU001 | F12: =정규화데이터!F12 -> 1 | G12: =정규화데이터!G12 -> 119000 | H12: =정규화데이터!H12 -> 119000 | ... L12: =정규화데이터!L12 -> 61496 | M12: =J12-L12 -> 46685.818 | N12: =IF(J12=0,0,M12/J12) -> 0.43154958
A13: =정규화데이터!A13 -> SK스토아 | B13: =정규화데이터!B13 -> 20260205992438 | C13: =정규화데이터!C13 -> [워커힐]워커힐 고메 시그니처 양념 본갈비 8팩 | D13: =정규화데이터!D13 -> 58481090 | E13: =정규화데이터!E13 -> SKU001 | F13: =정규화데이터!F13 -> 1 | G13: =정규화데이터!G13 -> 119000 | H13: =정규화데이터!H13 -> 119000 | ... L13: =정규화데이터!L13 -> 61496 | M13: =J13-L13 -> 46685.818 | N13: =IF(J13=0,0,M13/J13) -> 0.43154958
... A1545: =정규화데이터!A1545 -> 리씽크 | B1545: =정규화데이터!B1545 -> 2.026021e+18 | C1545: =정규화데이터!C1545 -> 워커힐 본갈비 3+1 최초❤️5만원대! 총1.2kg✨호텔특제 양념갈비 8인분 (✨1인분 7,375원꼴! / [300g,2인분] x 총 4팩 / ✨초이스등급 본갈비 / ❣️워커힐 | D1545: =정규화데이터!D1545 -> 143790 | E1545: =정규화데이터!E1545 -> SKU001 | F1545: =정규화데이터!F1545 -> 1 | G1545: =정규화데이터!G1545 -> 57272.727 | H1545: =정규화데이터!H1545 -> 63000 | ... L1545: =정규화데이터!L1545 -> 30748 | M1545: =J1545-L1545 -> 26524.727 | N1545: =IF(J1545=0,0,M1545/J1545) -> 0.46313016

Sheet 물류비용
A1: 물류사명 | B1: 택배비 | C1: 보관료(1.2%) | D1: 작업료(포장) | E1: 아이스박스/박스 | F1: 아이스팩 | G1: 보냉비닐 | H1: 드라이아이스 | I1: OPP테이프 | J1: 최종수정일 | K1: 비고
A2: 정인 | B2: 2400 | C2: 0 | D2: 1000 | E2: 850 | F2: 100 | G2: 100 | H2: 600 | I2: 0 | J2: 46065 | K2: 현재 사용 중
A4: 📌 사용 안내
A6: 파란색 숫자 | B6: 사용자가 수정 가능한 항목
A8: 💡 계산 방식
A10: 총 물류비 | B10: 택배비 + 작업료 + 아이스박스 + 아이스팩 + 보냉비닐 + 드라이아이스 + OPP테이프

Sheet 원본데이터_쿠팡
A1: 번호 | B1: 묶음배송번호 | C1: 주문번호 | D1: 택배사 | E1: 운송장번호 | F1: 분리배송 Y/N | G1: 분리배송 출고예정일 | H1: 주문시 출고예정일 | I1: 출고일(발송일) | J1: 주문일 | K1: 등록상품명 | L1: 등록옵션명 | M1: 노출상품명(옵션명) | N1: 노출상품ID | O1: 옵션ID | P1: 최초등록등록상품명/옵션명 | Q1: 업체상품코드 | R1: 바코드 | S1: 결제액 | T1: 배송비구분 | U1: 배송비 | V1: 도서산간 추가배송비 | W1: 구매수(수량) | X1: 옵션판매가(판매단가) | Y1: 구매자 | Z1: 구매자전화번호 | AA1: 수취인이름 | AB1: 수취인전화번호 | AC1: 우편번호 | AD1: 수취인 주소 | AE1: 배송메세지 | AF1: 상품별 추가메시지 | AG1: 주문자 추가메시지 | AH1: 배송완료일 | AI1: 구매확정일자 | AJ1: 개인통관번호(PCCC) | AK1: 통관용수취인전화번호 | AL1: 기타 | AM1: 결제위치 | AN1: 배송유형
A2: 1 | B2: 651343802793997 | C2: 12100169248866 | D2: 한진택배 | F2: 분리배송불가 | H2: 46058 | J2: 46057.87 | K2: 워커힐 시그니처 양념 본갈비 300g | L2: 300g 1개 | M2: 워커힐 시그니처 양념 본갈비 300g, 1개 (1개 300g) | N2: 9354612220 | O2: 94659124876 | P2: 워커힐 시그니처 양념 본갈비 300g,300g 1개 | S2: 20900 | T2: 무료 | U2: 0 | V2: 0 | W2: 1 | X2: 20900 | Y2: 이정례 | Z2: 0502-4122-2717 | AA2: 이정례 | AB2: 0502-4122-2717 | AC2: 10021 | AD2: 경기도 김포시 월곶면 용강로57번길 31-5 1층 | AE2: 문 앞 | AM2: 안드로이드앱 | AN2: 판매자 배송
A3: 2 | B3: 651376581296215 | C3: 28100169339326 | D3: 한진택배 | F3: 분리배송불가 | H3: 46058 | J3: 46057.961 | K3: 워커힐 시그니처 양념 본갈비 300g | L3: 300g 1개 | M3: 워커힐 시그니처 양념 본갈비 300g, 1개 (1개 300g) | N3: 9354612220 | O3: 94659124876 | P3: 워커힐 시그니처 양념 본갈비 300g,300g 1개 | S3: 20900 | T3: 무료 | U3: 0 | V3: 0 | W3: 1 | X3: 20900 | Y3: 서은경 | Z3: 0502-1697-1836 | AA3: 서은경 | AB3: 0502-1697-1836 | AC3: 2535 | AD3: 서울특별시 동대문구 한천로37길 33 래미안 엘파인 아파트, 108동 1103호 ( 답십리동, 래미안엘파인아파트 ) | AE3: 문 앞 | AM3: 아이폰앱 | AN3: 판매자 배송
A4: 3 | B4: 651516109013044 | C4: 30100169868577 | D4: 한진택배 | F4: 분리배송불가 | H4: 46059 | J4: 46058.346 | K4: 워커힐 시그니처 양념 본갈비 300g | L4: 300g 1개 | M4: 워커힐 시그니처 양념 본갈비 300g, 1개 (1개 300g) | N4: 9354612220 | O4: 94659124876 | P4: 워커힐 시그니처 양념 본갈비 300g,300g 1개 | S4: 62700 | T4: 무료 | U4: 0 | V4: 0 | W4: 3 | X4: 20900 | Y4: 이미숙 | Z4: 0502-5119-6719 | AA4: 이미숙 | AB4: 0502-5119-6719 | AC4: 31168 | AD4: 충청남도 천안시 서북구 공원로 196 103동2002호 ( 불당동, 펜타포트 ) | AE4: 문 앞 | AM4: 안드로이드앱 | AN4: 판매자 배송
A5: 1 | B5: 651643817082938 | C5: 19100169693948 | D5: 한진택배 | F5: 분리배송불가 | H5: 46062 | J5: 46058.698 | K5: 워커힐 시그니처 양념 본갈비 300g | L5: 300g 1개 | M5: 워커힐 시그니처 양념 본갈비 300g, 1개 (1개 300g) | N5: 9354612220 | O5: 94659124876 | P5: 워커힐 시그니처 양념 본갈비 300g,300g 1개 | S5: 20900 | T5: 무료 | U5: 0 | V5: 0 | W5: 1 | X5: 20900 | Y5: 김원정 | Z5: 0502-5175-0051 | AA5: 김원정 | AB5: 0502-5175-0051 | AC5: 25919 | AD5: 강원특별자치도 삼척시 건지동 173 건지주공아파트 106동 906호 | AE5: 문 앞 | AM5: 안드로이드앱 | AN5: 판매자 배송
A6: 2 | B6: 651742110662698 | C6: 26100169614931 | D6: 한진택배 | F6: 분리배송불가 | H6: 46062 | J6: 46058.969 | K6: 워커힐 시그니처 양념 본갈비 300g | L6: 300g 2개 | M6: 워커힐 시그니처 양념 본갈비 300g, 2개 (2개 300g) | N6: 9354612220 | O6: 94659124877 | P6: 워커힐 시그니처 양념 본갈비 300g,300g 2개 | S6: 40000 | T6: 무료 | U6: 0 | V6: 0 | W6: 1 | X6: 40000 | Y6: 최복임 | Z6: 0502-5169-1516 | AA6: 최복임 | AB6: 0502-5169-1516 | AC6: 1402 | AD6: 서울특별시 도봉구 해등로 118 2동 207호(상아1차 @) ( 창동, 상아1차아파트 ) | AE6: 문 앞 | AM6: 안드로이드앱 | AN6: 판매자 배송
A7: 1 | B7: 652449983266836 | C7: 7100170513612 | D7: 한진택배 | F7: 분리배송불가 | H7: 46064 | J7: 46060.923 | K7: 워커힐 시그니처 양념 본갈비 300g | L7: 300g 4개 | M7: 워커힐 시그니처 양념 본갈비 300g, 4개 (4개 300g) | N7: 9361402632 | O7: 94659124878 | P7: 워커힐 시그니처 양념 본갈비 300g,300g 4개 | S7: 78000 | T7: 무료 | U7: 0 | V7: 0 | W7: 1 | X7: 78000 | Y7: 최명신 | Z7: 0504-1889-4017 | AA7: 최명신 | AB7: 0504-1889-4017 | AC7: 8291 | AD7: 서울특별시 구로구 구로동 1263 신도림롯데아파트 108동 901호 | AE7: 문 앞 | AM7: 아이폰앱 | AN7: 판매자 배송
A8: 2 | B8: 652750438154320 | C8: 32100170207333 | D8: 한진택배 | F8: 분리배송불가 | H8: 46064 | J8: 46061.752 | K8: 워커힐 시그니처 양념 본갈비 300g | L8: 300g 4개 | M8: 워커힐 시그니처 양념 본갈비 300g, 4개 (4개 300g) | N8: 9361402632 | O8: 94659124878 | P8: 워커힐 시그니처 양념 본갈비 300g,300g 4개 | S8: 78000 | T8: 무료 | U8: 0 | V8: 0 | W8: 1 | X8: 78000 | Y8: 함미자 | Z8: 0504-2720-8765 | AA8: 함미자 | AB8: 0504-2720-8765 | AC8: 5209 | AD8: 서울특별시 강동구 아리수로97길 20 강일리버507동901호 ( 강일동, 강일리버파크5단지아파트 ) | AE8: 문 앞 | AM8: 안드로이드앱 | AN8: 판매자 배송
A9: 1 | B9: 653046421766198 | C9: 18100170248996 | D9: 한진택배 | F9: 분리배송불가 | H9: 46064 | J9: 46062.549 | K9: 워커힐 시그니처 양념 본갈비 300g | L9: 300g 2개 | M9: 워커힐 시그니처 양념 본갈비 300g, 2개 (2개 300g) | N9: 9354612220 | O9: 94659124877 | P9: 워커힐 시그니처 양념 본갈비 300g,300g 2개 | S9: 40000 | T9: 무료 | U9: 0 | V9: 0 | W9: 1 | X9: 40000 | Y9: 송현근 | Z9: 0502-5003-2593 | AA9: 송현근 | AB9: 0502-5003-2593 | AC9: 4420 | AD9: 서울특별시 용산구 유엔빌리지길 94 조이하우스 B101호(B1F) 엘레베이터 타시고 지하1층입니다. ( 한남동 ) | AE9: 문 앞 | AM9: PC웹 | AN9: 판매자 배송
A10: 1 | B10: 653459095158797 | C10: 9100170443201 | D10: 한진택배 | F10: 분리배송불가 | H10: 46065 | J10: 46063.707 | K10: 워커힐 시그니처 양념 본갈비 300g | L10: 300g 4개 | M10: 워커힐 시그니처 양념 본갈비 300g, 4개 (4개 300g) | N10: 9361402632 | O10: 94659124878 | P10: 워커힐 시그니처 양념 본갈비 300g,300g 4개 | S10: 78000 | T10: 무료 | U10: 0 | V10: 0 | W10: 1 | X10: 78000 | Y10: 박영애 | Z10: 0502-1688-7274 | AA10: 박영애 | AB10: 0502-1688-7274 | AC10: 3978 | AD10: 서울특별시 마포구 성산동 13-21 예림아너스빌 301호 | AE10: 문 앞 | AM10: 안드로이드앱 | AN10: 판매자 배송
A11: 2 | B11: 653472424656948 | C11: 9100170453124 | D11: 한진택배 | F11: 분리배송불가 | H11: 46065 | J11: 46063.744 | K11: 워커힐 시그니처 양념 본갈비 300g | L11: 300g 4개 | M11: 워커힐 시그니처 양념 본갈비 300g, 4개 (4개 300g) | N11: 9361402632 | O11: 94659124878 | P11: 워커힐 시그니처 양념 본갈비 300g,300g 4개 | S11: 78000 | T11: 무료 | U11: 0 | V11: 0 | W11: 1 | X11: 78000 | Y11: 장경남 | Z11: 0502-1585-1491 | AA11: 장경남 | AB11: 0502-1585-1491 | AC11: 10423 | AD11: 경기도 고양시 일산동구 장항동 877 호수마을3단지아파트 314동902호 | AE11: 문 앞 | AM11: 안드로이드앱 | AN11: 판매자 배송
A12: 3 | B12: 653527206477885 | C12: 16100171241527 | D12: 한진택배 | F12: 분리배송불가 | H12: 46065 | J12: 46063.895 | K12: 워커힐 시그니처 양념 본갈비 300g | L12: 300g 2개 | M12: 워커힐 시그니처 양념 본갈비 300g, 2개 (2개 300g) | N12: 9354612220 | O12: 94659124877 | P12: 워커힐 시그니처 양념 본갈비 300g,300g 2개 | S12: 40000 | T12: 무료 | U12: 0 | V12: 0 | W12: 1 | X12: 40000 | Y12: 이은신 | Z12: 0502-1811-1690 | AA12: 이은신 | AB12: 0502-1811-1690 | AC12: 13928 | AD12: 경기도 안양시 동안구 동편로 80 동편마을204동1004호 ( 관양동, 동편마을2단지 ) | AE12: 도착전에 연락바랍니다 수고하세요 | AM12: 안드로이드앱 | AN12: 판매자 배송
A13: 1 | B13: 653724598698045 | C13: 32100170791524 | D13: 한진택배 | F13: 분리배송불가 | H13: 46066 | J13: 46064.44 | K13: 워커힐 시그니처 양념 본갈비 300g | L13: 300g 4개 | M13: 워커힐 시그니처 양념 본갈비 300g, 4개 (4개 300g) | N13: 9361402632 | O13: 94659124878 | P13: 워커힐 시그니처 양념 본갈비 300g,300g 4개 | S13: 78000 | T13: 무료 | U13: 0 | V13: 0 | W13: 1 | X13: 78000 | Y13: 조현경 | Z13: 0504-1314-8287 | AA13: 조현경 | AB13: 0504-1314-8287 | AC13: 5507 | AD13: 서울 송파구 잠실4동 파크리오아파트 115동204호 | AE13: 문 앞 | AM13: 안드로이드앱 | AN13: 판매자 배송
... A16: 3 | B16: 653823005442088 | C16: 20100171016693 | D16: 한진택배 | F16: 분리배송불가 | H16: 46066 | J16: 46064.712 | K16: 워커힐 시그니처 양념 본갈비 300g | L16: 300g 1개 | M16: 워커힐 시그니처 양념 본갈비 300g, 1개 (1개 300g) | N16: 9361402619 | O16: 94659124876 | P16: 워커힐 시그니처 양념 본갈비 300g,300g 1개 | S16: 20900 | T16: 무료 | U16: 0 | V16: 0 | W16: 1 | X16: 20900 | Y16: 김성옥 | Z16: 0504-3431-5415 | AA16: 김성옥 | AB16: 0504-3431-5415 | AC16: 7291 | AD16: 서울특별시 영등포구 당산동2가 16-1 대우아파트 101동1710호 | AE16: 문 앞 | AM16: 안드로이드앱 | AN16: 판매자 배송

Sheet 원본데이터_네이버
A1: 상품주문번호 | B1: 주문번호 | C1: 배송속성 | D1: 풀필먼트사(주문 기준) | E1: 택배사(주문 기준) | F1: 배송방법(구매자 요청) | G1: 배송방법 | H1: 택배사 | I1: 송장번호 | J1: 발송일 | K1: 판매채널 | L1: 구매자명 | M1: 구매자ID | N1: 수취인명 | O1: 주문상태 | P1: 주문세부상태 | Q1: 수량클레임 여부 | R1: 결제위치 | S1: 결제일 | T1: 상품번호 | U1: 상품명 | V1: 상품종류 | W1: 반품안심케어 | X1: 멤버십N배송 | Y1: 옵션정보 | Z1: 옵션관리코드 | AA1: 수량 | AB1: 옵션가격 | AC1: 상품가격 | AD1: 최종 상품별 할인액 | AE1: 최초 상품별 할인액 | AF1: 판매자 부담 할인액 | AG1: 최종 상품별 총 주문금액 | AH1: 최초 상품별 총 주문금액 | AI1: 사은품 | AJ1: 발주확인일 | AK1: 발송기한 | AL1: 발송처리일 | AM1: 송장출력일 | AN1: 배송비 형태 | AO1: 배송비 묶음번호 | AP1: 배송비 유형 | AQ1: 배송비 합계 | AR1: 제주/도서 추가배송비 | AS1: 배송비 할인액 | AT1: 판매자 상품코드 | AU1: 판매자 내부코드1 | AV1: 판매자 내부코드2 | AW1: 수취인연락처1 | AX1: 수취인연락처2 | AY1: 통합배송지 | AZ1: 기본배송지 | BA1: 상세배송지 | BB1: 구매자연락처 | BC1: 우편번호 | BD1: 배송메세지 | BE1: 출고지 | BF1: 결제수단 | BG1: 네이버페이 주문관리 수수료 | BH1: 매출연동 수수료 | BI1: 정산예정금액 | BJ1: 개인통관고유부호 | BK1: 주문일시 | BL1: 배송희망일 | BM1: 구독신청회차 | BN1: 구독진행회차 | BO1: 구독배송희망일 | BP1: 배송태그 유형 | BQ1: 출입방법 유형 | BR1: 출입방법 내용 | BS1: 수령위치 유형 | BT1: 수령위치 내용
A2: 2.0260206e+15 | B2: 2.0260206e+15 | C2: 일반배송 | E2: 한진택배 | F2: 택배,등기,소포 | G2: 택배,등기,소포 | J2: 46058.38 | K2: 스마트스토어 | L2: 이진우 | M2: jinu**** | N2: 이진우 | O2: 발송대기 | P2: 발주확인 | Q2: N | R2: PC | S2: 46058.379 | T2: 13026511254 | U2: 워커힐 시그니처 양념 본갈비 300g, 2개 | V2: 단일상품 | W2: 비대상 | X2: 비대상 | AA2: 1 | AB2: 0 | AC2: 45800 | AD2: 11900 | AE2: 11900 | AF2: 11900 | AG2: 33900 | AH2: 33900 | AJ2: 46058.38 | AK2: 46064 | AN2: 무료 | AO2: 2.0260205e+15 | AP2: 조건부무료 | AQ2: 0 | AR2: 0 | AS2: 0 | AT2: A2 | AW2: 010-4516-7881 | AY2: 서울특별시 구로구 구로동로47길 24 (구로동, 구로중앙하이츠아파트) 102-906 | AZ2: 서울특별시 구로구 구로동로47길 24 (구로동, 구로중앙하이츠아파트) | BA2: 102-906 | BB2: 010-4516-7881 | BC2: 8279 | BE2: (10318) 경기도 고양시 일산동구 동국로245번길 53 | BF2: 신용카드 간편결제 | BG2: -1230 | BH2: -1017 | BI2: 31653 | BK2: 46058.379
A3: 2.0260206e+15 | B3: 2.0260206e+15 | C3: 일반배송 | E3: 한진택배 | F3: 택배,등기,소포 | G3: 택배,등기,소포 | J3: 46058.38 | K3: 스마트스토어 | L3: 선우동국 | M3: alei**** | N3: 선우동국 | O3: 발송대기 | P3: 발주확인 | Q3: N | R3: PC | S3: 46058.371 | T3: 13026511253 | U3: 워커힐 시그니처 양념 본갈비 300g, 1개 | V3: 단일상품 | W3: 비대상 | X3: 비대상 | AA3: 1 | AB3: 0 | AC3: 22900 | AD3: 5100 | AE3: 5100 | AF3: 5100 | AG3: 17800 | AH3: 17800 | AJ3: 46058.376 | AK3: 46064 | AN3: 무료 | AO3: 2.0260205e+15 | AP3: 조건부무료 | AQ3: 0 | AR3: 0 | AS3: 0 | AT3: A1 | AW3: 010-3090-6765 | AY3: 서울특별시 동대문구 사가정로 190 (전농동, 전농우성아파트) 3동 1103호 | AZ3: 서울특별시 동대문구 사가정로 190 (전농동, 전농우성아파트) | BA3: 3동 1103호 | BB3: 010-3090-6765 | BC3: 2533 | BE3: (10318) 경기도 고양시 일산동구 동국로245번길 53 | BF3: 신용카드 간편결제 | BG3: -646 | BH3: -534 | BI3: 16620 | BK3: 46058.371
A4: 2.0260205e+15 | B4: 2.0260205e+15 | C4: 일반배송 | E4: 한진택배 | F4: 택배,등기,소포 | G4: 택배,등기,소포 | J4: 46058.38 | K4: 스마트스토어 | L4: 서은경 | M4: dmsr***** | N4: 서은경 | O4: 발송대기 | P4: 발주확인 | Q4: N | R4: MOBILE | S4: 46057.952 | T4: 13026511253 | U4: 워커힐 시그니처 양념 본갈비 300g, 1개 | V4: 단일상품 | W4: 비대상 | X4: 비대상 | AA4: 1 | AB4: 0 | AC4: 22900 | AD4: 5100 | AE4: 5100 | AF4: 5100 | AG4: 17800 | AH4: 17800 | AJ4: 46058.376 | AK4: 46063 | AN4: 무료 | AO4: 2.0260204e+15 | AP4: 조건부무료 | AQ4: 0 | AR4: 0 | AS4: 0 | AT4: A1 | AW4: 010-7470-6174 | AY4: 서울특별시 동대문구 한천로37길 33 (답십리동, 래미안엘파인아파트) 108동 1103호 | AZ4: 서울특별시 동대문구 한천로37길 33 (답십리동, 래미안엘파인아파트) | BA4: 108동 1103호 | BB4: 010-7470-6174 | BC4: 2535 | BE4: (10318) 경기도 고양시 일산동구 동국로245번길 53 | BF4: 신용카드 간편결제 | BG4: -646 | BH4: -534 | BI4: 16620 | BK4: 46057.952
A5: 2.0260207e+15 | B5: 2.0260206e+15 | C5: 일반배송 | E5: 한진택배 | F5: 택배,등기,소포 | G5: 택배,등기,소포 | H5: 한진택배 | J5: 46062.377 | K5: 스마트스토어 | L5: 현정화 | M5: kk**** | N5: 현정화 | O5: 발송대기 | P5: 발주확인 | Q5: N | R5: MOBILE | S5: 46059.746 | T5: 13026511254 | U5: 워커힐 시그니처 양념 본갈비 300g, 2개 | V5: 단일상품 | W5: 비대상 | X5: 비대상 | AA5: 1 | AB5: 0 | AC5: 45800 | AD5: 11900 | AE5: 11900 | AF5: 11900 | AG5: 33900 | AH5: 33900 | AJ5: 46062.377 | AK5: 46065 | AN5: 무료 | AO5: 2.0260206e+15 | AP5: 조건부무료 | AQ5: 0 | AR5: 0 | AS5: 0 | AT5: A2 | AW5: 010-8718-8985 | AY5: 경기도 고양시 덕양구 대덕산로 21 (덕은동, DMC자이 더 포레리버뷰) 104동 804호 | AZ5: 경기도 고양시 덕양구 대덕산로 21 (덕은동, DMC자이 더 포레리버뷰) | BA5: 104동 804호 | BB5: 010-8718-8985 | BC5: 10543 | BE5: (10318) 경기도 고양시 일산동구 동국로245번길 53 | BF5: 신용카드 간편결제 | BG5: -1230 | BH5: -1017 | BI5: 31653 | BK5: 46059.746

Sheet 원본데이터_카카오
A1: 결제번호 | B1: 배송지/수신자정보 입력일 | C1: 주문상태 | D1: 주문번호 | E1: 개인통관고유부호 | F1: 채널상품번호 | G1: 상품명 | H1: 옵션 | I1: 수량 | J1: 배송방법 | K1: 택배사코드 | L1: 송장번호 | M1: 수령인명 | N1: 수령인연락처1 | O1: 하이픈포함 수령인연락처1 | P1: 수령인연락처2 | Q1: 하이픈포함 수령인연락처2 | R1: 배송지주소 | S1: 우편번호 | T1: 배송메세지 | U1: 타입 | V1: 발송예정일 | W1: 배송지연출고일 | X1: 주문일 | Y1: 상품금액 | Z1: 옵션금액 | AA1: 판매자할인금액 | AB1: 판매자쿠폰할인금액 | AC1: 정산기준금액 | AD1: 기본수수료 | AE1: 노출추가수수료 | AF1: 추천리워드수수료 | AG1: 수수료할인금액 | AH1: 채널 | AI1: 브랜드 | AJ1: 모델명 | AK1: 판매자상품번호 | AL1: 옵션코드 | AM1: 최초배송비번호 | AN1: 배송비지불방법 | AO1: 기본배송비 유형 | AP1: 기본배송비 금액 | AQ1: 도서산간 추가 배송비 금액 | AR1: 유입경로 | AS1: 톡딜여부 | AT1: 상품유형 | AU1: biz판매여부
A2: 2698095127 | B2: 46064.413 | C2: 301 배송 준비 중 | D2: 3242789909 | F2: 691542495 | G2: 워커힐 시그니처 양념 본갈비 300g, 1개 | I2: 1 | J2: 택배배송 | M2: 서O경 | N2: 1074706174 | O2: 010-7470-6174 | R2: 서울 동대문구 한천로33길 11 (답십리동, 래미안엘파인아파트) 108동 1103호 | S2: 2535 | X2: 46064.413 | Y2: 22900 | Z2: 0 | AA2: 2500 | AB2: 2000 | AC2: 18400 | AD2: 607 | AE2: 0 | AF2: 0 | AG2: 0 | AH2: 톡스토어 | AI2: 워커힐 | AK2: A1 | AM2: 982886524 | AN2: 선불 | AO2: 조건부 무료 | AP2: 0 | AQ2: 0 | AR2: 톡딜 | AT2: 배송 | AU2: -
A3: 2698153034 | B3: 46064.447 | C3: 301 배송 준비 중 | D3: 3242866950 | F3: 691542495 | G3: 워커힐 시그니처 양념 본갈비 300g, 1개 | I3: 2 | J3: 택배배송 | M3: 이O아 | N3: 1075581194 | O3: 010-7558-1194 | R3: 충북 충주시 염밭로 22 (용산동, 남산동일하이빌) 110-603 | S3: 27404 | X3: 46064.447 | Y3: 45800 | Z3: 0 | AA3: 6000 | AB3: 2000 | AC3: 37800 | AD3: 1247 | AE3: 0 | AF3: 0 | AG3: 0 | AH3: 톡스토어 | AI3: 워커힐 | AK3: A1 | AM3: 982914821 | AN3: 선불 | AO3: 조건부 무료 | AP3: 0 | AQ3: 0 | AT3: 배송 | AU3: -
A4: 2698218645 | B4: 46064.486 | C4: 301 배송 준비 중 | D4: 3242952358 | F4: 691542495 | G4: 워커힐 시그니처 양념 본갈비 300g, 1개 | I4: 1 | J4: 택배배송 | M4: 서O경 | N4: 1041786174 | O4: 010-4178-6174 | R4: 서울 동대문구 한천로33길 11 (답십리동, 래미안엘파인아파트) 래미안엘파인108동1103호 | S4: 2535 | X4: 46064.486 | Y4: 22900 | Z4: 0 | AA4: 2000 | AB4: 2000 | AC4: 18900 | AD4: 623 | AE4: 0 | AF4: 0 | AG4: 0 | AH4: 톡스토어 | AI4: 워커힐 | AK4: A1 | AM4: 982946696 | AN4: 선불 | AO4: 조건부 무료 | AP4: 0 | AQ4: 0 | AT4: 배송 | AU4: -
A5: 2698226324 | B5: 46064.491 | C5: 301 배송 준비 중 | D5: 3242962470 | F5: 691542495 | G5: 워커힐 시그니처 양념 본갈비 300g, 1개 | I5: 2 | J5: 택배배송 | M5: 오O미 | N5: 1047130595 | O5: 010-4713-0595 | P5: 1047130595 | Q5: 010-4713-0595 | R5: 충북 충주시 지현천변2길 27-1 (지현동, 태영하이츠타운2차) 8동201호 | S5: 27416 | X5: 46064.491 | Y5: 45800 | Z5: 0 | AA5: 6000 | AB5: 2000 | AC5: 37800 | AD5: 1247 | AE5: 0 | AF5: 0 | AG5: 0 | AH5: 톡스토어 | AI5: 워커힐 | AK5: A1 | AM5: 982950567 | AN5: 선불 | AO5: 조건부 무료 | AP5: 0 | AQ5: 0 | AT5: 배송 | AU5: -
A6: 2698235082 | B6: 46064.497 | C6: 301 배송 준비 중 | D6: 3242973875 | F6: 691542495 | G6: 워커힐 시그니처 양념 본갈비 300g, 1개 | I6: 2 | J6: 택배배송 | M6: 유O옥 | N6: 1033292563 | O6: 010-3329-2563 | R6: 서울 강서구 강서로18가길 7-15 (화곡동, 이수아트빌) 이수아트빌 503호 | S6: 7751 | X6: 46064.497 | Y6: 45800 | Z6: 0 | AA6: 4000 | AB6: 2000 | AC6: 39800 | AD6: 1313 | AE6: 0 | AF6: 0 | AG6: 0 | AH6: 톡스토어 | AI6: 워커힐 | AK6: A1 | AM6: 982954794 | AN6: 선불 | AO6: 조건부 무료 | AP6: 0 | AQ6: 0 | AT6: 배송 | AU6: -

Sheet 원본데이터_리씽크
A1: 주문일 | B1: 주문번호 | C1: 주문자명 | D1: 주문자연락처 | E1: 주문자휴대폰 | F1: 수령인 | G1: 수령인연락처 | H1: 수령인휴대폰 | I1: 우편번호 | J1: 전체주소(도로명) | K1: 전체주소(지번) | L1: 상품명 | M1: (추가) 옵션 | N1: (추가) 정산금액 | O1: 공급가 | P1: 보낼수량 | Q1: 매입가 | R1: 사용자메모 | S1: 상품고유번호 | T1: 출고상품번호 | U1: 택배사 | V1: 운송장번호 | W1: 보낸수량 | X1: 정산금액 | Y1: 매출(vat-) | Z1: 발주일자
A2: 46058.458 | B2: 2.0260205e+18 | C2: 편경화 | D2: 010-6268-4062 | E2: 010-6268-4062 | F2: 편경화 | G2: 010-6268-4062 | H2: 010-6268-4062 | I2: 13993 | J2: 경기 안양시 만안구 안양천서로 357 안양역한양수자인리버파크 101동 2404호 | K2: 경기 안양시 만안구 안양천서로 357 안양역한양수자인리버파크 101동 2404호 | L2: 워커힐 본갈비 3+1 최초❤️5만원대! 총1.2kg✨호텔특제 양념갈비 8인분 (✨1인분 7,375원꼴! / [300g,2인분] x 총 4팩 / ✨초이스등급 본갈비 / ❣️워커힐 특제 비법소스) | M2: ✨1인분 7,375원꼴! / [300g,2인분] x 총 4팩 / ✨초이스등급 본갈비 / ❣️워커힐 특제 비법소스) | N2: 54363 | O2: 45500 | P2: 1 | Q2: 0 | S2: 143790 | T2: OPT-2474637-2720942 | U2: CJ대한통운 | W2: 0 | X2: 45500 | Y2: 41363.636 | Z2: 46058
A3: 46058.447 | B3: 2.0260205e+18 | C3: 정희순 | D3: 010-8509-1977 | E3: 010-8509-1977 | F3: 정희순 | G3: 010-8509-1977 | H3: 010-8509-1977 | I3: 48414 | J3: 부산 남구 전포대로20번길 15 102동 2402호 | K3: 부산 남구 전포대로20번길 15 102동 2402호 | L3: 워커힐 본갈비 3+1 최초❤️5만원대! 총1.2kg✨호텔특제 양념갈비 8인분 (✨1인분 7,375원꼴! / [300g,2인분] x 총 4팩 / ✨초이스등급 본갈비 / ❣️워커힐 특제 비법소스) | M3: ✨1인분 7,375원꼴! / [300g,2인분] x 총 4팩 / ✨초이스등급 본갈비 / ❣️워커힐 특제 비법소스) | N3: 54363 | O3: 45500 | P3: 1 | Q3: 0 | R3: 문 앞에 놔주세요. | S3: 143790 | T3: OPT-2474614-2720917 | U3: CJ대한통운 | W3: 0 | X3: 45500 | Y3: 41363.636 | Z3: 46058
A4: 46058.445 | B4: 2.0260205e+18 | C4: 서경수 | D4: 010-3268-6326 | E4: 010-3268-6326 | F4: 서경수 | G4: 010-3268-6326 | H4: 010-3268-6326 | I4: 22779 | J4: 인천광역시 서구 봉오재1로 49 (신현동, 루원시티루에블리) 806동2203호 | K4: 인천광역시 서구 봉오재1로 49 (신현동, 루원시티루에블리) 806동2203호 | L4: 워커힐 본갈비 3+1 최초❤️5만원대! 총1.2kg✨호텔특제 양념갈비 8인분 (✨1인분 7,375원꼴! / [300g,2인분] x 총 4팩 / ✨초이스등급 본갈비 / ❣️워커힐 특제 비법소스) | M4: ✨1인분 7,375원꼴! / [300g,2인분] x 총 4팩 / ✨초이스등급 본갈비 / ❣️워커힐 특제 비법소스) | N4: 54363 | O4: 45500 | P4: 1 | Q4: 0 | S4: 143790 | T4: OPT-2474611-2720914 | U4: CJ대한통운 | W4: 0 | X4: 45500 | Y4: 41363.636 | Z4: 46058
A5: 46058.436 | B5: 2.0260205e+18 | C5: 유경태 | D5: 010-7104-8919 | E5: 010-7104-8919 | F5: 유경태 | G5: 010-7104-8919 | H5: 010-7104-8919 | I5: 3438 | J5: 서울 은평구 갈현로1길 31 103동701호 | K5: 서울 은평구 갈현로1길 31 103동701호 | L5: 워커힐 본갈비 3+1 최초❤️5만원대! 총1.2kg✨호텔특제 양념갈비 8인분 (✨1인분 7,375원꼴! / [300g,2인분] x 총 4팩 / ✨초이스등급 본갈비 / ❣️워커힐 특제 비법소스) | M5: ✨1인분 7,375원꼴! / [300g,2인분] x 총 4팩 / ✨초이스등급 본갈비 / ❣️워커힐 특제 비법소스) | N5: 54363 | O5: 45500 | P5: 1 | Q5: 0 | S5: 143790 | T5: OPT-2474591-2720893 | U5: CJ대한통운 | W5: 0 | X5: 45500 | Y5: 41363.636 | Z5: 46058
A6: 46058.435 | B6: 2.0260205e+18 | C6: 김남희 | D6: 010-5018-5129 | E6: 010-5018-5129 | F6: 김남희 | G6: 010-5018-5129 | H6: 010-5018-5129 | I6: 31971 | J6: 충남 서산시 부춘2로 47 대림동신아파트 202동1308호 | K6: 충남 서산시 부춘2로 47 대림동신아파트 202동1308호 | L6: 워커힐 본갈비 3+1 최초❤️5만원대! 총1.2kg✨호텔특제 양념갈비 8인분 (✨1인분 7,375원꼴! / [300g,2인분] x 총 4팩 / ✨초이스등급 본갈비 / ❣️워커힐 특제 비법소스) | M6: ✨1인분 7,375원꼴! / [300g,2인분] x 총 4팩 / ✨초이스등급 본갈비 / ❣️워커힐 특제 비법소스) | N6: 54363 | O6: 45500 | P6: 1 | Q6: 0 | S6: 143790 | T6: OPT-2474590-2720892 | U6: CJ대한통운 | W6: 0 | X6: 45500 | Y6: 41363.636 | Z6: 46058
A7: 46058.433 | B7: 2.0260205e+18 | C7: 노 도빈 | D7: 010-5095-3185 | E7: 010-5095-3185 | F7: 노 도빈 | G7: 010-5095-3185 | H7: 010-5095-3185 | I7: 6276 | J7: 서울특별시 강남구 선릉로 221 (도곡동, 도곡렉슬아파트) 212동 201호 | K7: 서울특별시 강남구 선릉로 221 (도곡동, 도곡렉슬아파트) 212동 201호 | L7: 워커힐 본갈비 3+1 최초❤️5만원대! 총1.2kg✨호텔특제 양념갈비 8인분 (✨1인분 7,375원꼴! / [300g,2인분] x 총 4팩 / ✨초이스등급 본갈비 / ❣️워커힐 특제 비법소스) | M7: ✨1인분 7,375원꼴! / [300g,2인분] x 총 4팩 / ✨초이스등급 본갈비 / ❣️워커힐 특제 비법소스) | N7: 54363 | O7: 45500 | P7: 1 | Q7: 0 | S7: 143790 | T7: OPT-2474583-2720885 | U7: CJ대한통운 | W7: 0 | X7: 45500 | Y7: 41363.636 | Z7: 46058
A8: 46058.431 | B8: 2.0260205e+18 | C8: 김인경 | D8: 010-4276-8831 | E8: 010-4276-8831 | F8: 김인경 | G8: 010-4276-8831 | H8: 010-4276-8831 | I8: 13595 | J8: 경기도 성남시 분당구 백현로 105 (수내동) B동 1601 | K8: 경기도 성남시 분당구 백현로 105 (수내동) B동 1601 | L8: 워커힐 본갈비 3+1 최초❤️5만원대! 총1.2kg✨호텔특제 양념갈비 8인분 (✨1인분 7,375원꼴! / [300g,2인분] x 총 4팩 / ✨초이스등급 본갈비 / ❣️워커힐 특제 비법소스) | M8: ✨1인분 7,375원꼴! / [300g,2인분] x 총 4팩 / ✨초이스등급 본갈비 / ❣️워커힐 특제 비법소스) | N8: 108726 | O8: 45500 | P8: 2 | Q8: 0 | S8: 143790 | T8: OPT-2474579-2720881 | U8: CJ대한통운 | W8: 0 | X8: 91000 | Y8: 82727.273 | Z8: 46058
A9: 46058.426 | B9: 2.0260205e+18 | C9: 김성민 | D9: 010-2499-3939 | E9: 010-2499-3939 | F9: 김성민 | G9: 010-2799-5539 | H9: 010-2799-5539 | I9: 4969 | J9: 서울 광진구 아차산로76길 31 102동805호(광장동, 광나루현대아파트) | K9: 서울 광진구 아차산로76길 31 102동805호(광장동, 광나루현대아파트) | L9: 워커힐 본갈비 3+1 최초❤️5만원대! 총1.2kg✨호텔특제 양념갈비 8인분 (✨1인분 7,375원꼴! / [300g,2인분] x 총 4팩 / ✨초이스등급 본갈비 / ❣️워커힐 특제 비법소스) | M9: ✨1인분 7,375원꼴! / [300g,2인분] x 총 4팩 / ✨초이스등급 본갈비 / ❣️워커힐 특제 비법소스) | N9: 54363 | O9: 45500 | P9: 1 | Q9: 0 | R9: 문앞 | S9: 143790 | T9: OPT-2474568-2720870 | U9: CJ대한통운 | W9: 0 | X9: 45500 | Y9: 41363.636 | Z9: 46058
A10: 46058.419 | B10: 2.0260205e+18 | C10: 신현정 | D10: 010-8395-9816 | E10: 010-8395-9816 | F10: 신현정 | G10: 010-8395-9816 | H10: 010-8395-9816 | I10: 2095 | J10: 서울 중랑구 동일로 752 중화한신아파트 105동2106호 | K10: 서울 중랑구 동일로 752 중화한신아파트 105동2106호 | L10: 워커힐 본갈비 3+1 최초❤️5만원대! 총1.2kg✨호텔특제 양념갈비 8인분 (✨1인분 7,375원꼴! / [300g,2인분] x 총 4팩 / ✨초이스등급 본갈비 / ❣️워커힐 특제 비법소스) | M10: ✨1인분 7,375원꼴! / [300g,2인분] x 총 4팩 / ✨초이스등급 본갈비 / ❣️워커힐 특제 비법소스) | N10: 54363 | O10: 45500 | P10: 1 | Q10: 0 | S10: 143790 | T10: OPT-2474500-2720801 | U10: CJ대한통운 | W10: 0 | X10: 45500 | Y10: 41363.636 | Z10: 46058
