Workbook
Name ItemList: [1]제품기본정보!$A$1:$H$144

Sheet 매출요약
B2: · 일자별 실적 현황 (vat-)
B4: 월 | C4: WK | D4: 일자 | E4: TOTAL | G4: SK스토아 | I4: 리씽크 | K4: 스마트스토어 | M4: 쿠팡 | O4: 카카오 | P4: 톡스토어 | Q4: 기타
E5: 매출 | F5: 수량 | G5: 매출 | H5: 수량 | I5: 매출 | J5: 수량 | K5: 매출 | L5: 수량 | M5: 매출 | N5: 수량 | O5: 매출 | P5: 수량 | Q5: 매출 | R5: 수량
E6: =SUM(E7:E34) -> 1.3338109e+08 | F6: =SUM(F7:F34) -> 4268 | G6: =SUM(G7:G34) -> 98870909 | H6: =SUM(H7:H34) -> 918 | I6: =SUM(I7:I34) -> 31487273 | J6: =SUM(J7:J34) -> 3086 | K6: =SUM(K7:K34) -> 94000 | L6: =SUM(L7:L34) -> 6 | ... R6: =SUM(R7:R34) -> 208
B7: 2월 | C7: W5 | D7: 46054 | E7: =SUM(G7,I7,K7,M7,Q7,O7) -> 0 | F7: =SUM(H7,J7,L7,N7,R7,P7) -> 0 | G7: =SUMIF(SK스토아_raw!$AM:$AM,매출요약!$D7,SK스토아_raw!$AQ:$AQ) -> 0 | H7: =SUMIF(SK스토아_raw!$AM:$AM,$D7,SK스토아_raw!$AN:$AN) -> 0 | I7: =SUMIFS(출고요청서_raw!$V:$V,출고요청서_raw!$Q:$Q,매출요약!$D7,출고요청서_raw!$R:$R,매출요약!$I$4) -> 0 | J7: =SUMIFS(출고요청서_raw!$W:$W,출고요청서_raw!$Q:$Q,매출요약!$D7,출고요청서_raw!$R:$R,매출요약!$I$4) -> 0 | K7: =SUMIFS(출고요청서_raw!$V:$V,출고요청서_raw!$Q:$Q,매출요약!$D7,출고요청서_raw!$R:$R,매출요약!$K$4) -> 0 | L7: =SUMIFS(출고요청서_raw!$W:$W,출고요청서_raw!$Q:$Q,매출요약!$D7,출고요청서_raw!$R:$R,매출요약!$K$4) -> 0 | M7: =SUMIFS(출고요청서_raw!$V:$V,출고요청서_raw!$Q:$Q,매출요약!$D7,출고요청서_raw!$R:$R,매출요약!$M$4) -> 0 | N7: =SUMIFS(출고요청서_raw!$W:$W,출고요청서_raw!$Q:$Q,매출요약!$D7,출고요청서_raw!$R:$R,매출요약!$M$4) -> 0 | O7: =SUMIFS(출고요청서_raw!$V:$V,출고요청서_raw!$Q:$Q,매출요약!$D7,출고요청서_raw!$R:$R,매출요약!$O$4) -> 0 | P7: =SUMIFS(출고요청서_raw!$W:$W,출고요청서_raw!$Q:$Q,매출요약!$D7,출고요청서_raw!$R:$R,매출요약!$O$4) -> 0 | Q7: =SUMIFS(출고요청서_raw!$V:$V,출고요청서_raw!$Q:$Q,매출요약!$D7,출고요청서_raw!$R:$R,매출요약!$Q$4) -> 0 | R7: =SUMIFS(출고요청서_raw!$W:$W,출고요청서_raw!$Q:$Q,매출요약!$D7,출고요청서_raw!$R:$R,매출요약!$Q$4) -> 0
C8: W6 | D8: 46055 | E8: =SUM(G8,I8,K8,M8,Q8,O8) -> 0 | F8: =SUM(H8,J8,L8,N8,R8,P8) -> 0 | G8: =SUMIF(SK스토아_raw!$AM:$AM,매출요약!$D8,SK스토아_raw!$AQ:$AQ) -> 0 | H8: =SUMIF(SK스토아_raw!$AM:$AM,$D8,SK스토아_raw!$AN:$AN) -> 0 | I8: =SUMIFS(출고요청서_raw!$V:$V,출고요청서_raw!$Q:$Q,매출요약!$D8,출고요청서_raw!$R:$R,매출요약!$I$4) -> 0 | J8: =SUMIFS(출고요청서_raw!$W:$W,출고요청서_raw!$Q:$Q,매출요약!$D8,출고요청서_raw!$R:$R,매출요약!$I$4) -> 0 | K8: =SUMIFS(출고요청서_raw!$V:$V,출고요청서_raw!$Q:$Q,매출요약!$D8,출고요청서_raw!$R:$R,매출요약!$K$4) -> 0 | L8: =SUMIFS(출고요청서_raw!$W:$W,출고요청서_raw!$Q:$Q,매출요약!$D8,출고요청서_raw!$R:$R,매출요약!$K$4) -> 0 | M8: =SUMIFS(출고요청서_raw!$V:$V,출고요청서_raw!$Q:$Q,매출요약!$D8,출고요청서_raw!$R:$R,매출요약!$M$4) -> 0 | N8: =SUMIFS(출고요청서_raw!$W:$W,출고요청서_raw!$Q:$Q,매출요약!$D8,출고요청서_raw!$R:$R,매출요약!$M$4) -> 0 | O8: =SUMIFS(출고요청서_raw!$V:$V,출고요청서_raw!$Q:$Q,매출요약!$D8,출고요청서_raw!$R:$R,매출요약!$O$4) -> 0 | P8: =SUMIFS(출고요청서_raw!$W:$W,출고요청서_raw!$Q:$Q,매출요약!$D8,출고요청서_raw!$R:$R,매출요약!$O$4) -> 0 | Q8: =SUMIFS(출고요청서_raw!$V:$V,출고요청서_raw!$Q:$Q,매출요약!$D8,출고요청서_raw!$R:$R,매출요약!$Q$4) -> 0 | R8: =SUMIFS(출고요청서_raw!$W:$W,출고요청서_raw!$Q:$Q,매출요약!$D8,출고요청서_raw!$R:$R,매출요약!$Q$4) -> 0
D9: 46056 | E9: =SUM(G9,I9,K9,M9,Q9,O9) -> 0 | F9: =SUM(H9,J9,L9,N9,R9,P9) -> 0 | G9: =SUMIF(SK스토아_raw!$AM:$AM,매출요약!$D9,SK스토아_raw!$AQ:$AQ) -> 0 | H9: =SUMIF(SK스토아_raw!$AM:$AM,$D9,SK스토아_raw!$AN:$AN) -> 0 | I9: =SUMIFS(출고요청서_raw!$V:$V,출고요청서_raw!$Q:$Q,매출요약!$D9,출고요청서_raw!$R:$R,매출요약!$I$4) -> 0 | J9: =SUMIFS(출고요청서_raw!$W:$W,출고요청서_raw!$Q:$Q,매출요약!$D9,출고요청서_raw!$R:$R,매출요약!$I$4) -> 0 | K9: =SUMIFS(출고요청서_raw!$V:$V,출고요청서_raw!$Q:$Q,매출요약!$D9,출고요청서_raw!$R:$R,매출요약!$K$4) -> 0 | L9: =SUMIFS(출고요청서_raw!$W:$W,출고요청서_raw!$Q:$Q,매출요약!$D9,출고요청서_raw!$R:$R,매출요약!$K$4) -> 0 | M9: =SUMIFS(출고요청서_raw!$V:$V,출고요청서_raw!$Q:$Q,매출요약!$D9,출고요청서_raw!$R:$R,매출요약!$M$4) -> 0 | N9: =SUMIFS(출고요청서_raw!$W:$W,출고요청서_raw!$Q:$Q,매출요약!$D9,출고요청서_raw!$R:$R,매출요약!$M$4) -> 0 | O9: =SUMIFS(출고요청서_raw!$V:$V,출고요청서_raw!$Q:$Q,매출요약!$D9,출고요청서_raw!$R:$R,매출요약!$O$4) -> 0 | P9: =SUMIFS(출고요청서_raw!$W:$W,출고요청서_raw!$Q:$Q,매출요약!$D9,출고요청서_raw!$R:$R,매출요약!$O$4) -> 0 | Q9: =SUMIFS(출고요청서_raw!$V:$V,출고요청서_raw!$Q:$Q,매출요약!$D9,출고요청서_raw!$R:$R,매출요약!$Q$4) -> 0 | R9: =SUMIFS(출고요청서_raw!$W:$W,출고요청서_raw!$Q:$Q,매출요약!$D9,출고요청서_raw!$R:$R,매출요약!$Q$4) -> 0
D10: 46057 | E10: =SUM(G10,I10,K10,M10,Q10,O10) -> 0 | F10: =SUM(H10,J10,L10,N10,R10,P10) -> 0 | G10: =SUMIF(SK스토아_raw!$AM:$AM,매출요약!$D10,SK스토아_raw!$AQ:$AQ) -> 0 | H10: =SUMIF(SK스토아_raw!$AM:$AM,$D10,SK스토아_raw!$AN:$AN) -> 0 | I10: =SUMIFS(출고요청서_raw!$V:$V,출고요청서_raw!$Q:$Q,매출요약!$D10,출고요청서_raw!$R:$R,매출요약!$I$4) -> 0 | J10: =SUMIFS(출고요청서_raw!$W:$W,출고요청서_raw!$Q:$Q,매출요약!$D10,출고요청서_raw!$R:$R,매출요약!$I$4) -> 0 | K10: =SUMIFS(출고요청서_raw!$V:$V,출고요청서_raw!$Q:$Q,매출요약!$D10,출고요청서_raw!$R:$R,매출요약!$K$4) -> 0 | L10: =SUMIFS(출고요청서_raw!$W:$W,출고요청서_raw!$Q:$Q,매출요약!$D10,출고요청서_raw!$R:$R,매출요약!$K$4) -> 0 | M10: =SUMIFS(출고요청서_raw!$V:$V,출고요청서_raw!$Q:$Q,매출요약!$D10,출고요청서_raw!$R:$R,매출요약!$M$4) -> 0 | N10: =SUMIFS(출고요청서_raw!$W:$W,출고요청서_raw!$Q:$Q,매출요약!$D10,출고요청서_raw!$R:$R,매출요약!$M$4) -> 0 | O10: =SUMIFS(출고요청서_raw!$V:$V,출고요청서_raw!$Q:$Q,매출요약!$D10,출고요청서_raw!$R:$R,매출요약!$O$4) -> 0 | P10: =SUMIFS(출고요청서_raw!$W:$W,출고요청서_raw!$Q:$Q,매출요약!$D10,출고요청서_raw!$R:$R,매출요약!$O$4) -> 0 | Q10: =SUMIFS(출고요청서_raw!$V:$V,출고요청서_raw!$Q:$Q,매출요약!$D10,출고요청서_raw!$R:$R,매출요약!$Q$4) -> 0 | R10: =SUMIFS(출고요청서_raw!$W:$W,출고요청서_raw!$Q:$Q,매출요약!$D10,출고요청서_raw!$R:$R,매출요약!$Q$4) -> 0
D11: 46058 | E11: =SUM(G11,I11,K11,M11,Q11,O11) -> 13366091 | F11: =SUM(H11,J11,L11,N11,R11,P11) -> 1303 | G11: =SUMIF(SK스토아_raw!$AM:$AM,매출요약!$D11,SK스토아_raw!$AQ:$AQ) -> 0 | H11: =SUMIF(SK스토아_raw!$AM:$AM,$D11,SK스토아_raw!$AN:$AN) -> 0 | I11: =SUMIFS(출고요청서_raw!$V:$V,출고요청서_raw!$Q:$Q,매출요약!$D11,출고요청서_raw!$R:$R,매출요약!$I$4) -> 12644545 | J11: =SUMIFS(출고요청서_raw!$W:$W,출고요청서_raw!$Q:$Q,매출요약!$D11,출고요청서_raw!$R:$R,매출요약!$I$4) -> 1238 | K11: =SUMIFS(출고요청서_raw!$V:$V,출고요청서_raw!$Q:$Q,매출요약!$D11,출고요청서_raw!$R:$R,매출요약!$K$4) -> 63181.818 | L11: =SUMIFS(출고요청서_raw!$W:$W,출고요청서_raw!$Q:$Q,매출요약!$D11,출고요청서_raw!$R:$R,매출요약!$K$4) -> 4 | M11: =SUMIFS(출고요청서_raw!$V:$V,출고요청서_raw!$Q:$Q,매출요약!$D11,출고요청서_raw!$R:$R,매출요약!$M$4) -> 92000 | N11: =SUMIFS(출고요청서_raw!$W:$W,출고요청서_raw!$Q:$Q,매출요약!$D11,출고요청서_raw!$R:$R,매출요약!$M$4) -> 5 | O11: =SUMIFS(출고요청서_raw!$V:$V,출고요청서_raw!$Q:$Q,매출요약!$D11,출고요청서_raw!$R:$R,매출요약!$O$4) -> 0 | P11: =SUMIFS(출고요청서_raw!$W:$W,출고요청서_raw!$Q:$Q,매출요약!$D11,출고요청서_raw!$R:$R,매출요약!$O$4) -> 0 | Q11: =SUMIFS(출고요청서_raw!$V:$V,출고요청서_raw!$Q:$Q,매출요약!$D11,출고요청서_raw!$R:$R,매출요약!$Q$4) -> 566363.64 | R11: =SUMIFS(출고요청서_raw!$W:$W,출고요청서_raw!$Q:$Q,매출요약!$D11,출고요청서_raw!$R:$R,매출요약!$Q$4) -> 56
D12: 46059 | E12: =SUM(G12,I12,K12,M12,Q12,O12) -> 7311090.9 | F12: =SUM(H12,J12,L12,N12,R12,P12) -> 655 | G12: =SUMIF(SK스토아_raw!$AM:$AM,매출요약!$D12,SK스토아_raw!$AQ:$AQ) -> 649090.91 | H12: =SUMIF(SK스토아_raw!$AM:$AM,$D12,SK스토아_raw!$AN:$AN) -> 6 | I12: =SUMIFS(출고요청서_raw!$V:$V,출고요청서_raw!$Q:$Q,매출요약!$D12,출고요청서_raw!$R:$R,매출요약!$I$4) -> 5883181.8 | J12: =SUMIFS(출고요청서_raw!$W:$W,출고요청서_raw!$Q:$Q,매출요약!$D12,출고요청서_raw!$R:$R,매출요약!$I$4) -> 574 | K12: =SUMIFS(출고요청서_raw!$V:$V,출고요청서_raw!$Q:$Q,매출요약!$D12,출고요청서_raw!$R:$R,매출요약!$K$4) -> 0 | L12: =SUMIFS(출고요청서_raw!$W:$W,출고요청서_raw!$Q:$Q,매출요약!$D12,출고요청서_raw!$R:$R,매출요약!$K$4) -> 0 | M12: =SUMIFS(출고요청서_raw!$V:$V,출고요청서_raw!$Q:$Q,매출요약!$D12,출고요청서_raw!$R:$R,매출요약!$M$4) -> 50636.364 | N12: =SUMIFS(출고요청서_raw!$W:$W,출고요청서_raw!$Q:$Q,매출요약!$D12,출고요청서_raw!$R:$R,매출요약!$M$4) -> 3 | O12: =SUMIFS(출고요청서_raw!$V:$V,출고요청서_raw!$Q:$Q,매출요약!$D12,출고요청서_raw!$R:$R,매출요약!$O$4) -> 0 | P12: =SUMIFS(출고요청서_raw!$W:$W,출고요청서_raw!$Q:$Q,매출요약!$D12,출고요청서_raw!$R:$R,매출요약!$O$4) -> 0 | Q12: =SUMIFS(출고요청서_raw!$V:$V,출고요청서_raw!$Q:$Q,매출요약!$D12,출고요청서_raw!$R:$R,매출요약!$Q$4) -> 728181.82 | R12: =SUMIFS(출고요청서_raw!$W:$W,출고요청서_raw!$Q:$Q,매출요약!$D12,출고요청서_raw!$R:$R,매출요약!$Q$4) -> 72
D13: 46060 | E13: =SUM(G13,I13,K13,M13,Q13,O13) -> 47130000 | F13: =SUM(H13,J13,L13,N13,R13,P13) -> 436 | G13: =SUMIF(SK스토아_raw!$AM:$AM,매출요약!$D13,SK스토아_raw!$AQ:$AQ) -> 47130000 | H13: =SUMIF(SK스토아_raw!$AM:$AM,$D13,SK스토아_raw!$AN:$AN) -> 436 | I13: =SUMIFS(출고요청서_raw!$V:$V,출고요청서_raw!$Q:$Q,매출요약!$D13,출고요청서_raw!$R:$R,매출요약!$I$4) -> 0 | J13: =SUMIFS(출고요청서_raw!$W:$W,출고요청서_raw!$Q:$Q,매출요약!$D13,출고요청서_raw!$R:$R,매출요약!$I$4) -> 0 | K13: =SUMIFS(출고요청서_raw!$V:$V,출고요청서_raw!$Q:$Q,매출요약!$D13,출고요청서_raw!$R:$R,매출요약!$K$4) -> 0 | L13: =SUMIFS(출고요청서_raw!$W:$W,출고요청서_raw!$Q:$Q,매출요약!$D13,출고요청서_raw!$R:$R,매출요약!$K$4) -> 0 | M13: =SUMIFS(출고요청서_raw!$V:$V,출고요청서_raw!$Q:$Q,매출요약!$D13,출고요청서_raw!$R:$R,매출요약!$M$4) -> 0 | N13: =SUMIFS(출고요청서_raw!$W:$W,출고요청서_raw!$Q:$Q,매출요약!$D13,출고요청서_raw!$R:$R,매출요약!$M$4) -> 0 | O13: =SUMIFS(출고요청서_raw!$V:$V,출고요청서_raw!$Q:$Q,매출요약!$D13,출고요청서_raw!$R:$R,매출요약!$O$4) -> 0 | P13: =SUMIFS(출고요청서_raw!$W:$W,출고요청서_raw!$Q:$Q,매출요약!$D13,출고요청서_raw!$R:$R,매출요약!$O$4) -> 0 | Q13: =SUMIFS(출고요청서_raw!$V:$V,출고요청서_raw!$Q:$Q,매출요약!$D13,출고요청서_raw!$R:$R,매출요약!$Q$4) -> 0 | R13: =SUMIFS(출고요청서_raw!$W:$W,출고요청서_raw!$Q:$Q,매출요약!$D13,출고요청서_raw!$R:$R,매출요약!$Q$4) -> 0
D14: 46061 | E14: =SUM(G14,I14,K14,M14,Q14,O14) -> 216363.64 | F14: =SUM(H14,J14,L14,N14,R14,P14) -> 2 | G14: =SUMIF(SK스토아_raw!$AM:$AM,매출요약!$D14,SK스토아_raw!$AQ:$AQ) -> 216363.64 | H14: =SUMIF(SK스토아_raw!$AM:$AM,$D14,SK스토아_raw!$AN:$AN) -> 2 | I14: =SUMIFS(출고요청서_raw!$V:$V,출고요청서_raw!$Q:$Q,매출요약!$D14,출고요청서_raw!$R:$R,매출요약!$I$4) -> 0 | J14: =SUMIFS(출고요청서_raw!$W:$W,출고요청서_raw!$Q:$Q,매출요약!$D14,출고요청서_raw!$R:$R,매출요약!$I$4) -> 0 | K14: =SUMIFS(출고요청서_raw!$V:$V,출고요청서_raw!$Q:$Q,매출요약!$D14,출고요청서_raw!$R:$R,매출요약!$K$4) -> 0 | L14: =SUMIFS(출고요청서_raw!$W:$W,출고요청서_raw!$Q:$Q,매출요약!$D14,출고요청서_raw!$R:$R,매출요약!$K$4) -> 0 | M14: =SUMIFS(출고요청서_raw!$V:$V,출고요청서_raw!$Q:$Q,매출요약!$D14,출고요청서_raw!$R:$R,매출요약!$M$4) -> 0 | N14: =SUMIFS(출고요청서_raw!$W:$W,출고요청서_raw!$Q:$Q,매출요약!$D14,출고요청서_raw!$R:$R,매출요약!$M$4) -> 0 | O14: =SUMIFS(출고요청서_raw!$V:$V,출고요청서_raw!$Q:$Q,매출요약!$D14,출고요청서_raw!$R:$R,매출요약!$O$4) -> 0 | P14: =SUMIFS(출고요청서_raw!$W:$W,출고요청서_raw!$Q:$Q,매출요약!$D14,출고요청서_raw!$R:$R,매출요약!$O$4) -> 0 | Q14: =SUMIFS(출고요청서_raw!$V:$V,출고요청서_raw!$Q:$Q,매출요약!$D14,출고요청서_raw!$R:$R,매출요약!$Q$4) -> 0 | R14: =SUMIFS(출고요청서_raw!$W:$W,출고요청서_raw!$Q:$Q,매출요약!$D14,출고요청서_raw!$R:$R,매출요약!$Q$4) -> 0
C15: W7 | D15: 46062 | E15: =SUM(G15,I15,K15,M15,Q15,O15) -> 9154363.6 | F15: =SUM(H15,J15,L15,N15,R15,P15) -> 894 | G15: =SUMIF(SK스토아_raw!$AM:$AM,매출요약!$D15,SK스토아_raw!$AQ:$AQ) -> 0 | H15: =SUMIF(SK스토아_raw!$AM:$AM,$D15,SK스토아_raw!$AN:$AN) -> 0 | I15: =SUMIFS(출고요청서_raw!$V:$V,출고요청서_raw!$Q:$Q,매출요약!$D15,출고요청서_raw!$R:$R,매출요약!$I$4) -> 8972727.3 | J15: =SUMIFS(출고요청서_raw!$W:$W,출고요청서_raw!$Q:$Q,매출요약!$D15,출고요청서_raw!$R:$R,매출요약!$I$4) -> 882 | K15: =SUMIFS(출고요청서_raw!$V:$V,출고요청서_raw!$Q:$Q,매출요약!$D15,출고요청서_raw!$R:$R,매출요약!$K$4) -> 30818.182 | L15: =SUMIFS(출고요청서_raw!$W:$W,출고요청서_raw!$Q:$Q,매출요약!$D15,출고요청서_raw!$R:$R,매출요약!$K$4) -> 2 | M15: =SUMIFS(출고요청서_raw!$V:$V,출고요청서_raw!$Q:$Q,매출요약!$D15,출고요청서_raw!$R:$R,매출요약!$M$4) -> 150818.18 | N15: =SUMIFS(출고요청서_raw!$W:$W,출고요청서_raw!$Q:$Q,매출요약!$D15,출고요청서_raw!$R:$R,매출요약!$M$4) -> 10 | O15: =SUMIFS(출고요청서_raw!$V:$V,출고요청서_raw!$Q:$Q,매출요약!$D15,출고요청서_raw!$R:$R,매출요약!$O$4) -> 0 | P15: =SUMIFS(출고요청서_raw!$W:$W,출고요청서_raw!$Q:$Q,매출요약!$D15,출고요청서_raw!$R:$R,매출요약!$O$4) -> 0 | Q15: =SUMIFS(출고요청서_raw!$V:$V,출고요청서_raw!$Q:$Q,매출요약!$D15,출고요청서_raw!$R:$R,매출요약!$Q$4) -> 0 | R15: =SUMIFS(출고요청서_raw!$W:$W,출고요청서_raw!$Q:$Q,매출요약!$D15,출고요청서_raw!$R:$R,매출요약!$Q$4) -> 0
D16: 46063 | E16: =SUM(G16,I16,K16,M16,Q16,O16) -> 6286818.2 | F16: =SUM(H16,J16,L16,N16,R16,P16) -> 264 | G16: =SUMIF(SK스토아_raw!$AM:$AM,매출요약!$D16,SK스토아_raw!$AQ:$AQ) -> 3999090.9 | H16: =SUMIF(SK스토아_raw!$AM:$AM,$D16,SK스토아_raw!$AN:$AN) -> 40 | I16: =SUMIFS(출고요청서_raw!$V:$V,출고요청서_raw!$Q:$Q,매출요약!$D16,출고요청서_raw!$R:$R,매출요약!$I$4) -> 2287727.3 | J16: =SUMIFS(출고요청서_raw!$W:$W,출고요청서_raw!$Q:$Q,매출요약!$D16,출고요청서_raw!$R:$R,매출요약!$I$4) -> 224 | K16: =SUMIFS(출고요청서_raw!$V:$V,출고요청서_raw!$Q:$Q,매출요약!$D16,출고요청서_raw!$R:$R,매출요약!$K$4) -> 0 | L16: =SUMIFS(출고요청서_raw!$W:$W,출고요청서_raw!$Q:$Q,매출요약!$D16,출고요청서_raw!$R:$R,매출요약!$K$4) -> 0 | M16: =SUMIFS(출고요청서_raw!$V:$V,출고요청서_raw!$Q:$Q,매출요약!$D16,출고요청서_raw!$R:$R,매출요약!$M$4) -> 0 | N16: =SUMIFS(출고요청서_raw!$W:$W,출고요청서_raw!$Q:$Q,매출요약!$D16,출고요청서_raw!$R:$R,매출요약!$M$4) -> 0 | O16: =SUMIFS(출고요청서_raw!$V:$V,출고요청서_raw!$Q:$Q,매출요약!$D16,출고요청서_raw!$R:$R,매출요약!$O$4) -> 0 | P16: =SUMIFS(출고요청서_raw!$W:$W,출고요청서_raw!$Q:$Q,매출요약!$D16,출고요청서_raw!$R:$R,매출요약!$O$4) -> 0 | Q16: =SUMIFS(출고요청서_raw!$V:$V,출고요청서_raw!$Q:$Q,매출요약!$D16,출고요청서_raw!$R:$R,매출요약!$Q$4) -> 0 | R16: =SUMIFS(출고요청서_raw!$W:$W,출고요청서_raw!$Q:$Q,매출요약!$D16,출고요청서_raw!$R:$R,매출요약!$Q$4) -> 0
D17: 46064 | E17: =SUM(G17,I17,K17,M17,Q17,O17) -> 4035545.5 | F17: =SUM(H17,J17,L17,N17,R17,P17) -> 219 | G17: =SUMIF(SK스토아_raw!$AM:$AM,매출요약!$D17,SK스토아_raw!$AQ:$AQ) -> 1910000 | H17: =SUMIF(SK스토아_raw!$AM:$AM,$D17,SK스토아_raw!$AN:$AN) -> 18 | I17: =SUMIFS(출고요청서_raw!$V:$V,출고요청서_raw!$Q:$Q,매출요약!$D17,출고요청서_raw!$R:$R,매출요약!$I$4) -> 1699090.9 | J17: =SUMIFS(출고요청서_raw!$W:$W,출고요청서_raw!$Q:$Q,매출요약!$D17,출고요청서_raw!$R:$R,매출요약!$I$4) -> 168 | K17: =SUMIFS(출고요청서_raw!$V:$V,출고요청서_raw!$Q:$Q,매출요약!$D17,출고요청서_raw!$R:$R,매출요약!$K$4) -> 0 | L17: =SUMIFS(출고요청서_raw!$W:$W,출고요청서_raw!$Q:$Q,매출요약!$D17,출고요청서_raw!$R:$R,매출요약!$K$4) -> 0 | M17: =SUMIFS(출고요청서_raw!$V:$V,출고요청서_raw!$Q:$Q,매출요약!$D17,출고요청서_raw!$R:$R,매출요약!$M$4) -> 209909.09 | N17: =SUMIFS(출고요청서_raw!$W:$W,출고요청서_raw!$Q:$Q,매출요약!$D17,출고요청서_raw!$R:$R,매출요약!$M$4) -> 14 | O17: =SUMIFS(출고요청서_raw!$V:$V,출고요청서_raw!$Q:$Q,매출요약!$D17,출고요청서_raw!$R:$R,매출요약!$O$4) -> 54727.273 | P17: =SUMIFS(출고요청서_raw!$W:$W,출고요청서_raw!$Q:$Q,매출요약!$D17,출고요청서_raw!$R:$R,매출요약!$O$4) -> 3 | Q17: =SUMIFS(출고요청서_raw!$V:$V,출고요청서_raw!$Q:$Q,매출요약!$D17,출고요청서_raw!$R:$R,매출요약!$Q$4) -> 161818.18 | R17: =SUMIFS(출고요청서_raw!$W:$W,출고요청서_raw!$Q:$Q,매출요약!$D17,출고요청서_raw!$R:$R,매출요약!$Q$4) -> 16
D18: 46065 | E18: =SUM(G18,I18,K18,M18,Q18,O18) -> 43051000 | F18: =SUM(H18,J18,L18,N18,R18,P18) -> 466 | G18: =SUMIF(SK스토아_raw!$AM:$AM,매출요약!$D18,SK스토아_raw!$AQ:$AQ) -> 42190909 | H18: =SUMIF(SK스토아_raw!$AM:$AM,$D18,SK스토아_raw!$AN:$AN) -> 390 | I18: =SUMIFS(출고요청서_raw!$V:$V,출고요청서_raw!$Q:$Q,매출요약!$D18,출고요청서_raw!$R:$R,매출요약!$I$4) -> 0 | J18: =SUMIFS(출고요청서_raw!$W:$W,출고요청서_raw!$Q:$Q,매출요약!$D18,출고요청서_raw!$R:$R,매출요약!$I$4) -> 0 | K18: =SUMIFS(출고요청서_raw!$V:$V,출고요청서_raw!$Q:$Q,매출요약!$D18,출고요청서_raw!$R:$R,매출요약!$K$4) -> 0 | L18: =SUMIFS(출고요청서_raw!$W:$W,출고요청서_raw!$Q:$Q,매출요약!$D18,출고요청서_raw!$R:$R,매출요약!$K$4) -> 0 | M18: =SUMIFS(출고요청서_raw!$V:$V,출고요청서_raw!$Q:$Q,매출요약!$D18,출고요청서_raw!$R:$R,매출요약!$M$4) -> 119636.36 | N18: =SUMIFS(출고요청서_raw!$W:$W,출고요청서_raw!$Q:$Q,매출요약!$D18,출고요청서_raw!$R:$R,매출요약!$M$4) -> 7 | O18: =SUMIFS(출고요청서_raw!$V:$V,출고요청서_raw!$Q:$Q,매출요약!$D18,출고요청서_raw!$R:$R,매출요약!$O$4) -> 93181.818 | P18: =SUMIFS(출고요청서_raw!$W:$W,출고요청서_raw!$Q:$Q,매출요약!$D18,출고요청서_raw!$R:$R,매출요약!$O$4) -> 5 | Q18: =SUMIFS(출고요청서_raw!$V:$V,출고요청서_raw!$Q:$Q,매출요약!$D18,출고요청서_raw!$R:$R,매출요약!$Q$4) -> 647272.73 | R18: =SUMIFS(출고요청서_raw!$W:$W,출고요청서_raw!$Q:$Q,매출요약!$D18,출고요청서_raw!$R:$R,매출요약!$Q$4) -> 64
D19: 46066 | E19: =SUM(G19,I19,K19,M19,Q19,O19) -> 2667272.7 | F19: =SUM(H19,J19,L19,N19,R19,P19) -> 25 | G19: =SUMIF(SK스토아_raw!$AM:$AM,매출요약!$D19,SK스토아_raw!$AQ:$AQ) -> 2667272.7 | H19: =SUMIF(SK스토아_raw!$AM:$AM,$D19,SK스토아_raw!$AN:$AN) -> 25 | I19: =SUMIFS(출고요청서_raw!$V:$V,출고요청서_raw!$Q:$Q,매출요약!$D19,출고요청서_raw!$R:$R,매출요약!$I$4) -> 0 | J19: =SUMIFS(출고요청서_raw!$W:$W,출고요청서_raw!$Q:$Q,매출요약!$D19,출고요청서_raw!$R:$R,매출요약!$I$4) -> 0 | K19: =SUMIFS(출고요청서_raw!$V:$V,출고요청서_raw!$Q:$Q,매출요약!$D19,출고요청서_raw!$R:$R,매출요약!$K$4) -> 0 | L19: =SUMIFS(출고요청서_raw!$W:$W,출고요청서_raw!$Q:$Q,매출요약!$D19,출고요청서_raw!$R:$R,매출요약!$K$4) -> 0 | M19: =SUMIFS(출고요청서_raw!$V:$V,출고요청서_raw!$Q:$Q,매출요약!$D19,출고요청서_raw!$R:$R,매출요약!$M$4) -> 0 | N19: =SUMIFS(출고요청서_raw!$W:$W,출고요청서_raw!$Q:$Q,매출요약!$D19,출고요청서_raw!$R:$R,매출요약!$M$4) -> 0 | O19: =SUMIFS(출고요청서_raw!$V:$V,출고요청서_raw!$Q:$Q,매출요약!$D19,출고요청서_raw!$R:$R,매출요약!$O$4) -> 0 | P19: =SUMIFS(출고요청서_raw!$W:$W,출고요청서_raw!$Q:$Q,매출요약!$D19,출고요청서_raw!$R:$R,매출요약!$O$4) -> 0 | Q19: =SUMIFS(출고요청서_raw!$V:$V,출고요청서_raw!$Q:$Q,매출요약!$D19,출고요청서_raw!$R:$R,매출요약!$Q$4) -> 0 | R19: =SUMIFS(출고요청서_raw!$W:$W,출고요청서_raw!$Q:$Q,매출요약!$D19,출고요청서_raw!$R:$R,매출요약!$Q$4) -> 0
D20: 46067 | E20: =SUM(G20,I20,K20,M20,Q20,O20) -> 108181.82 | F20: =SUM(H20,J20,L20,N20,R20,P20) -> 1 | G20: =SUMIF(SK스토아_raw!$AM:$AM,매출요약!$D20,SK스토아_raw!$AQ:$AQ) -> 108181.82 | H20: =SUMIF(SK스토아_raw!$AM:$AM,$D20,SK스토아_raw!$AN:$AN) -> 1 | I20: =SUMIFS(출고요청서_raw!$V:$V,출고요청서_raw!$Q:$Q,매출요약!$D20,출고요청서_raw!$R:$R,매출요약!$I$4) -> 0 | J20: =SUMIFS(출고요청서_raw!$W:$W,출고요청서_raw!$Q:$Q,매출요약!$D20,출고요청서_raw!$R:$R,매출요약!$I$4) -> 0 | K20: =SUMIFS(출고요청서_raw!$V:$V,출고요청서_raw!$Q:$Q,매출요약!$D20,출고요청서_raw!$R:$R,매출요약!$K$4) -> 0 | L20: =SUMIFS(출고요청서_raw!$W:$W,출고요청서_raw!$Q:$Q,매출요약!$D20,출고요청서_raw!$R:$R,매출요약!$K$4) -> 0 | M20: =SUMIFS(출고요청서_raw!$V:$V,출고요청서_raw!$Q:$Q,매출요약!$D20,출고요청서_raw!$R:$R,매출요약!$M$4) -> 0 | N20: =SUMIFS(출고요청서_raw!$W:$W,출고요청서_raw!$Q:$Q,매출요약!$D20,출고요청서_raw!$R:$R,매출요약!$M$4) -> 0 | O20: =SUMIFS(출고요청서_raw!$V:$V,출고요청서_raw!$Q:$Q,매출요약!$D20,출고요청서_raw!$R:$R,매출요약!$O$4) -> 0 | P20: =SUMIFS(출고요청서_raw!$W:$W,출고요청서_raw!$Q:$Q,매출요약!$D20,출고요청서_raw!$R:$R,매출요약!$O$4) -> 0 | Q20: =SUMIFS(출고요청서_raw!$V:$V,출고요청서_raw!$Q:$Q,매출요약!$D20,출고요청서_raw!$R:$R,매출요약!$Q$4) -> 0 | R20: =SUMIFS(출고요청서_raw!$W:$W,출고요청서_raw!$Q:$Q,매출요약!$D20,출고요청서_raw!$R:$R,매출요약!$Q$4) -> 0
D21: 46068 | E21: =SUM(G21,I21,K21,M21,Q21,O21) -> 0 | F21: =SUM(H21,J21,L21,N21,R21,P21) -> 0 | G21: =SUMIF(SK스토아_raw!$AM:$AM,매출요약!$D21,SK스토아_raw!$AQ:$AQ) -> 0 | H21: =SUMIF(SK스토아_raw!$AM:$AM,$D21,SK스토아_raw!$AN:$AN) -> 0 | I21: =SUMIFS(출고요청서_raw!$V:$V,출고요청서_raw!$Q:$Q,매출요약!$D21,출고요청서_raw!$R:$R,매출요약!$I$4) -> 0 | J21: =SUMIFS(출고요청서_raw!$W:$W,출고요청서_raw!$Q:$Q,매출요약!$D21,출고요청서_raw!$R:$R,매출요약!$I$4) -> 0 | K21: =SUMIFS(출고요청서_raw!$V:$V,출고요청서_raw!$Q:$Q,매출요약!$D21,출고요청서_raw!$R:$R,매출요약!$K$4) -> 0 | L21: =SUMIFS(출고요청서_raw!$W:$W,출고요청서_raw!$Q:$Q,매출요약!$D21,출고요청서_raw!$R:$R,매출요약!$K$4) -> 0 | M21: =SUMIFS(출고요청서_raw!$V:$V,출고요청서_raw!$Q:$Q,매출요약!$D21,출고요청서_raw!$R:$R,매출요약!$M$4) -> 0 | N21: =SUMIFS(출고요청서_raw!$W:$W,출고요청서_raw!$Q:$Q,매출요약!$D21,출고요청서_raw!$R:$R,매출요약!$M$4) -> 0 | O21: =SUMIFS(출고요청서_raw!$V:$V,출고요청서_raw!$Q:$Q,매출요약!$D21,출고요청서_raw!$R:$R,매출요약!$O$4) -> 0 | P21: =SUMIFS(출고요청서_raw!$W:$W,출고요청서_raw!$Q:$Q,매출요약!$D21,출고요청서_raw!$R:$R,매출요약!$O$4) -> 0 | Q21: =SUMIFS(출고요청서_raw!$V:$V,출고요청서_raw!$Q:$Q,매출요약!$D21,출고요청서_raw!$R:$R,매출요약!$Q$4) -> 0 | R21: =SUMIFS(출고요청서_raw!$W:$W,출고요청서_raw!$Q:$Q,매출요약!$D21,출고요청서_raw!$R:$R,매출요약!$Q$4) -> 0
C22: W8 | D22: 46069 | E22: =SUM(G22,I22,K22,M22,Q22,O22) -> 0 | F22: =SUM(H22,J22,L22,N22,R22,P22) -> 0 | G22: =SUMIF(SK스토아_raw!$AM:$AM,매출요약!$D22,SK스토아_raw!$AQ:$AQ) -> 0 | H22: =SUMIF(SK스토아_raw!$AM:$AM,$D22,SK스토아_raw!$AN:$AN) -> 0 | I22: =SUMIFS(출고요청서_raw!$V:$V,출고요청서_raw!$Q:$Q,매출요약!$D22,출고요청서_raw!$R:$R,매출요약!$I$4) -> 0 | J22: =SUMIFS(출고요청서_raw!$W:$W,출고요청서_raw!$Q:$Q,매출요약!$D22,출고요청서_raw!$R:$R,매출요약!$I$4) -> 0 | K22: =SUMIFS(출고요청서_raw!$V:$V,출고요청서_raw!$Q:$Q,매출요약!$D22,출고요청서_raw!$R:$R,매출요약!$K$4) -> 0 | L22: =SUMIFS(출고요청서_raw!$W:$W,출고요청서_raw!$Q:$Q,매출요약!$D22,출고요청서_raw!$R:$R,매출요약!$K$4) -> 0 | M22: =SUMIFS(출고요청서_raw!$V:$V,출고요청서_raw!$Q:$Q,매출요약!$D22,출고요청서_raw!$R:$R,매출요약!$M$4) -> 0 | N22: =SUMIFS(출고요청서_raw!$W:$W,출고요청서_raw!$Q:$Q,매출요약!$D22,출고요청서_raw!$R:$R,매출요약!$M$4) -> 0 | O22: =SUMIFS(출고요청서_raw!$V:$V,출고요청서_raw!$Q:$Q,매출요약!$D22,출고요청서_raw!$R:$R,매출요약!$O$4) -> 0 | P22: =SUMIFS(출고요청서_raw!$W:$W,출고요청서_raw!$Q:$Q,매출요약!$D22,출고요청서_raw!$R:$R,매출요약!$O$4) -> 0 | Q22: =SUMIFS(출고요청서_raw!$V:$V,출고요청서_raw!$Q:$Q,매출요약!$D22,출고요청서_raw!$R:$R,매출요약!$Q$4) -> 0 | R22: =SUMIFS(출고요청서_raw!$W:$W,출고요청서_raw!$Q:$Q,매출요약!$D22,출고요청서_raw!$R:$R,매출요약!$Q$4) -> 0
D23: 46070 | E23: =SUM(G23,I23,K23,M23,Q23,O23) -> 0 | F23: =SUM(H23,J23,L23,N23,R23,P23) -> 0 | G23: =SUMIF(SK스토아_raw!$AM:$AM,매출요약!$D23,SK스토아_raw!$AQ:$AQ) -> 0 | H23: =SUMIF(SK스토아_raw!$AM:$AM,$D23,SK스토아_raw!$AN:$AN) -> 0 | I23: =SUMIFS(출고요청서_raw!$V:$V,출고요청서_raw!$Q:$Q,매출요약!$D23,출고요청서_raw!$R:$R,매출요약!$I$4) -> 0 | J23: =SUMIFS(출고요청서_raw!$W:$W,출고요청서_raw!$Q:$Q,매출요약!$D23,출고요청서_raw!$R:$R,매출요약!$I$4) -> 0 | K23: =SUMIFS(출고요청서_raw!$V:$V,출고요청서_raw!$Q:$Q,매출요약!$D23,출고요청서_raw!$R:$R,매출요약!$K$4) -> 0 | L23: =SUMIFS(출고요청서_raw!$W:$W,출고요청서_raw!$Q:$Q,매출요약!$D23,출고요청서_raw!$R:$R,매출요약!$K$4) -> 0 | M23: =SUMIFS(출고요청서_raw!$V:$V,출고요청서_raw!$Q:$Q,매출요약!$D23,출고요청서_raw!$R:$R,매출요약!$M$4) -> 0 | N23: =SUMIFS(출고요청서_raw!$W:$W,출고요청서_raw!$Q:$Q,매출요약!$D23,출고요청서_raw!$R:$R,매출요약!$M$4) -> 0 | O23: =SUMIFS(출고요청서_raw!$V:$V,출고요청서_raw!$Q:$Q,매출요약!$D23,출고요청서_raw!$R:$R,매출요약!$O$4) -> 0 | P23: =SUMIFS(출고요청서_raw!$W:$W,출고요청서_raw!$Q:$Q,매출요약!$D23,출고요청서_raw!$R:$R,매출요약!$O$4) -> 0 | Q23: =SUMIFS(출고요청서_raw!$V:$V,출고요청서_raw!$Q:$Q,매출요약!$D23,출고요청서_raw!$R:$R,매출요약!$Q$4) -> 0 | R23: =SUMIFS(출고요청서_raw!$W:$W,출고요청서_raw!$Q:$Q,매출요약!$D23,출고요청서_raw!$R:$R,매출요약!$Q$4) -> 0
D24: 46071 | E24: =SUM(G24,I24,K24,M24,Q24,O24) -> 0 | F24: =SUM(H24,J24,L24,N24,R24,P24) -> 0 | G24: =SUMIF(SK스토아_raw!$AM:$AM,매출요약!$D24,SK스토아_raw!$AQ:$AQ) -> 0 | H24: =SUMIF(SK스토아_raw!$AM:$AM,$D24,SK스토아_raw!$AN:$AN) -> 0 | I24: =SUMIFS(출고요청서_raw!$V:$V,출고요청서_raw!$Q:$Q,매출요약!$D24,출고요청서_raw!$R:$R,매출요약!$I$4) -> 0 | J24: =SUMIFS(출고요청서_raw!$W:$W,출고요청서_raw!$Q:$Q,매출요약!$D24,출고요청서_raw!$R:$R,매출요약!$I$4) -> 0 | K24: =SUMIFS(출고요청서_raw!$V:$V,출고요청서_raw!$Q:$Q,매출요약!$D24,출고요청서_raw!$R:$R,매출요약!$K$4) -> 0 | L24: =SUMIFS(출고요청서_raw!$W:$W,출고요청서_raw!$Q:$Q,매출요약!$D24,출고요청서_raw!$R:$R,매출요약!$K$4) -> 0 | M24: =SUMIFS(출고요청서_raw!$V:$V,출고요청서_raw!$Q:$Q,매출요약!$D24,출고요청서_raw!$R:$R,매출요약!$M$4) -> 0 | N24: =SUMIFS(출고요청서_raw!$W:$W,출고요청서_raw!$Q:$Q,매출요약!$D24,출고요청서_raw!$R:$R,매출요약!$M$4) -> 0 | O24: =SUMIFS(출고요청서_raw!$V:$V,출고요청서_raw!$Q:$Q,매출요약!$D24,출고요청서_raw!$R:$R,매출요약!$O$4) -> 0 | P24: =SUMIFS(출고요청서_raw!$W:$W,출고요청서_raw!$Q:$Q,매출요약!$D24,출고요청서_raw!$R:$R,매출요약!$O$4) -> 0 | Q24: =SUMIFS(출고요청서_raw!$V:$V,출고요청서_raw!$Q:$Q,매출요약!$D24,출고요청서_raw!$R:$R,매출요약!$Q$4) -> 0 | R24: =SUMIFS(출고요청서_raw!$W:$W,출고요청서_raw!$Q:$Q,매출요약!$D24,출고요청서_raw!$R:$R,매출요약!$Q$4) -> 0
D25: 46072 | E25: =SUM(G25,I25,K25,M25,Q25,O25) -> 0 | F25: =SUM(H25,J25,L25,N25,R25,P25) -> 0 | G25: =SUMIF(SK스토아_raw!$AM:$AM,매출요약!$D25,SK스토아_raw!$AQ:$AQ) -> 0 | H25: =SUMIF(SK스토아_raw!$AM:$AM,$D25,SK스토아_raw!$AN:$AN) -> 0 | I25: =SUMIFS(출고요청서_raw!$V:$V,출고요청서_raw!$Q:$Q,매출요약!$D25,출고요청서_raw!$R:$R,매출요약!$I$4) -> 0 | J25: =SUMIFS(출고요청서_raw!$W:$W,출고요청서_raw!$Q:$Q,매출요약!$D25,출고요청서_raw!$R:$R,매출요약!$I$4) -> 0 | K25: =SUMIFS(출고요청서_raw!$V:$V,출고요청서_raw!$Q:$Q,매출요약!$D25,출고요청서_raw!$R:$R,매출요약!$K$4) -> 0 | L25: =SUMIFS(출고요청서_raw!$W:$W,출고요청서_raw!$Q:$Q,매출요약!$D25,출고요청서_raw!$R:$R,매출요약!$K$4) -> 0 | M25: =SUMIFS(출고요청서_raw!$V:$V,출고요청서_raw!$Q:$Q,매출요약!$D25,출고요청서_raw!$R:$R,매출요약!$M$4) -> 0 | N25: =SUMIFS(출고요청서_raw!$W:$W,출고요청서_raw!$Q:$Q,매출요약!$D25,출고요청서_raw!$R:$R,매출요약!$M$4) -> 0 | O25: =SUMIFS(출고요청서_raw!$V:$V,출고요청서_raw!$Q:$Q,매출요약!$D25,출고요청서_raw!$R:$R,매출요약!$O$4) -> 0 | P25: =SUMIFS(출고요청서_raw!$W:$W,출고요청서_raw!$Q:$Q,매출요약!$D25,출고요청서_raw!$R:$R,매출요약!$O$4) -> 0 | Q25: =SUMIFS(출고요청서_raw!$V:$V,출고요청서_raw!$Q:$Q,매출요약!$D25,출고요청서_raw!$R:$R,매출요약!$Q$4) -> 0 | R25: =SUMIFS(출고요청서_raw!$W:$W,출고요청서_raw!$Q:$Q,매출요약!$D25,출고요청서_raw!$R:$R,매출요약!$Q$4) -> 0
D26: 46073 | E26: =SUM(G26,I26,K26,M26,Q26,O26) -> 0 | F26: =SUM(H26,J26,L26,N26,R26,P26) -> 0 | G26: =SUMIF(SK스토아_raw!$AM:$AM,매출요약!$D26,SK스토아_raw!$AQ:$AQ) -> 0 | H26: =SUMIF(SK스토아_raw!$AM:$AM,$D26,SK스토아_raw!$AN:$AN) -> 0 | I26: =SUMIFS(출고요청서_raw!$V:$V,출고요청서_raw!$Q:$Q,매출요약!$D26,출고요청서_raw!$R:$R,매출요약!$I$4) -> 0 | J26: =SUMIFS(출고요청서_raw!$W:$W,출고요청서_raw!$Q:$Q,매출요약!$D26,출고요청서_raw!$R:$R,매출요약!$I$4) -> 0 | K26: =SUMIFS(출고요청서_raw!$V:$V,출고요청서_raw!$Q:$Q,매출요약!$D26,출고요청서_raw!$R:$R,매출요약!$K$4) -> 0 | L26: =SUMIFS(출고요청서_raw!$W:$W,출고요청서_raw!$Q:$Q,매출요약!$D26,출고요청서_raw!$R:$R,매출요약!$K$4) -> 0 | M26: =SUMIFS(출고요청서_raw!$V:$V,출고요청서_raw!$Q:$Q,매출요약!$D26,출고요청서_raw!$R:$R,매출요약!$M$4) -> 0 | N26: =SUMIFS(출고요청서_raw!$W:$W,출고요청서_raw!$Q:$Q,매출요약!$D26,출고요청서_raw!$R:$R,매출요약!$M$4) -> 0 | O26: =SUMIFS(출고요청서_raw!$V:$V,출고요청서_raw!$Q:$Q,매출요약!$D26,출고요청서_raw!$R:$R,매출요약!$O$4) -> 0 | P26: =SUMIFS(출고요청서_raw!$W:$W,출고요청서_raw!$Q:$Q,매출요약!$D26,출고요청서_raw!$R:$R,매출요약!$O$4) -> 0 | Q26: =SUMIFS(출고요청서_raw!$V:$V,출고요청서_raw!$Q:$Q,매출요약!$D26,출고요청서_raw!$R:$R,매출요약!$Q$4) -> 0 | R26: =SUMIFS(출고요청서_raw!$W:$W,출고요청서_raw!$Q:$Q,매출요약!$D26,출고요청서_raw!$R:$R,매출요약!$Q$4) -> 0
D27: 46074 | E27: =SUM(G27,I27,K27,M27,Q27,O27) -> 0 | F27: =SUM(H27,J27,L27,N27,R27,P27) -> 0 | G27: =SUMIF(SK스토아_raw!$AM:$AM,매출요약!$D27,SK스토아_raw!$AQ:$AQ) -> 0 | H27: =SUMIF(SK스토아_raw!$AM:$AM,$D27,SK스토아_raw!$AN:$AN) -> 0 | I27: =SUMIFS(출고요청서_raw!$V:$V,출고요청서_raw!$Q:$Q,매출요약!$D27,출고요청서_raw!$R:$R,매출요약!$I$4) -> 0 | J27: =SUMIFS(출고요청서_raw!$W:$W,출고요청서_raw!$Q:$Q,매출요약!$D27,출고요청서_raw!$R:$R,매출요약!$I$4) -> 0 | K27: =SUMIFS(출고요청서_raw!$V:$V,출고요청서_raw!$Q:$Q,매출요약!$D27,출고요청서_raw!$R:$R,매출요약!$K$4) -> 0 | L27: =SUMIFS(출고요청서_raw!$W:$W,출고요청서_raw!$Q:$Q,매출요약!$D27,출고요청서_raw!$R:$R,매출요약!$K$4) -> 0 | M27: =SUMIFS(출고요청서_raw!$V:$V,출고요청서_raw!$Q:$Q,매출요약!$D27,출고요청서_raw!$R:$R,매출요약!$M$4) -> 0 | N27: =SUMIFS(출고요청서_raw!$W:$W,출고요청서_raw!$Q:$Q,매출요약!$D27,출고요청서_raw!$R:$R,매출요약!$M$4) -> 0 | O27: =SUMIFS(출고요청서_raw!$V:$V,출고요청서_raw!$Q:$Q,매출요약!$D27,출고요청서_raw!$R:$R,매출요약!$O$4) -> 0 | P27: =SUMIFS(출고요청서_raw!$W:$W,출고요청서_raw!$Q:$Q,매출요약!$D27,출고요청서_raw!$R:$R,매출요약!$O$4) -> 0 | Q27: =SUMIFS(출고요청서_raw!$V:$V,출고요청서_raw!$Q:$Q,매출요약!$D27,출고요청서_raw!$R:$R,매출요약!$Q$4) -> 0 | R27: =SUMIFS(출고요청서_raw!$W:$W,출고요청서_raw!$Q:$Q,매출요약!$D27,출고요청서_raw!$R:$R,매출요약!$Q$4) -> 0
D28: 46075 | E28: =SUM(G28,I28,K28,M28,Q28,O28) -> 0 | F28: =SUM(H28,J28,L28,N28,R28,P28) -> 0 | G28: =SUMIF(SK스토아_raw!$AM:$AM,매출요약!$D28,SK스토아_raw!$AQ:$AQ) -> 0 | H28: =SUMIF(SK스토아_raw!$AM:$AM,$D28,SK스토아_raw!$AN:$AN) -> 0 | I28: =SUMIFS(출고요청서_raw!$V:$V,출고요청서_raw!$Q:$Q,매출요약!$D28,출고요청서_raw!$R:$R,매출요약!$I$4) -> 0 | J28: =SUMIFS(출고요청서_raw!$W:$W,출고요청서_raw!$Q:$Q,매출요약!$D28,출고요청서_raw!$R:$R,매출요약!$I$4) -> 0 | K28: =SUMIFS(출고요청서_raw!$V:$V,출고요청서_raw!$Q:$Q,매출요약!$D28,출고요청서_raw!$R:$R,매출요약!$K$4) -> 0 | L28: =SUMIFS(출고요청서_raw!$W:$W,출고요청서_raw!$Q:$Q,매출요약!$D28,출고요청서_raw!$R:$R,매출요약!$K$4) -> 0 | M28: =SUMIFS(출고요청서_raw!$V:$V,출고요청서_raw!$Q:$Q,매출요약!$D28,출고요청서_raw!$R:$R,매출요약!$M$4) -> 0 | N28: =SUMIFS(출고요청서_raw!$W:$W,출고요청서_raw!$Q:$Q,매출요약!$D28,출고요청서_raw!$R:$R,매출요약!$M$4) -> 0 | O28: =SUMIFS(출고요청서_raw!$V:$V,출고요청서_raw!$Q:$Q,매출요약!$D28,출고요청서_raw!$R:$R,매출요약!$O$4) -> 0 | P28: =SUMIFS(출고요청서_raw!$W:$W,출고요청서_raw!$Q:$Q,매출요약!$D28,출고요청서_raw!$R:$R,매출요약!$O$4) -> 0 | Q28: =SUMIFS(출고요청서_raw!$V:$V,출고요청서_raw!$Q:$Q,매출요약!$D28,출고요청서_raw!$R:$R,매출요약!$Q$4) -> 0 | R28: =SUMIFS(출고요청서_raw!$W:$W,출고요청서_raw!$Q:$Q,매출요약!$D28,출고요청서_raw!$R:$R,매출요약!$Q$4) -> 0
C29: W9 | D29: 46076 | E29: =SUM(G29,I29,K29,M29,Q29,O29) -> 54363.636 | F29: =SUM(H29,J29,L29,N29,R29,P29) -> 3 | G29: =SUMIF(SK스토아_raw!$AM:$AM,매출요약!$D29,SK스토아_raw!$AQ:$AQ) -> 0 | H29: =SUMIF(SK스토아_raw!$AM:$AM,$D29,SK스토아_raw!$AN:$AN) -> 0 | I29: =SUMIFS(출고요청서_raw!$V:$V,출고요청서_raw!$Q:$Q,매출요약!$D29,출고요청서_raw!$R:$R,매출요약!$I$4) -> 0 | J29: =SUMIFS(출고요청서_raw!$W:$W,출고요청서_raw!$Q:$Q,매출요약!$D29,출고요청서_raw!$R:$R,매출요약!$I$4) -> 0 | K29: =SUMIFS(출고요청서_raw!$V:$V,출고요청서_raw!$Q:$Q,매출요약!$D29,출고요청서_raw!$R:$R,매출요약!$K$4) -> 0 | L29: =SUMIFS(출고요청서_raw!$W:$W,출고요청서_raw!$Q:$Q,매출요약!$D29,출고요청서_raw!$R:$R,매출요약!$K$4) -> 0 | M29: =SUMIFS(출고요청서_raw!$V:$V,출고요청서_raw!$Q:$Q,매출요약!$D29,출고요청서_raw!$R:$R,매출요약!$M$4) -> 54363.636 | N29: =SUMIFS(출고요청서_raw!$W:$W,출고요청서_raw!$Q:$Q,매출요약!$D29,출고요청서_raw!$R:$R,매출요약!$M$4) -> 3 | O29: =SUMIFS(출고요청서_raw!$V:$V,출고요청서_raw!$Q:$Q,매출요약!$D29,출고요청서_raw!$R:$R,매출요약!$O$4) -> 0 | P29: =SUMIFS(출고요청서_raw!$W:$W,출고요청서_raw!$Q:$Q,매출요약!$D29,출고요청서_raw!$R:$R,매출요약!$O$4) -> 0 | Q29: =SUMIFS(출고요청서_raw!$V:$V,출고요청서_raw!$Q:$Q,매출요약!$D29,출고요청서_raw!$R:$R,매출요약!$Q$4) -> 0 | R29: =SUMIFS(출고요청서_raw!$W:$W,출고요청서_raw!$Q:$Q,매출요약!$D29,출고요청서_raw!$R:$R,매출요약!$Q$4) -> 0
D30: 46077 | E30: =SUM(G30,I30,K30,M30,Q30,O30) -> 0 | F30: =SUM(H30,J30,L30,N30,R30,P30) -> 0 | G30: =SUMIF(SK스토아_raw!$AM:$AM,매출요약!$D30,SK스토아_raw!$AQ:$AQ) -> 0 | H30: =SUMIF(SK스토아_raw!$AM:$AM,$D30,SK스토아_raw!$AN:$AN) -> 0 | I30: =SUMIFS(출고요청서_raw!$V:$V,출고요청서_raw!$Q:$Q,매출요약!$D30,출고요청서_raw!$R:$R,매출요약!$I$4) -> 0 | J30: =SUMIFS(출고요청서_raw!$W:$W,출고요청서_raw!$Q:$Q,매출요약!$D30,출고요청서_raw!$R:$R,매출요약!$I$4) -> 0 | K30: =SUMIFS(출고요청서_raw!$V:$V,출고요청서_raw!$Q:$Q,매출요약!$D30,출고요청서_raw!$R:$R,매출요약!$K$4) -> 0 | L30: =SUMIFS(출고요청서_raw!$W:$W,출고요청서_raw!$Q:$Q,매출요약!$D30,출고요청서_raw!$R:$R,매출요약!$K$4) -> 0 | M30: =SUMIFS(출고요청서_raw!$V:$V,출고요청서_raw!$Q:$Q,매출요약!$D30,출고요청서_raw!$R:$R,매출요약!$M$4) -> 0 | N30: =SUMIFS(출고요청서_raw!$W:$W,출고요청서_raw!$Q:$Q,매출요약!$D30,출고요청서_raw!$R:$R,매출요약!$M$4) -> 0 | O30: =SUMIFS(출고요청서_raw!$V:$V,출고요청서_raw!$Q:$Q,매출요약!$D30,출고요청서_raw!$R:$R,매출요약!$O$4) -> 0 | P30: =SUMIFS(출고요청서_raw!$W:$W,출고요청서_raw!$Q:$Q,매출요약!$D30,출고요청서_raw!$R:$R,매출요약!$O$4) -> 0 | Q30: =SUMIFS(출고요청서_raw!$V:$V,출고요청서_raw!$Q:$Q,매출요약!$D30,출고요청서_raw!$R:$R,매출요약!$Q$4) -> 0 | R30: =SUMIFS(출고요청서_raw!$W:$W,출고요청서_raw!$Q:$Q,매출요약!$D30,출고요청서_raw!$R:$R,매출요약!$Q$4) -> 0
D31: 46078 | E31: =SUM(G31,I31,K31,M31,Q31,O31) -> 0 | F31: =SUM(H31,J31,L31,N31,R31,P31) -> 0 | G31: =SUMIF(SK스토아_raw!$AM:$AM,매출요약!$D31,SK스토아_raw!$AQ:$AQ) -> 0 | H31: =SUMIF(SK스토아_raw!$AM:$AM,$D31,SK스토아_raw!$AN:$AN) -> 0 | I31: =SUMIFS(출고요청서_raw!$V:$V,출고요청서_raw!$Q:$Q,매출요약!$D31,출고요청서_raw!$R:$R,매출요약!$I$4) -> 0 | J31: =SUMIFS(출고요청서_raw!$W:$W,출고요청서_raw!$Q:$Q,매출요약!$D31,출고요청서_raw!$R:$R,매출요약!$I$4) -> 0 | K31: =SUMIFS(출고요청서_raw!$V:$V,출고요청서_raw!$Q:$Q,매출요약!$D31,출고요청서_raw!$R:$R,매출요약!$K$4) -> 0 | L31: =SUMIFS(출고요청서_raw!$W:$W,출고요청서_raw!$Q:$Q,매출요약!$D31,출고요청서_raw!$R:$R,매출요약!$K$4) -> 0 | M31: =SUMIFS(출고요청서_raw!$V:$V,출고요청서_raw!$Q:$Q,매출요약!$D31,출고요청서_raw!$R:$R,매출요약!$M$4) -> 0 | N31: =SUMIFS(출고요청서_raw!$W:$W,출고요청서_raw!$Q:$Q,매출요약!$D31,출고요청서_raw!$R:$R,매출요약!$M$4) -> 0 | O31: =SUMIFS(출고요청서_raw!$V:$V,출고요청서_raw!$Q:$Q,매출요약!$D31,출고요청서_raw!$R:$R,매출요약!$O$4) -> 0 | P31: =SUMIFS(출고요청서_raw!$W:$W,출고요청서_raw!$Q:$Q,매출요약!$D31,출고요청서_raw!$R:$R,매출요약!$O$4) -> 0 | Q31: =SUMIFS(출고요청서_raw!$V:$V,출고요청서_raw!$Q:$Q,매출요약!$D31,출고요청서_raw!$R:$R,매출요약!$Q$4) -> 0 | R31: =SUMIFS(출고요청서_raw!$W:$W,출고요청서_raw!$Q:$Q,매출요약!$D31,출고요청서_raw!$R:$R,매출요약!$Q$4) -> 0
D32: 46079 | E32: =SUM(G32,I32,K32,M32,Q32,O32) -> 0 | F32: =SUM(H32,J32,L32,N32,R32,P32) -> 0 | G32: =SUMIF(SK스토아_raw!$AM:$AM,매출요약!$D32,SK스토아_raw!$AQ:$AQ) -> 0 | H32: =SUMIF(SK스토아_raw!$AM:$AM,$D32,SK스토아_raw!$AN:$AN) -> 0 | I32: =SUMIFS(출고요청서_raw!$V:$V,출고요청서_raw!$Q:$Q,매출요약!$D32,출고요청서_raw!$R:$R,매출요약!$I$4) -> 0 | J32: =SUMIFS(출고요청서_raw!$W:$W,출고요청서_raw!$Q:$Q,매출요약!$D32,출고요청서_raw!$R:$R,매출요약!$I$4) -> 0 | K32: =SUMIFS(출고요청서_raw!$V:$V,출고요청서_raw!$Q:$Q,매출요약!$D32,출고요청서_raw!$R:$R,매출요약!$K$4) -> 0 | L32: =SUMIFS(출고요청서_raw!$W:$W,출고요청서_raw!$Q:$Q,매출요약!$D32,출고요청서_raw!$R:$R,매출요약!$K$4) -> 0 | M32: =SUMIFS(출고요청서_raw!$V:$V,출고요청서_raw!$Q:$Q,매출요약!$D32,출고요청서_raw!$R:$R,매출요약!$M$4) -> 0 | N32: =SUMIFS(출고요청서_raw!$W:$W,출고요청서_raw!$Q:$Q,매출요약!$D32,출고요청서_raw!$R:$R,매출요약!$M$4) -> 0 | O32: =SUMIFS(출고요청서_raw!$V:$V,출고요청서_raw!$Q:$Q,매출요약!$D32,출고요청서_raw!$R:$R,매출요약!$O$4) -> 0 | P32: =SUMIFS(출고요청서_raw!$W:$W,출고요청서_raw!$Q:$Q,매출요약!$D32,출고요청서_raw!$R:$R,매출요약!$O$4) -> 0 | Q32: =SUMIFS(출고요청서_raw!$V:$V,출고요청서_raw!$Q:$Q,매출요약!$D32,출고요청서_raw!$R:$R,매출요약!$Q$4) -> 0 | R32: =SUMIFS(출고요청서_raw!$W:$W,출고요청서_raw!$Q:$Q,매출요약!$D32,출고요청서_raw!$R:$R,매출요약!$Q$4) -> 0
D33: 46080 | E33: =SUM(G33,I33,K33,M33,Q33,O33) -> 0 | F33: =SUM(H33,J33,L33,N33,R33,P33) -> 0 | G33: =SUMIF(SK스토아_raw!$AM:$AM,매출요약!$D33,SK스토아_raw!$AQ:$AQ) -> 0 | H33: =SUMIF(SK스토아_raw!$AM:$AM,$D33,SK스토아_raw!$AN:$AN) -> 0 | I33: =SUMIFS(출고요청서_raw!$V:$V,출고요청서_raw!$Q:$Q,매출요약!$D33,출고요청서_raw!$R:$R,매출요약!$I$4) -> 0 | J33: =SUMIFS(출고요청서_raw!$W:$W,출고요청서_raw!$Q:$Q,매출요약!$D33,출고요청서_raw!$R:$R,매출요약!$I$4) -> 0 | K33: =SUMIFS(출고요청서_raw!$V:$V,출고요청서_raw!$Q:$Q,매출요약!$D33,출고요청서_raw!$R:$R,매출요약!$K$4) -> 0 | L33: =SUMIFS(출고요청서_raw!$W:$W,출고요청서_raw!$Q:$Q,매출요약!$D33,출고요청서_raw!$R:$R,매출요약!$K$4) -> 0 | M33: =SUMIFS(출고요청서_raw!$V:$V,출고요청서_raw!$Q:$Q,매출요약!$D33,출고요청서_raw!$R:$R,매출요약!$M$4) -> 0 | N33: =SUMIFS(출고요청서_raw!$W:$W,출고요청서_raw!$Q:$Q,매출요약!$D33,출고요청서_raw!$R:$R,매출요약!$M$4) -> 0 | O33: =SUMIFS(출고요청서_raw!$V:$V,출고요청서_raw!$Q:$Q,매출요약!$D33,출고요청서_raw!$R:$R,매출요약!$O$4) -> 0 | P33: =SUMIFS(출고요청서_raw!$W:$W,출고요청서_raw!$Q:$Q,매출요약!$D33,출고요청서_raw!$R:$R,매출요약!$O$4) -> 0 | Q33: =SUMIFS(출고요청서_raw!$V:$V,출고요청서_raw!$Q:$Q,매출요약!$D33,출고요청서_raw!$R:$R,매출요약!$Q$4) -> 0 | R33: =SUMIFS(출고요청서_raw!$W:$W,출고요청서_raw!$Q:$Q,매출요약!$D33,출고요청서_raw!$R:$R,매출요약!$Q$4) -> 0
D34: 46081 | E34: =SUM(G34,I34,K34,M34,Q34,O34) -> 0 | F34: =SUM(H34,J34,L34,N34,R34,P34) -> 0 | G34: =SUMIF(SK스토아_raw!$AM:$AM,매출요약!$D34,SK스토아_raw!$AQ:$AQ) -> 0 | H34: =SUMIF(SK스토아_raw!$AM:$AM,$D34,SK스토아_raw!$AN:$AN) -> 0 | I34: =SUMIFS(출고요청서_raw!$V:$V,출고요청서_raw!$Q:$Q,매출요약!$D34,출고요청서_raw!$R:$R,매출요약!$I$4) -> 0 | J34: =SUMIFS(출고요청서_raw!$W:$W,출고요청서_raw!$Q:$Q,매출요약!$D34,출고요청서_raw!$R:$R,매출요약!$I$4) -> 0 | K34: =SUMIFS(출고요청서_raw!$V:$V,출고요청서_raw!$Q:$Q,매출요약!$D34,출고요청서_raw!$R:$R,매출요약!$K$4) -> 0 | L34: =SUMIFS(출고요청서_raw!$W:$W,출고요청서_raw!$Q:$Q,매출요약!$D34,출고요청서_raw!$R:$R,매출요약!$K$4) -> 0 | M34: =SUMIFS(출고요청서_raw!$V:$V,출고요청서_raw!$Q:$Q,매출요약!$D34,출고요청서_raw!$R:$R,매출요약!$M$4) -> 0 | N34: =SUMIFS(출고요청서_raw!$W:$W,출고요청서_raw!$Q:$Q,매출요약!$D34,출고요청서_raw!$R:$R,매출요약!$M$4) -> 0 | O34: =SUMIFS(출고요청서_raw!$V:$V,출고요청서_raw!$Q:$Q,매출요약!$D34,출고요청서_raw!$R:$R,매출요약!$O$4) -> 0 | P34: =SUMIFS(출고요청서_raw!$W:$W,출고요청서_raw!$Q:$Q,매출요약!$D34,출고요청서_raw!$R:$R,매출요약!$O$4) -> 0 | Q34: =SUMIFS(출고요청서_raw!$V:$V,출고요청서_raw!$Q:$Q,매출요약!$D34,출고요청서_raw!$R:$R,매출요약!$Q$4) -> 0 | R34: =SUMIFS(출고요청서_raw!$W:$W,출고요청서_raw!$Q:$Q,매출요약!$D34,출고요청서_raw!$R:$R,매출요약!$Q$4) -> 0
E35: =SUM(E36:E66) -> 0 | F35: =SUM(F36:F66) -> 0 | G35: =SUM(G36:G66) -> 0 | H35: =SUM(H36:H66) -> 0 | I35: =SUM(I36:I66) -> 0 | J35: =SUM(J36:J66) -> 0 | K35: =SUM(K36:K66) -> 0 | L35: =SUM(L36:L66) -> 0 | ... R35: =SUM(R36:R66) -> 0
B36: 3월 | C36: W9 | D36: 46082 | E36: =SUM(G36,I36,K36,M36,Q36) -> 0 | F36: =SUM(H36,J36,L36,N36,R36) -> 0 | G36: =SUMIF(SK스토아_raw!$AM:$AM,매출요약!$D36,SK스토아_raw!$AQ:$AQ) -> 0 | H36: =SUMIF(SK스토아_raw!$AM:$AM,$D36,SK스토아_raw!$AN:$AN) -> 0 | I36: =SUMIFS(출고요청서_raw!$V:$V,출고요청서_raw!$Q:$Q,매출요약!$D36,출고요청서_raw!$R:$R,매출요약!$I$4) -> 0 | J36: =SUMIFS(출고요청서_raw!$W:$W,출고요청서_raw!$Q:$Q,매출요약!$D36,출고요청서_raw!$R:$R,매출요약!$I$4) -> 0 | K36: =SUMIFS(출고요청서_raw!$V:$V,출고요청서_raw!$Q:$Q,매출요약!$D36,출고요청서_raw!$R:$R,매출요약!$K$4) -> 0 | L36: =SUMIFS(출고요청서_raw!$W:$W,출고요청서_raw!$Q:$Q,매출요약!$D36,출고요청서_raw!$R:$R,매출요약!$K$4) -> 0 | M36: =SUMIFS(출고요청서_raw!$V:$V,출고요청서_raw!$Q:$Q,매출요약!$D36,출고요청서_raw!$R:$R,매출요약!$M$4) -> 0 | N36: =SUMIFS(출고요청서_raw!$W:$W,출고요청서_raw!$Q:$Q,매출요약!$D36,출고요청서_raw!$R:$R,매출요약!$M$4) -> 0 | O36: =SUMIFS(출고요청서_raw!$V:$V,출고요청서_raw!$Q:$Q,매출요약!$D36,출고요청서_raw!$R:$R,매출요약!$O$4) -> 0 | P36: =SUMIFS(출고요청서_raw!$W:$W,출고요청서_raw!$Q:$Q,매출요약!$D36,출고요청서_raw!$R:$R,매출요약!$O$4) -> 0 | Q36: =SUMIFS(출고요청서_raw!$V:$V,출고요청서_raw!$Q:$Q,매출요약!$D36,출고요청서_raw!$R:$R,매출요약!$Q$4) -> 0 | R36: =SUMIFS(출고요청서_raw!$W:$W,출고요청서_raw!$Q:$Q,매출요약!$D36,출고요청서_raw!$R:$R,매출요약!$Q$4) -> 0
C37: W10 | D37: 46083 | E37: =SUM(G37,I37,K37,M37,Q37) -> 0 | F37: =SUM(H37,J37,L37,N37,R37) -> 0 | G37: =SUMIF(SK스토아_raw!$AM:$AM,매출요약!$D37,SK스토아_raw!$AQ:$AQ) -> 0 | H37: =SUMIF(SK스토아_raw!$AM:$AM,$D37,SK스토아_raw!$AN:$AN) -> 0 | I37: =SUMIFS(출고요청서_raw!$V:$V,출고요청서_raw!$Q:$Q,매출요약!$D37,출고요청서_raw!$R:$R,매출요약!$I$4) -> 0 | J37: =SUMIFS(출고요청서_raw!$W:$W,출고요청서_raw!$Q:$Q,매출요약!$D37,출고요청서_raw!$R:$R,매출요약!$I$4) -> 0 | K37: =SUMIFS(출고요청서_raw!$V:$V,출고요청서_raw!$Q:$Q,매출요약!$D37,출고요청서_raw!$R:$R,매출요약!$K$4) -> 0 | L37: =SUMIFS(출고요청서_raw!$W:$W,출고요청서_raw!$Q:$Q,매출요약!$D37,출고요청서_raw!$R:$R,매출요약!$K$4) -> 0 | M37: =SUMIFS(출고요청서_raw!$V:$V,출고요청서_raw!$Q:$Q,매출요약!$D37,출고요청서_raw!$R:$R,매출요약!$M$4) -> 0 | N37: =SUMIFS(출고요청서_raw!$W:$W,출고요청서_raw!$Q:$Q,매출요약!$D37,출고요청서_raw!$R:$R,매출요약!$M$4) -> 0 | O37: =SUMIFS(출고요청서_raw!$V:$V,출고요청서_raw!$Q:$Q,매출요약!$D37,출고요청서_raw!$R:$R,매출요약!$O$4) -> 0 | P37: =SUMIFS(출고요청서_raw!$W:$W,출고요청서_raw!$Q:$Q,매출요약!$D37,출고요청서_raw!$R:$R,매출요약!$O$4) -> 0 | Q37: =SUMIFS(출고요청서_raw!$V:$V,출고요청서_raw!$Q:$Q,매출요약!$D37,출고요청서_raw!$R:$R,매출요약!$Q$4) -> 0 | R37: =SUMIFS(출고요청서_raw!$W:$W,출고요청서_raw!$Q:$Q,매출요약!$D37,출고요청서_raw!$R:$R,매출요약!$Q$4) -> 0
D38: 46084 | E38: =SUM(G38,I38,K38,M38,Q38) -> 0 | F38: =SUM(H38,J38,L38,N38,R38) -> 0 | G38: =SUMIF(SK스토아_raw!$AM:$AM,매출요약!$D38,SK스토아_raw!$AQ:$AQ) -> 0 | H38: =SUMIF(SK스토아_raw!$AM:$AM,$D38,SK스토아_raw!$AN:$AN) -> 0 | I38: =SUMIFS(출고요청서_raw!$V:$V,출고요청서_raw!$Q:$Q,매출요약!$D38,출고요청서_raw!$R:$R,매출요약!$I$4) -> 0 | J38: =SUMIFS(출고요청서_raw!$W:$W,출고요청서_raw!$Q:$Q,매출요약!$D38,출고요청서_raw!$R:$R,매출요약!$I$4) -> 0 | K38: =SUMIFS(출고요청서_raw!$V:$V,출고요청서_raw!$Q:$Q,매출요약!$D38,출고요청서_raw!$R:$R,매출요약!$K$4) -> 0 | L38: =SUMIFS(출고요청서_raw!$W:$W,출고요청서_raw!$Q:$Q,매출요약!$D38,출고요청서_raw!$R:$R,매출요약!$K$4) -> 0 | M38: =SUMIFS(출고요청서_raw!$V:$V,출고요청서_raw!$Q:$Q,매출요약!$D38,출고요청서_raw!$R:$R,매출요약!$M$4) -> 0 | N38: =SUMIFS(출고요청서_raw!$W:$W,출고요청서_raw!$Q:$Q,매출요약!$D38,출고요청서_raw!$R:$R,매출요약!$M$4) -> 0 | O38: =SUMIFS(출고요청서_raw!$V:$V,출고요청서_raw!$Q:$Q,매출요약!$D38,출고요청서_raw!$R:$R,매출요약!$O$4) -> 0 | P38: =SUMIFS(출고요청서_raw!$W:$W,출고요청서_raw!$Q:$Q,매출요약!$D38,출고요청서_raw!$R:$R,매출요약!$O$4) -> 0 | Q38: =SUMIFS(출고요청서_raw!$V:$V,출고요청서_raw!$Q:$Q,매출요약!$D38,출고요청서_raw!$R:$R,매출요약!$Q$4) -> 0 | R38: =SUMIFS(출고요청서_raw!$W:$W,출고요청서_raw!$Q:$Q,매출요약!$D38,출고요청서_raw!$R:$R,매출요약!$Q$4) -> 0
D39: 46085 | E39: =SUM(G39,I39,K39,M39,Q39) -> 0 | F39: =SUM(H39,J39,L39,N39,R39) -> 0 | G39: =SUMIF(SK스토아_raw!$AM:$AM,매출요약!$D39,SK스토아_raw!$AQ:$AQ) -> 0 | H39: =SUMIF(SK스토아_raw!$AM:$AM,$D39,SK스토아_raw!$AN:$AN) -> 0 | I39: =SUMIFS(출고요청서_raw!$V:$V,출고요청서_raw!$Q:$Q,매출요약!$D39,출고요청서_raw!$R:$R,매출요약!$I$4) -> 0 | J39: =SUMIFS(출고요청서_raw!$W:$W,출고요청서_raw!$Q:$Q,매출요약!$D39,출고요청서_raw!$R:$R,매출요약!$I$4) -> 0 | K39: =SUMIFS(출고요청서_raw!$V:$V,출고요청서_raw!$Q:$Q,매출요약!$D39,출고요청서_raw!$R:$R,매출요약!$K$4) -> 0 | L39: =SUMIFS(출고요청서_raw!$W:$W,출고요청서_raw!$Q:$Q,매출요약!$D39,출고요청서_raw!$R:$R,매출요약!$K$4) -> 0 | M39: =SUMIFS(출고요청서_raw!$V:$V,출고요청서_raw!$Q:$Q,매출요약!$D39,출고요청서_raw!$R:$R,매출요약!$M$4) -> 0 | N39: =SUMIFS(출고요청서_raw!$W:$W,출고요청서_raw!$Q:$Q,매출요약!$D39,출고요청서_raw!$R:$R,매출요약!$M$4) -> 0 | O39: =SUMIFS(출고요청서_raw!$V:$V,출고요청서_raw!$Q:$Q,매출요약!$D39,출고요청서_raw!$R:$R,매출요약!$O$4) -> 0 | P39: =SUMIFS(출고요청서_raw!$W:$W,출고요청서_raw!$Q:$Q,매출요약!$D39,출고요청서_raw!$R:$R,매출요약!$O$4) -> 0 | Q39: =SUMIFS(출고요청서_raw!$V:$V,출고요청서_raw!$Q:$Q,매출요약!$D39,출고요청서_raw!$R:$R,매출요약!$Q$4) -> 0 | R39: =SUMIFS(출고요청서_raw!$W:$W,출고요청서_raw!$Q:$Q,매출요약!$D39,출고요청서_raw!$R:$R,매출요약!$Q$4) -> 0
D40: 46086 | E40: =SUM(G40,I40,K40,M40,Q40) -> 0 | F40: =SUM(H40,J40,L40,N40,R40) -> 0 | G40: =SUMIF(SK스토아_raw!$AM:$AM,매출요약!$D40,SK스토아_raw!$AQ:$AQ) -> 0 | H40: =SUMIF(SK스토아_raw!$AM:$AM,$D40,SK스토아_raw!$AN:$AN) -> 0 | I40: =SUMIFS(출고요청서_raw!$V:$V,출고요청서_raw!$Q:$Q,매출요약!$D40,출고요청서_raw!$R:$R,매출요약!$I$4) -> 0 | J40: =SUMIFS(출고요청서_raw!$W:$W,출고요청서_raw!$Q:$Q,매출요약!$D40,출고요청서_raw!$R:$R,매출요약!$I$4) -> 0 | K40: =SUMIFS(출고요청서_raw!$V:$V,출고요청서_raw!$Q:$Q,매출요약!$D40,출고요청서_raw!$R:$R,매출요약!$K$4) -> 0 | L40: =SUMIFS(출고요청서_raw!$W:$W,출고요청서_raw!$Q:$Q,매출요약!$D40,출고요청서_raw!$R:$R,매출요약!$K$4) -> 0 | M40: =SUMIFS(출고요청서_raw!$V:$V,출고요청서_raw!$Q:$Q,매출요약!$D40,출고요청서_raw!$R:$R,매출요약!$M$4) -> 0 | N40: =SUMIFS(출고요청서_raw!$W:$W,출고요청서_raw!$Q:$Q,매출요약!$D40,출고요청서_raw!$R:$R,매출요약!$M$4) -> 0 | O40: =SUMIFS(출고요청서_raw!$V:$V,출고요청서_raw!$Q:$Q,매출요약!$D40,출고요청서_raw!$R:$R,매출요약!$O$4) -> 0 | P40: =SUMIFS(출고요청서_raw!$W:$W,출고요청서_raw!$Q:$Q,매출요약!$D40,출고요청서_raw!$R:$R,매출요약!$O$4) -> 0 | Q40: =SUMIFS(출고요청서_raw!$V:$V,출고요청서_raw!$Q:$Q,매출요약!$D40,출고요청서_raw!$R:$R,매출요약!$Q$4) -> 0 | R40: =SUMIFS(출고요청서_raw!$W:$W,출고요청서_raw!$Q:$Q,매출요약!$D40,출고요청서_raw!$R:$R,매출요약!$Q$4) -> 0
D41: 46087 | E41: =SUM(G41,I41,K41,M41,Q41) -> 0 | F41: =SUM(H41,J41,L41,N41,R41) -> 0 | G41: =SUMIF(SK스토아_raw!$AM:$AM,매출요약!$D41,SK스토아_raw!$AQ:$AQ) -> 0 | H41: =SUMIF(SK스토아_raw!$AM:$AM,$D41,SK스토아_raw!$AN:$AN) -> 0 | I41: =SUMIFS(출고요청서_raw!$V:$V,출고요청서_raw!$Q:$Q,매출요약!$D41,출고요청서_raw!$R:$R,매출요약!$I$4) -> 0 | J41: =SUMIFS(출고요청서_raw!$W:$W,출고요청서_raw!$Q:$Q,매출요약!$D41,출고요청서_raw!$R:$R,매출요약!$I$4) -> 0 | K41: =SUMIFS(출고요청서_raw!$V:$V,출고요청서_raw!$Q:$Q,매출요약!$D41,출고요청서_raw!$R:$R,매출요약!$K$4) -> 0 | L41: =SUMIFS(출고요청서_raw!$W:$W,출고요청서_raw!$Q:$Q,매출요약!$D41,출고요청서_raw!$R:$R,매출요약!$K$4) -> 0 | M41: =SUMIFS(출고요청서_raw!$V:$V,출고요청서_raw!$Q:$Q,매출요약!$D41,출고요청서_raw!$R:$R,매출요약!$M$4) -> 0 | N41: =SUMIFS(출고요청서_raw!$W:$W,출고요청서_raw!$Q:$Q,매출요약!$D41,출고요청서_raw!$R:$R,매출요약!$M$4) -> 0 | O41: =SUMIFS(출고요청서_raw!$V:$V,출고요청서_raw!$Q:$Q,매출요약!$D41,출고요청서_raw!$R:$R,매출요약!$O$4) -> 0 | P41: =SUMIFS(출고요청서_raw!$W:$W,출고요청서_raw!$Q:$Q,매출요약!$D41,출고요청서_raw!$R:$R,매출요약!$O$4) -> 0 | Q41: =SUMIFS(출고요청서_raw!$V:$V,출고요청서_raw!$Q:$Q,매출요약!$D41,출고요청서_raw!$R:$R,매출요약!$Q$4) -> 0 | R41: =SUMIFS(출고요청서_raw!$W:$W,출고요청서_raw!$Q:$Q,매출요약!$D41,출고요청서_raw!$R:$R,매출요약!$Q$4) -> 0
D42: 46088 | E42: =SUM(G42,I42,K42,M42,Q42) -> 0 | F42: =SUM(H42,J42,L42,N42,R42) -> 0 | G42: =SUMIF(SK스토아_raw!$AM:$AM,매출요약!$D42,SK스토아_raw!$AQ:$AQ) -> 0 | H42: =SUMIF(SK스토아_raw!$AM:$AM,$D42,SK스토아_raw!$AN:$AN) -> 0 | I42: =SUMIFS(출고요청서_raw!$V:$V,출고요청서_raw!$Q:$Q,매출요약!$D42,출고요청서_raw!$R:$R,매출요약!$I$4) -> 0 | J42: =SUMIFS(출고요청서_raw!$W:$W,출고요청서_raw!$Q:$Q,매출요약!$D42,출고요청서_raw!$R:$R,매출요약!$I$4) -> 0 | K42: =SUMIFS(출고요청서_raw!$V:$V,출고요청서_raw!$Q:$Q,매출요약!$D42,출고요청서_raw!$R:$R,매출요약!$K$4) -> 0 | L42: =SUMIFS(출고요청서_raw!$W:$W,출고요청서_raw!$Q:$Q,매출요약!$D42,출고요청서_raw!$R:$R,매출요약!$K$4) -> 0 | M42: =SUMIFS(출고요청서_raw!$V:$V,출고요청서_raw!$Q:$Q,매출요약!$D42,출고요청서_raw!$R:$R,매출요약!$M$4) -> 0 | N42: =SUMIFS(출고요청서_raw!$W:$W,출고요청서_raw!$Q:$Q,매출요약!$D42,출고요청서_raw!$R:$R,매출요약!$M$4) -> 0 | O42: =SUMIFS(출고요청서_raw!$V:$V,출고요청서_raw!$Q:$Q,매출요약!$D42,출고요청서_raw!$R:$R,매출요약!$O$4) -> 0 | P42: =SUMIFS(출고요청서_raw!$W:$W,출고요청서_raw!$Q:$Q,매출요약!$D42,출고요청서_raw!$R:$R,매출요약!$O$4) -> 0 | Q42: =SUMIFS(출고요청서_raw!$V:$V,출고요청서_raw!$Q:$Q,매출요약!$D42,출고요청서_raw!$R:$R,매출요약!$Q$4) -> 0 | R42: =SUMIFS(출고요청서_raw!$W:$W,출고요청서_raw!$Q:$Q,매출요약!$D42,출고요청서_raw!$R:$R,매출요약!$Q$4) -> 0
...

Sheet 재고내역
B2: 재고내역 | G2: 차이 | H2: =H4-H3 -> 0 | I2: =I4-I3 -> 0 | J2: =J4-J3 -> 22
G3: 정인 | H3: 20000 | I3: 10759 | J3: 9219
G4: 로가온 | H4: =H6 -> 20000 | I4: 10759 | J4: =J3+22 -> 9241 | N4: =SUBTOTAL(9,N6:N9851) -> 71019384 | O4: =SUBTOTAL(9,O6:O9851) -> 153754640 | P4: =SUBTOTAL(9,P6:P9851) -> 83188129
A5: x | B5: 유통전문판매원 | C5: 창고명 | D5: 보관유형 | E5: 분류 | F5: 상품명 | G5: 단위 | H5: 입고 | I5: 출고 | J5: 현 재고 | K5: 유통기한 | L5: 비고 | M5: 단가 | N5: 재고금액(VAT별도) | O5: 입고금액(VAT별도) | P5: 출고금액(VAT별도)
B6: SK네트웍스 | C6: 정인 | D6: 냉동 | E6: 상품 | F6: [워커힐] 시그니처 양념본갈비 300G | G6: EA | H6: 20000 | I6: =SUM(H9:J9)*1+SUM(H10:J10)*2+SUM(H11:J11)*4+SUM(H12:J12)*6+SUM(H13:J13)*8 -> 10762 | J6: =H6-I6 -> 9238 | K6: 46412 | M6: 7687 | N6: =J6*M6 -> 71012506 | O6: =H6*M6 -> 153740000 | P6: =I6*M6 -> 82727494
F8: 옵션 | H8: 샘플 | I8: 플랫폼커머스팀 | J8: 미디어커머스팀
F9: 워커힐 시그니처 양념 본갈비 300g, 1개 | G9: EA | H9: 28 | I9: =SUMIF(출고요청서_raw!$H:$H,F9, 출고요청서_raw!$G:$G) -> 18 | J9: =SUMIF(SK스토아_raw!$W:$W,F9, SK스토아_raw!$Y:$Y) -> 0
F10: 워커힐 시그니처 양념 본갈비 300g, 2개 | G10: EA | I10: =SUMIF(출고요청서_raw!$H:$H,F10, 출고요청서_raw!$G:$G) -> 9 | J10: =SUMIF(SK스토아_raw!$W:$W,F10, SK스토아_raw!$Y:$Y) -> 0
F11: 워커힐 시그니처 양념 본갈비 300g, 4개 | G11: EA | I11: =SUMIF(출고요청서_raw!$H:$H,F11, 출고요청서_raw!$G:$G) -> 643 | J11: {=SUMPRODUCT((SK스토아_raw!AL$3:AL$2922=F11)*(SK스토아_raw!AN$3:AN$2922>0)*SK스토아_raw!AN$3:AN$2922)} -> 6
F12: 워커힐 시그니처 양념 본갈비 300g, 6개 | G12: EA | I12: =SUMIF(출고요청서_raw!$H:$H,F12, 출고요청서_raw!$G:$G) -> 89 | J12: {=SUMPRODUCT((SK스토아_raw!AL$3:AL$2922=F12)*(SK스토아_raw!AN$3:AN$2922>0)*SK스토아_raw!AN$3:AN$2922)} -> 0
F13: 워커힐 시그니처 양념 본갈비 300g, 8개 | G13: EA | H13: 8 | I13: =SUMIF(출고요청서_raw!$H:$H,F13, 출고요청서_raw!$G:$G) -> 26 | J13: {=SUMPRODUCT((SK스토아_raw!AL$3:AL$2922=F13)*(SK스토아_raw!AN$3:AN$2922>0)*SK스토아_raw!AN$3:AN$2922)} -> 912
L15: 정인 출고수량 | N15: 홈쇼핑 외 출고수량 | O15: 차이 수량 | P15: 날짜 | Q15: 8개입 출고 (+) | R15: 8개입 반품 (-) | S15: 4개입 출고 (+) | T15: 4개입 반품 (-)
K16: 46049 | L16: 8 | M16: 46049 | N16: 8 | O16: =L16-N16 -> 0 | P16: 46059 | Q16: {=SUMPRODUCT((SK스토아_raw!M$3:M$2922=TEXT(P16,"yyyy-mm-dd"))*(SK스토아_raw!AN$3:AN$2922>0)*(SK스토아_raw!AO$3:AO$2922=119000)*SK스토아_raw!AN$3:AN$2922)} -> 6 | R16: {=SUMPRODUCT((SK스토아_raw!M$3:M$2922=TEXT(P16,"yyyy-mm-dd"))*(SK스토아_raw!AN$3:AN$2922<0)*(SK스토아_raw!AO$3:AO$2922=119000)*SK스토아_raw!AN$3:AN$2922)} -> -1 | S16: {=SUMPRODUCT((SK스토아_raw!M$3:M$2922=TEXT(P16,"yyyy-mm-dd"))*(SK스토아_raw!AN$3:AN$2922>0)*(SK스토아_raw!AO$3:AO$2922=78000)*SK스토아_raw!AN$3:AN$2922)} -> 0 | T16: {=SUMPRODUCT((SK스토아_raw!M$3:M$2922=TEXT(P16,"yyyy-mm-dd"))*(SK스토아_raw!AN$3:AN$2922<0)*(SK스토아_raw!AO$3:AO$2922=78000)*SK스토아_raw!AN$3:AN$2922)} -> 0
K17: 46056 | L17: 20 | M17: 46056 | N17: 20 | O17: =L17-N17 -> 0 | P17: 46060 | Q17: {=SUMPRODUCT((SK스토아_raw!M$3:M$2922=TEXT(P17,"yyyy-mm-dd"))*(SK스토아_raw!AN$3:AN$2922>0)*(SK스토아_raw!AO$3:AO$2922=119000)*SK스토아_raw!AN$3:AN$2922)} -> 435 | R17: {=SUMPRODUCT((SK스토아_raw!M$3:M$2922=TEXT(P17,"yyyy-mm-dd"))*(SK스토아_raw!AN$3:AN$2922<0)*(SK스토아_raw!AO$3:AO$2922=119000)*SK스토아_raw!AN$3:AN$2922)} -> 0 | S17: {=SUMPRODUCT((SK스토아_raw!M$3:M$2922=TEXT(P17,"yyyy-mm-dd"))*(SK스토아_raw!AN$3:AN$2922>0)*(SK스토아_raw!AO$3:AO$2922=78000)*SK스토아_raw!AN$3:AN$2922)} -> 1 | T17: {=SUMPRODUCT((SK스토아_raw!M$3:M$2922=TEXT(P17,"yyyy-mm-dd"))*(SK스토아_raw!AN$3:AN$2922<0)*(SK스토아_raw!AO$3:AO$2922=78000)*SK스토아_raw!AN$3:AN$2922)} -> 0
K18: 46058 | L18: 1343 | M18: 46058 | N18: 1303 | O18: =L18-N18 -> 40 | P18: 46061 | Q18: {=SUMPRODUCT((SK스토아_raw!M$3:M$2922=TEXT(P18,"yyyy-mm-dd"))*(SK스토아_raw!AN$3:AN$2922>0)*(SK스토아_raw!AO$3:AO$2922=119000)*SK스토아_raw!AN$3:AN$2922)} -> 2 | R18: {=SUMPRODUCT((SK스토아_raw!M$3:M$2922=TEXT(P18,"yyyy-mm-dd"))*(SK스토아_raw!AN$3:AN$2922<0)*(SK스토아_raw!AO$3:AO$2922=119000)*SK스토아_raw!AN$3:AN$2922)} -> 0 | S18: {=SUMPRODUCT((SK스토아_raw!M$3:M$2922=TEXT(P18,"yyyy-mm-dd"))*(SK스토아_raw!AN$3:AN$2922>0)*(SK스토아_raw!AO$3:AO$2922=78000)*SK스토아_raw!AN$3:AN$2922)} -> 0 | T18: {=SUMPRODUCT((SK스토아_raw!M$3:M$2922=TEXT(P18,"yyyy-mm-dd"))*(SK스토아_raw!AN$3:AN$2922<0)*(SK스토아_raw!AO$3:AO$2922=78000)*SK스토아_raw!AN$3:AN$2922)} -> 0
K19: 46059 | L19: 4153 | M19: 46059 | N19: 649 | O19: =L19-N19 -> 3504 | P19: 46062 | Q19: {=SUMPRODUCT((SK스토아_raw!M$3:M$2922=TEXT(P19,"yyyy-mm-dd"))*(SK스토아_raw!AN$3:AN$2922>0)*(SK스토아_raw!AO$3:AO$2922=119000)*SK스토아_raw!AN$3:AN$2922)} -> 0 | R19: {=SUMPRODUCT((SK스토아_raw!M$3:M$2922=TEXT(P19,"yyyy-mm-dd"))*(SK스토아_raw!AN$3:AN$2922<0)*(SK스토아_raw!AO$3:AO$2922=119000)*SK스토아_raw!AN$3:AN$2922)} -> 0 | S19: {=SUMPRODUCT((SK스토아_raw!M$3:M$2922=TEXT(P19,"yyyy-mm-dd"))*(SK스토아_raw!AN$3:AN$2922>0)*(SK스토아_raw!AO$3:AO$2922=78000)*SK스토아_raw!AN$3:AN$2922)} -> 0 | T19: {=SUMPRODUCT((SK스토아_raw!M$3:M$2922=TEXT(P19,"yyyy-mm-dd"))*(SK스토아_raw!AN$3:AN$2922<0)*(SK스토아_raw!AO$3:AO$2922=78000)*SK스토아_raw!AN$3:AN$2922)} -> 0
K20: 46062 | L20: 1214 | M20: 46062 | N20: 894 | O20: =L20-N20 -> 320 | P20: 46063 | Q20: {=SUMPRODUCT((SK스토아_raw!M$3:M$2922=TEXT(P20,"yyyy-mm-dd"))*(SK스토아_raw!AN$3:AN$2922>0)*(SK스토아_raw!AO$3:AO$2922=119000)*SK스토아_raw!AN$3:AN$2922)} -> 37 | R20: {=SUMPRODUCT((SK스토아_raw!M$3:M$2922=TEXT(P20,"yyyy-mm-dd"))*(SK스토아_raw!AN$3:AN$2922<0)*(SK스토아_raw!AO$3:AO$2922=119000)*SK스토아_raw!AN$3:AN$2922)} -> -1 | S20: {=SUMPRODUCT((SK스토아_raw!M$3:M$2922=TEXT(P20,"yyyy-mm-dd"))*(SK스토아_raw!AN$3:AN$2922>0)*(SK스토아_raw!AO$3:AO$2922=78000)*SK스토아_raw!AN$3:AN$2922)} -> 3 | T20: {=SUMPRODUCT((SK스토아_raw!M$3:M$2922=TEXT(P20,"yyyy-mm-dd"))*(SK스토아_raw!AN$3:AN$2922<0)*(SK스토아_raw!AO$3:AO$2922=78000)*SK스토아_raw!AN$3:AN$2922)} -> 0
K21: 46063 | L21: 360 | M21: 46063 | N21: 224 | O21: =L21-N21 -> 136 | P21: 46064 | Q21: {=SUMPRODUCT((SK스토아_raw!M$3:M$2922=TEXT(P21,"yyyy-mm-dd"))*(SK스토아_raw!AN$3:AN$2922>0)*(SK스토아_raw!AO$3:AO$2922=119000)*SK스토아_raw!AN$3:AN$2922)} -> 17 | R21: {=SUMPRODUCT((SK스토아_raw!M$3:M$2922=TEXT(P21,"yyyy-mm-dd"))*(SK스토아_raw!AN$3:AN$2922<0)*(SK스토아_raw!AO$3:AO$2922=119000)*SK스토아_raw!AN$3:AN$2922)} -> -1 | S21: {=SUMPRODUCT((SK스토아_raw!M$3:M$2922=TEXT(P21,"yyyy-mm-dd"))*(SK스토아_raw!AN$3:AN$2922>0)*(SK스토아_raw!AO$3:AO$2922=78000)*SK스토아_raw!AN$3:AN$2922)} -> 1 | T21: {=SUMPRODUCT((SK스토아_raw!M$3:M$2922=TEXT(P21,"yyyy-mm-dd"))*(SK스토아_raw!AN$3:AN$2922<0)*(SK스토아_raw!AO$3:AO$2922=78000)*SK스토아_raw!AN$3:AN$2922)} -> 0
K22: 46064 | L22: 3425 | M22: 46064 | N22: 265 | O22: =L22-N22 -> 3160 | P22: 46065 | Q22: {=SUMPRODUCT((SK스토아_raw!M$3:M$2922=TEXT(P22,"yyyy-mm-dd"))*(SK스토아_raw!AN$3:AN$2922>0)*(SK스토아_raw!AO$3:AO$2922=119000)*SK스토아_raw!AN$3:AN$2922)} -> 390 | R22: {=SUMPRODUCT((SK스토아_raw!M$3:M$2922=TEXT(P22,"yyyy-mm-dd"))*(SK스토아_raw!AN$3:AN$2922<0)*(SK스토아_raw!AO$3:AO$2922=119000)*SK스토아_raw!AN$3:AN$2922)} -> 0 | S22: {=SUMPRODUCT((SK스토아_raw!M$3:M$2922=TEXT(P22,"yyyy-mm-dd"))*(SK스토아_raw!AN$3:AN$2922>0)*(SK스토아_raw!AO$3:AO$2922=78000)*SK스토아_raw!AN$3:AN$2922)} -> 0 | T22: {=SUMPRODUCT((SK스토아_raw!M$3:M$2922=TEXT(P22,"yyyy-mm-dd"))*(SK스토아_raw!AN$3:AN$2922<0)*(SK스토아_raw!AO$3:AO$2922=78000)*SK스토아_raw!AN$3:AN$2922)} -> 0
K23: 46065 | L23: 236 | M23: 46065 | N23: 76 | O23: =L23-N23 -> 160 | P23: 46066 | Q23: {=SUMPRODUCT((SK스토아_raw!M$3:M$2922=TEXT(P23,"yyyy-mm-dd"))*(SK스토아_raw!AN$3:AN$2922>0)*(SK스토아_raw!AO$3:AO$2922=119000)*SK스토아_raw!AN$3:AN$2922)} -> 24 | R23: {=SUMPRODUCT((SK스토아_raw!M$3:M$2922=TEXT(P23,"yyyy-mm-dd"))*(SK스토아_raw!AN$3:AN$2922<0)*(SK스토아_raw!AO$3:AO$2922=119000)*SK스토아_raw!AN$3:AN$2922)} -> 0 | S23: {=SUMPRODUCT((SK스토아_raw!M$3:M$2922=TEXT(P23,"yyyy-mm-dd"))*(SK스토아_raw!AN$3:AN$2922>0)*(SK스토아_raw!AO$3:AO$2922=78000)*SK스토아_raw!AN$3:AN$2922)} -> 1 | T23: {=SUMPRODUCT((SK스토아_raw!M$3:M$2922=TEXT(P23,"yyyy-mm-dd"))*(SK스토아_raw!AN$3:AN$2922<0)*(SK스토아_raw!AO$3:AO$2922=78000)*SK스토아_raw!AN$3:AN$2922)} -> 0
L24: =SUM(L16:L23) -> 10759 | N24: =SUM(N16:N23) -> 3439 | O24: =SUM(O16:O23) -> 7320 | P24: 46067 | Q24: {=SUMPRODUCT((SK스토아_raw!M$3:M$2922=TEXT(P24,"yyyy-mm-dd"))*(SK스토아_raw!AN$3:AN$2922>0)*(SK스토아_raw!AO$3:AO$2922=119000)*SK스토아_raw!AN$3:AN$2922)} -> 1 | R24: {=SUMPRODUCT((SK스토아_raw!M$3:M$2922=TEXT(P24,"yyyy-mm-dd"))*(SK스토아_raw!AN$3:AN$2922<0)*(SK스토아_raw!AO$3:AO$2922=119000)*SK스토아_raw!AN$3:AN$2922)} -> 0 | S24: {=SUMPRODUCT((SK스토아_raw!M$3:M$2922=TEXT(P24,"yyyy-mm-dd"))*(SK스토아_raw!AN$3:AN$2922>0)*(SK스토아_raw!AO$3:AO$2922=78000)*SK스토아_raw!AN$3:AN$2922)} -> 0 | T24: {=SUMPRODUCT((SK스토아_raw!M$3:M$2922=TEXT(P24,"yyyy-mm-dd"))*(SK스토아_raw!AN$3:AN$2922<0)*(SK스토아_raw!AO$3:AO$2922=78000)*SK스토아_raw!AN$3:AN$2922)} -> 0
P25: 46068 | Q25: {=SUMPRODUCT((SK스토아_raw!M$3:M$2922=TEXT(P25,"yyyy-mm-dd"))*(SK스토아_raw!AN$3:AN$2922>0)*(SK스토아_raw!AO$3:AO$2922=119000)*SK스토아_raw!AN$3:AN$2922)} -> 0 | R25: {=SUMPRODUCT((SK스토아_raw!M$3:M$2922=TEXT(P25,"yyyy-mm-dd"))*(SK스토아_raw!AN$3:AN$2922<0)*(SK스토아_raw!AO$3:AO$2922=119000)*SK스토아_raw!AN$3:AN$2922)} -> 0 | S25: {=SUMPRODUCT((SK스토아_raw!M$3:M$2922=TEXT(P25,"yyyy-mm-dd"))*(SK스토아_raw!AN$3:AN$2922>0)*(SK스토아_raw!AO$3:AO$2922=78000)*SK스토아_raw!AN$3:AN$2922)} -> 0 | T25: {=SUMPRODUCT((SK스토아_raw!M$3:M$2922=TEXT(P25,"yyyy-mm-dd"))*(SK스토아_raw!AN$3:AN$2922<0)*(SK스토아_raw!AO$3:AO$2922=78000)*SK스토아_raw!AN$3:AN$2922)} -> 0
P26: 합계 | Q26: =SUM(Q16:Q25) -> 912 | R26: =SUM(R16:R25) -> -3 | S26: =SUM(S16:S25) -> 6 | T26: =SUM(T16:T25) -> 0
Q27: =Q26*8 -> 7296 | S27: =S26*4 -> 24 | T27: =Q27+S27 -> 7320

Sheet 출고요청서_raw
H1: *큰 박스 최대 8개, 작은 박스 최대 4개 투입 | T1: 수식 | V1: 수식 | W1: 수식 | Z1: 수식 | AA1: 수식 | AB1: 수식 | AC1: 수식
S2: =SUBTOTAL(9,S4:S1048576) -> 35934300 | T2: =SUBTOTAL(9,T4:T1048576) -> 136100 | U2: =SUBTOTAL(9,U4:U1048576) -> 37961200 | V2: =SUBTOTAL(9,V4:V1048576) -> 34510182 | W2: =SUBTOTAL(9,W4:W1048576) -> 3442 | Y2: =SUBTOTAL(9,Y4:Y1048576) -> 99098.16 | Z2: =SUBTOTAL(9,Z4:Z1048576) -> 25751450 | AA2: =SUBTOTAL(9,AA4:AA1048576) -> 3235050 | AB2: =SUBTOTAL(9,AB4:AB1048576) -> 5424583.7 | AC2: =AB2/V2 -> 0.15718792 | AD2: =U2-Y2 -> 37862102 | AE2: =SUBTOTAL(9,AE4:AE1048576) -> 859274.52
A3: 받으시는 분 | B3: 받으시는 분 전화 | C3: 받는분담당자 | D3: 받는분핸드폰 | E3: 받는분우편번호 | F3: 받는분총주소 | G3: 수량 | H3: 품목명 | I3: 운임Type | J3: 지불조건 | K3: 출고번호 | L3: 특기사항 | M3: 메모1 | N3: 메모2 | O3: 메모3 | P3: 메모4 | Q3: 출고일 | R3: 매출처명 | S3: 판매가 | T3: 쿠폰비 | U3: 총 매출액 | V3: 실 매출(vat-) | W3: 수량(1ea 단품 기준) | X3: 수수료 | Y3: 수수료 | Z3: 원가 | AA3: 물류비 | AB3: 공헌이익 | AC3: 공헌이익율 | AD3: 비고 | AE3: 지급예정금액
G4: 20 | H4: [워커힐] 시그니처 양념본갈비 300G | Q4: 46056 | W4: 20 | AD4: 리씽크 샘플
A5: 이진우 | B5: 010-4516-7881 | E5: 08279 | F5: 서울특별시 구로구 구로동로47길 24 (구로동, 구로중앙하이츠아파트) 102-906 | G5: 1 | H5: 워커힐 시그니처 양념 본갈비 300g, 2개 | M5: 2026020586412211 | N5: 2026020586548501 | O5: 13026511254 | P5: 스마트스토어 | Q5: 46058 | R5: 스마트스토어 | S5: 45800 | T5: =S5-U5 -> 11900 | U5: 33900 | V5: =U5/1.1 -> 30818.182 | W5: =IF(H5=재고내역!$F$9,출고요청서_raw!G5*1,IF(H5=재고내역!$F$10,출고요청서_raw!G5*2,IF(출고요청서_raw!H5=재고내역!$F$11,출고요청서_raw!G5*4,IF(출고요청서_raw!H5=재고내역!$F$12,출고요청서_raw!G5*6,IF(출고요청서_raw!H5=재고내역!$F$13,출고요청서_raw!G5*8))))) -> 2 | X5: =Y5/U5 -> 0.066283186 | Y5: 2247 | Z5: =W5*재고내역!$M$6 -> 15374 | AA5: =IF(W5>8,4550*2,4550) -> 4550 | AB5: =V5-Z5-AA5-Y5 -> 8647.1818 | AC5: =AB5/V5 -> 0.28058702 | AE5: =U5-Y5 -> 31653
A6: 선우동국 | B6: 010-3090-6765 | E6: 02533 | F6: 서울특별시 동대문구 사가정로 190 (전농동, 전농우성아파트) 3동 1103호 | G6: 1 | H6: 워커힐 시그니처 양념 본갈비 300g, 1개 | M6: 2026020586046791 | N6: 2026020586295071 | O6: 13026511253 | P6: 스마트스토어 | Q6: 46058 | R6: 스마트스토어 | S6: 22900 | T6: =S6-U6 -> 5100 | U6: 17800 | V6: =U6/1.1 -> 16181.818 | W6: =IF(H6=재고내역!$F$9,출고요청서_raw!G6*1,IF(H6=재고내역!$F$10,출고요청서_raw!G6*2,IF(출고요청서_raw!H6=재고내역!$F$11,출고요청서_raw!G6*4,IF(출고요청서_raw!H6=재고내역!$F$12,출고요청서_raw!G6*6,IF(출고요청서_raw!H6=재고내역!$F$13,출고요청서_raw!G6*8))))) -> 1 | X6: =Y6/U6 -> 0.066292135 | Y6: 1180 | Z6: =W6*재고내역!$M$6 -> 7687 | AA6: =IF(W6>8,4550*2,4550) -> 4550 | AB6: =V6-Z6-AA6-Y6 -> 2764.8182 | AC6: =AB6/V6 -> 0.17085955 | AE6: =U6-Y6 -> 16620 | AF6: *쿠팡 즉시할인 | AG6: 2/5~2/11 | AI6: *채널 수수료 | AL6: 출고일 | AM6: 합계 : 수량(1ea 단품 기준)
A7: 서은경 | B7: 010-7470-6174 | E7: 02535 | F7: 서울특별시 동대문구 한천로37길 33 (답십리동, 래미안엘파인아파트) 108동 1103호 | G7: 1 | H7: 워커힐 시그니처 양념 본갈비 300g, 1개 | M7: 2026020477087661 | N7: 2026020480361831 | O7: 13026511253 | P7: 스마트스토어 | Q7: 46058 | R7: 스마트스토어 | S7: 22900 | T7: =S7-U7 -> 5100 | U7: 17800 | V7: =U7/1.1 -> 16181.818 | W7: =IF(H7=재고내역!$F$9,출고요청서_raw!G7*1,IF(H7=재고내역!$F$10,출고요청서_raw!G7*2,IF(출고요청서_raw!H7=재고내역!$F$11,출고요청서_raw!G7*4,IF(출고요청서_raw!H7=재고내역!$F$12,출고요청서_raw!G7*6,IF(출고요청서_raw!H7=재고내역!$F$13,출고요청서_raw!G7*8))))) -> 1 | X7: =Y7/U7 -> 0.066292135 | Y7: 1180 | Z7: =W7*재고내역!$M$6 -> 7687 | AA7: =IF(W7>8,4550*2,4550) -> 4550 | AB7: =V7-Z7-AA7-Y7 -> 2764.8182 | AC7: =AB7/V7 -> 0.17085955 | AE7: =U7-Y7 -> 16620 | AF7: 워커힐 시그니처 양념 본갈비 300g, 1개 | AG7: 1100 | AI7: 스마트스토어 | AJ7: 0.0663 | AL7: 46049 | AM7: 8
A8: 이정례 | B8: 0502-4122-2717 | E8: 10021 | F8: 경기도 김포시 월곶면 용강로57번길 31-5 1층 | G8: 1 | H8: 워커힐 시그니처 양념 본갈비 300g, 1개 | L8: 문 앞 | M8: 651343802793997 | N8: 12100169248866 | O8: 94659124876 | P8: 쿠팡 | Q8: 46058 | R8: 쿠팡 | S8: 20900 | T8: =IF(R8="쿠팡",VLOOKUP(H8,$AF$7:$AG$10,2,0)*G8,"0") -> 1100 | U8: =S8-T8 -> 19800 | V8: =U8/1.1 -> 18000 | W8: =IF(H8=재고내역!$F$9,출고요청서_raw!G8*1,IF(H8=재고내역!$F$10,출고요청서_raw!G8*2,IF(출고요청서_raw!H8=재고내역!$F$11,출고요청서_raw!G8*4,IF(출고요청서_raw!H8=재고내역!$F$12,출고요청서_raw!G8*6,IF(출고요청서_raw!H8=재고내역!$F$13,출고요청서_raw!G8*8))))) -> 1 | X8: =Y8/U8 -> 0.11656566 | Y8: 2308 | Z8: =W8*재고내역!$M$6 -> 7687 | AA8: =IF(W8>8,4550*2,4550) -> 4550 | AB8: =V8-Z8-AA8-Y8 -> 3455 | AC8: =AB8/V8 -> 0.19194444 | AE8: =U8-Y8 -> 17492 | AF8: 워커힐 시그니처 양념 본갈비 300g, 2개 | AG8: 4100 | AI8: 쿠팡 | AJ8: 0.1166 | AL8: 46056 | AM8: 20
A9: 서은경 | B9: 0502-1697-1836 | E9: 02535 | F9: 서울특별시 동대문구 한천로37길 33 래미안 엘파인 아파트, 108동 1103호 ( 답십리동, 래미안엘파인아파트 ) | G9: 1 | H9: 워커힐 시그니처 양념 본갈비 300g, 1개 | L9: 문 앞 | M9: 651376581296215 | N9: 28100169339326 | O9: 94659124876 | P9: 쿠팡 | Q9: 46058 | R9: 쿠팡 | S9: 20900 | T9: =IF(R9="쿠팡",VLOOKUP(H9,$AF$7:$AG$10,2,0)*G9,"0") -> 1100 | U9: =S9-T9 -> 19800 | V9: =U9/1.1 -> 18000 | W9: =IF(H9=재고내역!$F$9,출고요청서_raw!G9*1,IF(H9=재고내역!$F$10,출고요청서_raw!G9*2,IF(출고요청서_raw!H9=재고내역!$F$11,출고요청서_raw!G9*4,IF(출고요청서_raw!H9=재고내역!$F$12,출고요청서_raw!G9*6,IF(출고요청서_raw!H9=재고내역!$F$13,출고요청서_raw!G9*8))))) -> 1 | X9: =Y9/U9 -> 0.11656566 | Y9: 2308 | Z9: =W9*재고내역!$M$6 -> 7687 | AA9: =IF(W9>8,4550*2,4550) -> 4550 | AB9: =V9-Z9-AA9-Y9 -> 3455 | AC9: =AB9/V9 -> 0.19194444 | AE9: =U9-Y9 -> 17492 | AF9: 워커힐 시그니처 양념 본갈비 300g, 4개 | AG9: 13000 | AI9: 카카오 | AJ9: 0.033 | AL9: 46058 | AM9: 1303
A10: 이미숙 | B10: 0502-5119-6719 | E10: 31168 | F10: 충청남도 천안시 서북구 공원로 196 103동2002호 ( 불당동, 펜타포트 ) | G10: 3 | H10: 워커힐 시그니처 양념 본갈비 300g, 1개 | L10: 문 앞 | M10: 651516109013044 | N10: 30100169868577 | O10: 94659124876 | P10: 쿠팡 | Q10: 46058 | R10: 쿠팡 | S10: =20900*3 -> 62700 | T10: =IF(R10="쿠팡",VLOOKUP(H10,$AF$7:$AG$10,2,0),"0") -> 1100 | U10: =S10-T10 -> 61600 | V10: =U10/1.1 -> 56000 | W10: =IF(H10=재고내역!$F$9,출고요청서_raw!G10*1,IF(H10=재고내역!$F$10,출고요청서_raw!G10*2,IF(출고요청서_raw!H10=재고내역!$F$11,출고요청서_raw!G10*4,IF(출고요청서_raw!H10=재고내역!$F$12,출고요청서_raw!G10*6,IF(출고요청서_raw!H10=재고내역!$F$13,출고요청서_raw!G10*8))))) -> 3 | X10: =Y10/U10 -> 0.11657468 | Y10: 7181 | Z10: =W10*재고내역!$M$6 -> 23061 | AA10: =IF(W10>8,4550*2,4550) -> 4550 | AB10: =V10-Z10-AA10-Y10 -> 21208 | AC10: =AB10/V10 -> 0.37871429 | AE10: =U10-Y10 -> 54419 | AF10: 워커힐 시그니처 양념 본갈비 300g, 8개 | AG10: 25000 | AL10: 46059 | AM10: 649
A11: 편경화 | B11: 010-6268-4062 | E11: 13993 | F11: 경기 안양시 만안구 안양천서로 357 안양역한양수자인리버파크 101동 2404호 | G11: 1 | H11: 워커힐 시그니처 양념 본갈비 300g, 4개 | N11: OPT-2474637-2720942 | P11: 리씽크 | Q11: 46058 | R11: 리씽크 | S11: 45500 | T11: =IF(R11="쿠팡",VLOOKUP(H11,$AF$7:$AG$10,2,0)*G11,"0") -> 0 | U11: 45500 | V11: =U11/1.1 -> 41363.636 | W11: =IF(H11=재고내역!$F$9,출고요청서_raw!G11*1,IF(H11=재고내역!$F$10,출고요청서_raw!G11*2,IF(출고요청서_raw!H11=재고내역!$F$11,출고요청서_raw!G11*4,IF(출고요청서_raw!H11=재고내역!$F$12,출고요청서_raw!G11*6,IF(출고요청서_raw!H11=재고내역!$F$13,출고요청서_raw!G11*8))))) -> 4 | Z11: =W11*재고내역!$M$6 -> 30748 | AA11: =IF(W11>8,4550*2,4550) -> 4550 | AB11: =V11-Z11-AA11-Y11 -> 6065.6364 | AC11: =AB11/V11 -> 0.14664176 | AL11: 46062 | AM11: 894
A12: 정희순 | B12: 010-8509-1977 | E12: 48414 | F12: 부산 남구 전포대로20번길 15 102동 2402호 | G12: 1 | H12: 워커힐 시그니처 양념 본갈비 300g, 4개 | L12: 문 앞에 놔주세요. | N12: OPT-2474614-2720917 | P12: 리씽크 | Q12: 46058 | R12: 리씽크 | S12: 45500 | T12: =IF(R12="쿠팡",VLOOKUP(H12,$AF$7:$AG$10,2,0)*G12,"0") -> 0 | U12: 45500 | V12: =U12/1.1 -> 41363.636 | W12: =IF(H12=재고내역!$F$9,출고요청서_raw!G12*1,IF(H12=재고내역!$F$10,출고요청서_raw!G12*2,IF(출고요청서_raw!H12=재고내역!$F$11,출고요청서_raw!G12*4,IF(출고요청서_raw!H12=재고내역!$F$12,출고요청서_raw!G12*6,IF(출고요청서_raw!H12=재고내역!$F$13,출고요청서_raw!G12*8))))) -> 4 | Z12: =W12*재고내역!$M$6 -> 30748 | AA12: =IF(W12>8,4550*2,4550) -> 4550 | AB12: =V12-Z12-AA12-Y12 -> 6065.6364 | AC12: =AB12/V12 -> 0.14664176 | AF12: *쿠팡 즉시할인 | AG12: 2/12~2/28 | AL12: 46063 | AM12: 224
A13: 서경수 | B13: 010-3268-6326 | E13: 22779 | F13: 인천광역시 서구 봉오재1로 49 (신현동, 루원시티루에블리) 806동2203호 | G13: 1 | H13: 워커힐 시그니처 양념 본갈비 300g, 4개 | N13: OPT-2474611-2720914 | P13: 리씽크 | Q13: 46058 | R13: 리씽크 | S13: 45500 | T13: =IF(R13="쿠팡",VLOOKUP(H13,$AF$7:$AG$10,2,0)*G13,"0") -> 0 | U13: 45500 | V13: =U13/1.1 -> 41363.636 | W13: =IF(H13=재고내역!$F$9,출고요청서_raw!G13*1,IF(H13=재고내역!$F$10,출고요청서_raw!G13*2,IF(출고요청서_raw!H13=재고내역!$F$11,출고요청서_raw!G13*4,IF(출고요청서_raw!H13=재고내역!$F$12,출고요청서_raw!G13*6,IF(출고요청서_raw!H13=재고내역!$F$13,출고요청서_raw!G13*8))))) -> 4 | Z13: =W13*재고내역!$M$6 -> 30748 | AA13: =IF(W13>8,4550*2,4550) -> 4550 | AB13: =V13-Z13-AA13-Y13 -> 6065.6364 | AC13: =AB13/V13 -> 0.14664176 | AF13: 워커힐 시그니처 양념 본갈비 300g, 1개 | AG13: 1100 | AL13: 46064 | AM13: 265
A14: 유경태 | B14: 010-7104-8919 | E14: 03438 | F14: 서울 은평구 갈현로1길 31 103동701호 | G14: 1 | H14: 워커힐 시그니처 양념 본갈비 300g, 4개 | N14: OPT-2474591-2720893 | P14: 리씽크 | Q14: 46058 | R14: 리씽크 | S14: 45500 | T14: =IF(R14="쿠팡",VLOOKUP(H14,$AF$7:$AG$10,2,0)*G14,"0") -> 0 | U14: 45500 | V14: =U14/1.1 -> 41363.636 | W14: =IF(H14=재고내역!$F$9,출고요청서_raw!G14*1,IF(H14=재고내역!$F$10,출고요청서_raw!G14*2,IF(출고요청서_raw!H14=재고내역!$F$11,출고요청서_raw!G14*4,IF(출고요청서_raw!H14=재고내역!$F$12,출고요청서_raw!G14*6,IF(출고요청서_raw!H14=재고내역!$F$13,출고요청서_raw!G14*8))))) -> 4 | Z14: =W14*재고내역!$M$6 -> 30748 | AA14: =IF(W14>8,4550*2,4550) -> 4550 | AB14: =V14-Z14-AA14-Y14 -> 6065.6364 | AC14: =AB14/V14 -> 0.14664176 | AF14: 워커힐 시그니처 양념 본갈비 300g, 2개 | AL14: 46065 | AM14: 76
A15: 김남희 | B15: 010-5018-5129 | E15: 31971 | F15: 충남 서산시 부춘2로 47 대림동신아파트 202동1308호 | G15: 1 | H15: 워커힐 시그니처 양념 본갈비 300g, 4개 | N15: OPT-2474590-2720892 | P15: 리씽크 | Q15: 46058 | R15: 리씽크 | S15: 45500 | T15: =IF(R15="쿠팡",VLOOKUP(H15,$AF$7:$AG$10,2,0)*G15,"0") -> 0 | U15: 45500 | V15: =U15/1.1 -> 41363.636 | W15: =IF(H15=재고내역!$F$9,출고요청서_raw!G15*1,IF(H15=재고내역!$F$10,출고요청서_raw!G15*2,IF(출고요청서_raw!H15=재고내역!$F$11,출고요청서_raw!G15*4,IF(출고요청서_raw!H15=재고내역!$F$12,출고요청서_raw!G15*6,IF(출고요청서_raw!H15=재고내역!$F$13,출고요청서_raw!G15*8))))) -> 4 | Z15: =W15*재고내역!$M$6 -> 30748 | AA15: =IF(W15>8,4550*2,4550) -> 4550 | AB15: =V15-Z15-AA15-Y15 -> 6065.6364 | AC15: =AB15/V15 -> 0.14664176 | AF15: 워커힐 시그니처 양념 본갈비 300g, 4개 | AL15: (비어 있음)
A16: 노 도빈 | B16: 010-5095-3185 | E16: 06276 | F16: 서울특별시 강남구 선릉로 221 (도곡동, 도곡렉슬아파트) 212동 201호 | G16: 1 | H16: 워커힐 시그니처 양념 본갈비 300g, 4개 | N16: OPT-2474583-2720885 | P16: 리씽크 | Q16: 46058 | R16: 리씽크 | S16: 45500 | T16: =IF(R16="쿠팡",VLOOKUP(H16,$AF$7:$AG$10,2,0)*G16,"0") -> 0 | U16: 45500 | V16: =U16/1.1 -> 41363.636 | W16: =IF(H16=재고내역!$F$9,출고요청서_raw!G16*1,IF(H16=재고내역!$F$10,출고요청서_raw!G16*2,IF(출고요청서_raw!H16=재고내역!$F$11,출고요청서_raw!G16*4,IF(출고요청서_raw!H16=재고내역!$F$12,출고요청서_raw!G16*6,IF(출고요청서_raw!H16=재고내역!$F$13,출고요청서_raw!G16*8))))) -> 4 | Z16: =W16*재고내역!$M$6 -> 30748 | AA16: =IF(W16>8,4550*2,4550) -> 4550 | AB16: =V16-Z16-AA16-Y16 -> 6065.6364 | AC16: =AB16/V16 -> 0.14664176 | AF16: 워커힐 시그니처 양념 본갈비 300g, 8개 | AL16: 총합계 | AM16: 3439
A17: 김인경 | B17: 010-4276-8831 | E17: 13595 | F17: 경기도 성남시 분당구 백현로 105 (수내동) B동 1601 | G17: 2 | H17: 워커힐 시그니처 양념 본갈비 300g, 4개 | N17: OPT-2474579-2720881 | P17: 리씽크 | Q17: 46058 | R17: 리씽크 | S17: 45500 | T17: =IF(R17="쿠팡",VLOOKUP(H17,$AF$7:$AG$10,2,0)*G17,"0") -> 0 | U17: 91000 | V17: =U17/1.1 -> 82727.273 | W17: =IF(H17=재고내역!$F$9,출고요청서_raw!G17*1,IF(H17=재고내역!$F$10,출고요청서_raw!G17*2,IF(출고요청서_raw!H17=재고내역!$F$11,출고요청서_raw!G17*4,IF(출고요청서_raw!H17=재고내역!$F$12,출고요청서_raw!G17*6,IF(출고요청서_raw!H17=재고내역!$F$13,출고요청서_raw!G17*8))))) -> 8 | Z17: =W17*재고내역!$M$6 -> 61496 | AA17: =IF(W17>8,4550*2,4550) -> 4550 | AB17: =V17-Z17-AA17-Y17 -> 16681.273 | AC17: =AB17/V17 -> 0.20164176
